Workbook
Name ba_KoachAdam: 'עלויות כח אדם (6)'!$B$14:$M$3014
Name bs_bitzua: 'דוח ביצוע (3)'!$A$20:$X$520
Name bs_hotzaot: 'דוח הוצאות בפועל (4)'!$B$16:$G$3016
Name bs_mafilim: #REF!
Name bs_matzevet: 'מצבת והרשמה (2)'!$B$20:$N$520
Name bs_melagot: 'תשלומי הורים ומלגות להורים (5) '!$B$17:$I$517
Name bs_netunim: 'נתונים כלליים (1)'!$C$5:$C$7
Name bs_SganRakaz: ' איוש משרות (8)'!$B$15:$M$515
Name bs_shura: 'בית ספר - תקצוב לפי מוסד (9)'!$AS$9:$BE$10
Name בדיק: #REF!
Name בדיקה: #REF!
Name הוצאות_פעילות: 'סיווג התפקידים והעלויות'!$C$15:$C$199
Name הוצאות_פעילות_ללא_מלגות: 'סיווג התפקידים והעלויות'!$D$15:$D$198
Name השתתפות_לילד_ביס: 'גנים ובתי ספר- מבנה תקציב'!$B$80:$H$90
Name ישובים_מפונים: #REF!
Name מדצ: 'סיווג התפקידים והעלויות'!$B$3
Name מוכשר: #REF!
Name מוסדות: 'מצבת והרשמה (2)'!$C$21:$C$520
Name מורה: 'סיווג התפקידים והעלויות'!$A$3:$A$6
Name מעמד: 'מצבת והרשמה (2)'!#REF!
Name מעמד_משפטי: #REF!
Name מפעיל: #REF!
Name סגנית_רכזת_מעל_150: 'סיווג התפקידים והעלויות'!$D$3
Name סוג: 'סיווג התפקידים והעלויות'!$A$2:$E$2
Name סייעת_רפואית_או_אישית: 'סיווג התפקידים והעלויות'!$F3
Name סמלים: 'מצבת והרשמה (2)'!$C$21:$C$1015
Name סמלפעילות: 'דוח ביצוע (3)'!$B$21:$B$520
Name פעילות: 'מצבת והרשמה (2)'!$F$21:$F$520
Name רכזת_תכנית_בבית_הספר: 'סיווג התפקידים והעלויות'!$C$3
Name רשויות: 'רשימת רשויות'!$A$3:$A$260
Name רשויות_מפונות: #REF!
Name רשימה: #REF!
Name רשימה: #REF!
Name תוספת_כח_אדם: 'סיווג התפקידים והעלויות'!$E$3:$E$5

Sheet תוכן העניינים
B2: תוכנית הגנים ובתי הספר של החופש הגדול - תשפ"ו | תוכן עניינים
B3: יש למלא את הגיליונות לפי הסדר המוצג מטה (שלב 1 עד 9). לחצו על שם הגיליון למעבר ישיר.
B5: מקרא צבעים:
C6: תא קלט - יש למלא | D6: תא מחושב/נעול - אין לערוך | E6: שגיאה / לא תקין
B9: # | C9: שלב / גיליון | D9: הסבר קצר | E9: הנחיות מפורטות | F9: סטטוס מילוי | G9: בדיקת תקינות
B10: 1 | C10: נתונים כלליים (1) | D10: יש לעדכן פרטי רשות, אנשי קשר וגופים מפעילים | E10: הנחיות כלליות | F10: =IF('נתונים כלליים (1)'!$C$5="","טרם מולא","תקין") -> טרם מולא | G10: =IF('נתונים כלליים (1)'!$E$4=" ","תקין","לא תקין, יש לתקן דיווח!") -> לא תקין, יש לתקן דיווח!
B11: 2 | C11: מצבת והרשמה (2) | D11: מתעדכן אוטומטית - אין למלא | E11: הנחיות למילוי הדוח
B12: 3 | C12: דוח ביצוע (3) | D12: דיווח סמלי מוסד שהשתתפו בתוכנית, מספר ילדים ומפעיל | E12: הנחיות למילוי הדוח | F12: =IF('דוח ביצוע (3)'!C13=0,"טרם מולא","תקין") -> טרם מולא | G12: =IF('דוח ביצוע (3)'!$L$3=" ","תקין","לא תקין, יש לתקן דיווח!") -> תקין
B13: 4 | C13: דוח הוצאות בפועל (4) | D13: דיווח הוצאות בפועל לפי מהות ההוצאה | E13: הנחיות למילוי הדוח | F13: =IF('דוח הוצאות בפועל (4)'!H9=0,"טרם מולא","תקין") -> טרם מולא | G13: =IF('דוח הוצאות בפועל (4)'!$I$3=" ","תקין","לא תקין, יש לתקן דיווח!") -> תקין
B14: 5 | C14: תשלומי הורים ומלגות להורים (5) | D14: דייוח גבייה מהורים ומלגות שניתנו | E14: הנחיות למילוי הדוח | F14: =IF('תשלומי הורים ומלגות להורים (5) '!D12=0,"טרם מולא","תקין") -> טרם מולא | G14: =IF('תשלומי הורים ומלגות להורים (5) '!$I$3=" ","תקין","לא תקין, יש לתקן דיווח!") -> תקין
B15: 6 | C15: עלויות כח אדם (6) | D15: דיווח כח אדם שהועסק בתוכנית, תפקידים ושעות | E15: הנחיות למילוי הדוח | F15: =IF('עלויות כח אדם (6)'!E11=0,"טרם מולא","תקין") -> טרם מולא | G15: =IF('עלויות כח אדם (6)'!$H$5=" ","תקין","לא תקין, יש לתקן דיווח!") -> תקין
B16: 7 | C16: סייעות רפואיות או אישיות (7) | D16: דיווח פרטי סייעות רפואיות שהועסקו בתכנית | E16: הנחיות למילוי הדוח | F16: =IF('סייעות רפואיות או אישיות (7)'!D13=0,"טרם מולא","תקין") -> טרם מולא
B17: 8 | C17: איוש משרות (8) | D17: נבדק אוטומטית - אין למלא | E17: הנחיות למילוי הדוח | F17: =IF(' איוש משרות (8)'!C16="","טרם מולא","תקין") -> טרם מולא | G17: =IF(' איוש משרות (8)'!$K$5=" ","תקין","לא תקין, יש לתקן דיווח!") -> תקין
B18: 9 | C18: תקצוב לפי מוסד (9) | D18: גיליון מחושב ונעול - לעיון בלבד | E18: הנחיות למילוי הדוח

Sheet הנחיות כלליות
A1: גירסה בתי ספר 8.2026
A2: בס"ד | B2: הנחיות למילוי
A3: תכנית בתי הספר והגנים של החופש הגדול, קיץ תשפ"ו
A4: מסמכים נדרשים ודגשים לדיווח לצורך קבלת תקצוב
A6: >> חשוב לקרוא בעיון את ההוראות על מנת להגיש את המסמכים בצורה תקינה ולמנוע קיזוזים מיותרים!
A8: להלן רשימת מסמכים הנדרשים לצורך קבלת תקצוב ברשויות עבור תוכנית "הגנים ובית הספר של החופש הגדול" תשפ"ו בגני הילדים ובכיתות א-ג:
A9: סעיף | B9: מס' | C9: מסמכים נדרשים ודגשים לדיווח
A10: שכר | B10: 1 | C10: יש להגדיר בתוכנת השכר מחלקה/רכיב נפרדת עבור שכר עובדי הקייטנה.
B11: 2 | C11: דוח ריכוז משכורות – דוח מרוכז לכלל העובדים המכיל פירוט של כל רכיבי השכר ששולמו לעובדים בחודש הקייטנה – יולי 2026, בהתאמה לנתונים שדווחו בדוח ביצוע. יצוין כי כל תוכנה מגדירה את הדוח בשם אחר (לדוגמא: דוח חזותי, ריכוז תלושים, דוח רכיבי שכר) ולכן נא להתייחס לרכיבים הנדרשים בדוח.
B12: 3 | C12: דוח עלות – דוח מרכז המפרט את עלויות המעסיק של כלל העובדים (נקרא: דוח 66) בהתאמה לסכום שדווח בדוח ביצוע.
B13: 4 | C13: כרטסת הוצאות שכר – כרטסת הנהלת חשבונות נפרדת המכילה את הוצאות השכר בגין הקייטנה בלבד, בהתאמה לסכום שדווח בדוח ביצוע. במידה וכרטסת השכר כוללת הוצאות שכר בגין פעילות העשרה יש לצרף מסמך התאמה ברור ולציין את שם העובד המועסק ותפקידו בקייטנה (לדוג' ישראל ישראלי – פעילות ספורט).
A14: ניהול ותפעול | B14: 1 | C14: כרטסת ניהול ותפעול – א. כרטסת הנהלת חשבונות נפרדת המכילה את הוצאות הניהול והתפעול בהתאמה לסכום שדווח בדוח ביצוע. הכרטסת צריכה להכיל את פירוט מהות ההוצאות ושמות הספקים של כל חשבונית. ב. ההוצאות צריכות להתבצע בחודש הפעילות – חודש יולי 2026. במידה וההוצאות רשומות במועדים אחרים יש לצרף הסבר.
A15: העשרה | B15: 1 | C15: כרטסת העשרה – א. כרטסת הנהלת חשבונות נפרדת המכילה את הוצאות העשרה בהתאמה לסכום שדווח בדוח ביצוע. הכרטסת צריכה להכיל את פירוט מהות ההוצאות ושמות הספקים של כל חשבונית. ב. ההוצאות צריכות להתבצע בחודש הפעילות – חודש יולי 2026. במידה וההוצאות רשומות במועדים אחרים יש לצרף הסבר.
A16: ארוחת בוקר | B16: 1 | C16: כרטסת ארוחת בוקר - כרטסת הנהלת חשבונות נפרדת המכילה את ההוצאות שדווחו בדוח ביצוע בגין ארוחת בוקר כהגדרתה בקול קורא – "ארוחת בוקר קלה במימון המסגרת" (לא ממתקים כגון קרטיבים וכד'). הכרטסת צריכה להכיל את פירוט מהות ההוצאות ושמות הספקים של כל חשבונית.
A17: גביה | C17: ברשויות בהן קיימת גביה מההורים נדרש להגיש את המסמכים הבאים:
B18: 1 | C18: כרטסת גביה מההורים - כרטסת הנהלת חשבונות נפרדת המכילה את ההכנסות בגין הכנסות גביה בהתאמה לסכום שדווח בדוח ביצוע.
B19: 2 | C19: כרטסת מלגות – כרטסת הנהלת חשבונות נפרדת המכילה את המלגות שניתנו להורים בהתאמה לסכום שדווח בדוח ביצוע, יש להקפיד על רישום בשיטת הברוטו ובהתאמה לדרישות קול הקורא בנושא.
A20: חשוב מאוד! | B20: 1 | C20: נדרש להעביר את הקבצים בפורמט אקסל.
B21: 2 | C21: יש להעביר קבצים מקוריים מתוכנת השכר או מתוכנת הנהלת חשבונות ולא קבצים מעובדים. (במידת הצורך ניתן להעביר מסמך התאמה).
B22: 3 | C22: נדרש רישום הוצאות או הכנסות בכרטסות נפרדות למוסדות כדלהלן: גנים רשמי – לכלל הגנים יחד (שכר בנפרד העשרה בנפרד וכו', כל כרטסת מכילה את ההוצאות של כל הגנים רשמי בלבד), גנים מוכשר – לכלל הגנים יחד, בתי ספר רשמי – כל בית ספר בנפרד (שכר בנפרד העשרה בנפרד וכו', כל כרטסת מכילה את ההוצאות של כל מוסד בנפרד), בתי ספר מוכשר – כל בית ספר בנפרד.
B23: 4 | C23: יש להקפיד על ניהול ותיעוד אסמכתאות מפורטות ברמת מוסד ככל הניתן.
B24: 5 | C24: במידה והרשות מבצעת את פעילות העשרה או הדרכה באמצעות עובדים חיצוניים (תשלום בחשבונית), יש לצרף בנוסף לכרטסת חשבונית מס או קבלה בגין השירות שניתן. על החשבונית להיות מפורטת וכוללת כמות שעות תאריכים ותעריפים.
B25: 6 | C25: לכל שאלה בנושא אופן הגשת המסמכים יש לפנות למדריכות מטעם משרד החינוך בדוא"ל.

Sheet הנחיות למילוי הדוח
A3: שם גיליון | B3: מס' | C3: הנחיות למילוי דוח הביצוע
A4: כללי | B4: 1 | C4: יש להקפיד למלא את הגיליונות לפי סדר הצגתם בדוח מגיליון 1 עד גיליון 7.
A5: נתונים כלליים (1) | B5: 1 | C5: יש לבחור את שם הרשות מהרשימה הנפתחת.
B6: 2 | C6: יש למלא נתוני אנשי קשר- גזבר ומנהל מחלקת חינוך. לתשומת לב, לכתובות מייל אלו יישלחו המכתבים.
B7: 3 | C7: יש לרשום בגליון את פרטי כל הגופים איתם הרשות התקשרה בהסכמים לביצוע הפעילות כולה או חלקה. בעמודת הערות יש לפרט את הפעילות שבוצעה ע"י כל אחד מהגופים.
B8: 4 | C8: במקרים שישנה בנוסף גם חברה מנהלת (כגון משכ"ל, החברה למשאבי אנוש וכו') יש לציין זאת. במקרים שהרשות מפעילה את הפעילות בעצמה, ומעסיקה את העובדים בתכנית, יש לציין זאת.
A9: מצבת והרשמה (2) | B9: 1 | C9: הגיליון כולו מוזן באופן אוטומטי.
B10: 2 | C10: סמל מוסד של גני ילדים בחטיבות צעירות ידווח כחלק מגני הילדים של הרשות בדו״ח הביצוע של גני הילדים.
A11: דוח ביצוע (3) | B11: 1 | C11: בעמודה B - "סמל בי"ס בו מתקיימת הפעילות" - יש לבחור סמל מוסד מהרשימה הנפתחת. יש להקפיד כי כל סמל מוסד יירשם פעם אחת בלבד.
B12: 2 | C12: יש לבחור מרשימה נפתחת את מפעיל התוכנית.
B13: 3 | C13: בעמודות G ו-H "ביצוע בפועל" - יש למלא את מספר התלמידים עבורם הרשות דורשת תשלום.
B14: 4 | C14: בעמודות L, K "תקופת הפעילות" - יש לרשום את תאריכי הפתיחה והסגירה בבית הספר.
B15: 5 | C15: בעמודה P- יש למלא מס' משתתפים בפועל במסגרת פעילות קיץ פלוס, ד-ו
B16: 6 | C16: בבתי"ס בהם מספר הימים נמוך מ- 15 יש לציין בעמודה Q את הסיבה וכן בעמודה R האם אושר ע"י המשרד. כמו כן בבתי"ס בהם מספר התלמידים נמוך ממינימום משתתפים - 60 תלמידים יש לציין את הסיבה לכך ולצרף את אישור כאסמכתא.
A17: דוח הוצאות בפועל (4) | B17: 1 | C17: בעמודה B - "סמל מוסד מקום הפעילות" - יש לבחור סמל מוסד מהרשימה הנפתחת.
B18: 2 | C18: יש להקפיד ולערוך את הדוח אך ורק עפ"י ההוצאות והנתונים שנכללו במערכת הנהלת החשבונות של הרשות/ המפעיל. יש למלא את מספר הסעיף התקציבי בו נרשמה ההוצאה בכל אחד מהסעיפים בדוח הביצוע הכספי.
B19: 3 | C19: לגבי "מלגות להורים" - יש לרשום את הסכום הכולל שהרשות חילקה להורים כמלגות ושימשו למימון התכנית במקום תשלומי הורים. בכלל זה, גם סכומי המלגות שמתוקצבות ע"י משרד החינוך.
A20: תשלומי הורים ומלגות להורים (5) | B20: 1 | C20: עבור כל סמל מוסד, יש לרשום את סך הגבייה מההורים עבור התכנית.
B21: 2 | C21: הסכום שחולק כמלגות להורים, מועבר מגיליון דוח הוצאות בפועל (4), כאמור לעיל.
B22: 3 | C22: יש למלא בעמודה H את כמות הילדים להם ניתנה מלגה.
B23: 4 | C23: יש למלא בעמודה I את כמות הילדים עבורם בוצעה גביה.
B24: 5 | C24: יש להקפיד ולרשום את מספרי הכרטיסים בהם נרשמו ההכנסות בסעיפים אלו.
A25: עלויות כח אדם (6) | B25: 1 | C25: השורה הראשונה לדיווח (שורה 15 בגיליון מסומנת בצהוב חזק) מיועדת לדיווח עלות השכר של הרכז הרשותי
B26: 2 | C26: בכל שורה בטבלה, יש למלא את התא בעמודה I רק לאחר מילוי התא בעמודה H. בעמודות אלו יש לבחור את סוג איש הצוות ואת התפקיד מתוך הרשימה הנפתחת, סעיפים שיירשמו באופן שונה לא ייכנסו לחישוב התשלום בגיליון (9). יש לשים לב שחלק מהתאים בעמודה I ימולאו באופן אוטומטי ללא צורך בבחירה מתוך הרשימה הנפתחת (התאים ייצבעו בלבן אוטומטית).
B27: 3 | C27: דיווח בגין רכז מוסדי בהתאם לסעיף ג.2 בקול הקורא, ככל שלא ניתן להעסיק את רכז כיתות א-ג במוסד, יהיה ניתן להעסיק רכז ייעודי . ככל שהועסק רכז יעודי יש לדווח את מלוא משרתו, התקציב ינתן בהתאם להנחיות ובעבור 1.5 שעות ליום. במידה ולא הועסק רכז מוסדי ייעודי הדיווח בגינו יעשה בדוח הביצוע לבתי הספר המוגש על ידי הרשות.
A28: סייעות רפואיות או אישיות (7) | B28: 1 | C28: יש למלא סייעות רפואיות או אישיות שהועסקו במהלך הפעילות ומספרי הזהות של התלמידים הזכאים במהלך השנה. לתשומת ליבכם יש לדווח גם בגין העסקת סיעות רפואיות בתוכנית קיץ פלוס שהתקיימה ברשמי ובמוכשר
A29: איוש משרות (8) | B29: 1 | C29: בגיליון זה אין צורך להזין נתונים, נתוני איוש המשרות נלקחים מגיליון 'פירוט עלויות כח אדם (7)', נתוני המוסדות וכמות תלמידים נלקחים מגיליון 'בתי ספר דוח ביצוע (4)' במידה ויש לרשות הערות ניתן לציין בעמודה L.
B30: 2 | C30: שימו לב, בהתאם לסעיף ד.2.ב.ב בקול קורא איוש רכז/ת וסגן/נית רכז/ת הינם תנאי סף לתקצוב התוכנית כולה - ועל כן במידה וישנם מוסדות אשר לא אוישו המשרות הנ"ל כנדרש אין זכאות לתקציב במוסד. יצויין כי הזכאות לתקציב עבור סגן רכז הינה לבתי ספר גדולים - עם מעל 149 ילדים.
A31: תקצוב לפי מוסד (9) | B31: 1 | C31: בגיליון זה אין צורך להזין נתונים, הגיליון כולו מחושב עפ"י הנתונים שמולאו בגיליונות 1-8 כאמור לעיל.

Sheet גנים ובתי ספר- מבנה תקציב
E1: תכנית בתי הספר והגנים של החופש הגדול, קיץ תשפ"ו
E2: חישוב לפי מרכיבי התקצוב והעלויות שפורסמו
A4: א. | B4: מבנה תקציבי גנים
B6: מפתח עלות לתלמיד - כל האשכולות כולל גבייה מהורים
B7: סוג המסגרת | C7: סוג עלות | D7: מספר ימים/תלמידים | E7: סל ניהול ותפעול | F7: סל הדרכה | G7: סל העשרה | H7: סל גמיש | I7: סה"כ
B8: גן רגיל | C8: כוללת למסגרת של 25 תלמידים | D8: 5 | E8: 428 | F8: 3920 | G8: 1400 | H8: 800 | I8: =SUM(E8:H8) -> 6548
D9: משקל יחסי | E9: =E8/$I$8 -> 0.06536347 | F9: =F8/$I$8 -> 0.59865608 | G9: =G8/$I$8 -> 0.21380574 | H9: =H8/$I$8 -> 0.12217471 | I9: =SUM(E9:H9) -> 1
C10: לתלמיד נורמטיבי | D10: לתלמיד ליום | E10: =E8/25/5 -> 3.424 | F10: =F8/25/5 -> 31.36 | G10: =G8/25/5 -> 11.2 | H10: =H8/25/5 -> 6.4 | I10: =I8/25/5 -> 52.384
D11: לתלמיד ל- 15 ימים | E11: =E10*15 -> 51.36 | F11: =F10*15 -> 470.4 | G11: =G10*15 -> 168 | H11: =H10*15 -> 96 | I11: =I8/25*3 -> 785.76
C12: הרחבה | D12: 5 | E12: 497 | F12: 4895 | G12: 1400 | H12: 800 | I12: =SUM(E12:H12) -> 7592
D13: משקל יחסי | E13: =E12/$I$12 -> 0.065463646 | F13: =F12/$I$12 -> 0.64475764 | G13: =G12/$I$12 -> 0.18440464 | H13: =H12/$I$12 -> 0.10537408 | I13: =SUM(E13:H13) -> 1
D14: לתלמיד ליום | E14: =E12/25/5 -> 3.976 | F14: =F12/25/5 -> 39.16 | G14: =G12/25/5 -> 11.2 | H14: =H12/25/5 -> 6.4 | I14: =I12/25/5 -> 60.736
D15: לתלמיד ל- 7 ימים | E15: =E14*7 -> 27.832 | F15: =F14*7 -> 274.12 | G15: =G14*7 -> 78.4 | H15: =H14*7 -> 44.8 | I15: =I14*7 -> 425.152
B18: עלות קבועה לרכזת גנים שאושרה
B19: סוג המסגרת | C19: סוג עלות | D19: מספר ימים | E19: עלות לרכזת | F19: עלות לגן
B20: גנים | C20: שכר עבור ריכוז 5 גנים בהם המובילה איננה גננת, לפי 5 שעות ביום ו- 103.6 ש"ח עלות שעה | D20: 15 | E20: =6*D20*103.6 -> 9324 | F20: =E20/5 -> 1864.8
B22: מפתח השתתפויות לתלמיד גן
B24: מפתח השתתפויות לתלמיד ח. רגיל | G24: =I11 -> 785.76 | H24: =I15 -> 425.152
B25: אשכול למ"ס | C25: גבייה מההורים | D25: גבייה מההורים - הרחבה | E25: סבסוד המשרד - חינוך רגיל | F25: סבסוד המשרד - חינוך רגיל -הרחבה | G25: אחוז הסבסוד חינוך רגיל | H25: אחוז הסבסוד חינוך רגיל-הרחבה
B26: 1 | C26: 75 | D26: 35 | E26: =$G$24-C26 -> 710.76 | F26: =$H$24-D26 -> 390.152 | G26: =1-C26/$G$24 -> 0.90455101 | H26: =1-D26/$H$24 -> 0.9176765
B27: 2 | C27: 75 | D27: 35 | E27: =$G$24-C27 -> 710.76 | F27: =$H$24-D27 -> 390.152 | G27: =1-C27/$G$24 -> 0.90455101 | H27: =1-D27/$H$24 -> 0.9176765
B28: 3 | C28: 75 | D28: 35 | E28: =$G$24-C28 -> 710.76 | F28: =$H$24-D28 -> 390.152 | G28: =1-C28/$G$24 -> 0.90455101 | H28: =1-D28/$H$24 -> 0.9176765
B29: 4 | C29: 75 | D29: 35 | E29: =$G$24-C29 -> 710.76 | F29: =$H$24-D29 -> 390.152 | G29: =1-C29/$G$24 -> 0.90455101 | H29: =1-D29/$H$24 -> 0.9176765
B30: 5 | C30: 300 | D30: 140 | E30: =$G$24-C30 -> 485.76 | F30: =$H$24-D30 -> 285.152 | G30: =1-C30/$G$24 -> 0.61820403 | H30: =1-D30/$H$24 -> 0.67070601
B31: 6 | C31: 300 | D31: 140 | E31: =$G$24-C31 -> 485.76 | F31: =$H$24-D31 -> 285.152 | G31: =1-C31/$G$24 -> 0.61820403 | H31: =1-D31/$H$24 -> 0.67070601
B32: 7 | C32: 300 | D32: 140 | E32: =$G$24-C32 -> 485.76 | F32: =$H$24-D32 -> 285.152 | G32: =1-C32/$G$24 -> 0.61820403 | H32: =1-D32/$H$24 -> 0.67070601
B33: 8 | C33: 450 | D33: 210 | E33: =$G$24-C33 -> 335.76 | F33: =$H$24-D33 -> 215.152 | G33: =1-C33/$G$24 -> 0.42730605 | H33: =1-D33/$H$24 -> 0.50605901
B34: 9 | C34: 450 | D34: 210 | E34: =$G$24-C34 -> 335.76 | F34: =$H$24-D34 -> 215.152 | G34: =1-C34/$G$24 -> 0.42730605 | H34: =1-D34/$H$24 -> 0.50605901
B35: 10 | C35: 450 | D35: 210 | E35: =$G$24-C35 -> 335.76 | F35: =$H$24-D35 -> 215.152 | G35: =1-C35/$G$24 -> 0.42730605 | H35: =1-D35/$H$24 -> 0.50605901
A37: ב. | B37: מבנה תקציבי בתי ספר
B39: בית ספר - עלות לתלמיד
B40: מפתח עלות לתלמיד - כל האשכולות כולל גבייה מהורים
B41: סוג המסגרת | C41: סוג עלות | D41: מספר ימים | E41: סל ניהול ותפעול | F41: סל הדרכה | G41: סל העשרה | H41: סל גמיש | I41: סה"כ
B42: בי"ס רגיל | C42: כוללת למסגרת של 28 תלמידים | D42: 5 | E42: 396 | F42: 3108 | G42: 1550 | H42: 1000 | I42: =SUM(E42:H42) -> 6054
D43: משקל יחסי | E43: =E42/$I$42 -> 0.065411298 | F43: =F42/$I$42 -> 0.51337958 | G43: =G42/$I$42 -> 0.25602907 | H43: =H42/$I$42 -> 0.16518005 | I43: =SUM(E43:H43) -> 1
C44: לפי תלמיד נורמטיבי לתקופה | D44: לתלמיד ליום | E44: =E43*$I$44 -> 2.8285714 | F44: =F43*$I$44 -> 22.2 | G44: =G43*$I$44 -> 11.071429 | H44: =H43*$I$44 -> 7.1428571 | I44: =I42/28/5 -> 43.242857
D45: לתלמיד ל- 15 ימים | E45: =E43*$I$45 -> 42.428571 | F45: =F43*$I$45 -> 333 | G45: =G43*$I$45 -> 166.07143 | H45: =H43*$I$45 -> 107.14286 | I45: =I42/28*3 -> 648.64286
D46: לתלמיד ל- 7 ימים | E46: =E44*7 -> 19.8 | F46: =F44*7 -> 155.4 | G46: =G44*7 -> 77.5 | H46: =H44*7 -> 50 | I46: =SUM(E46:H46) -> 302.7
B47: בי"ס חנ"מ | C47: כוללת למסגרת של 8 תלמידים | D47: 5 | E47: 324 | F47: 3108 | G47: 1215 | H47: 300 | I47: =SUM(E47:H47) -> 4947
D48: משקל יחסי | E48: =E47/$I$47 -> 0.065494239 | F48: =F47/$I$47 -> 0.62825955 | G48: =G47/$I$47 -> 0.2456034 | H48: =H47/$I$47 -> 0.060642814 | I48: =SUM(E48:H48) -> 1
...

Sheet נתונים כלליים (1)
A1: תוכן העניינים | C1: ='גנים ובתי ספר- מבנה תקציב'!$E$1 -> תכנית בתי הספר והגנים של החופש הגדול, קיץ תשפ"ו
B3: נתונים כללים
E4: =IF(AND(E5=" ",E6=" ",E7=" ")," ","שגיאות בגיליון:") -> שגיאות בגיליון:
B5: שם הרשות המקומית | C5: באר טוביה | E5: =IF(ISBLANK(C5),"יש לבחור את שם הרשות מהרשימה הנפתחת"," ") -> יש לבחור את שם הרשות מהרשימה הנפתחת
B6: מספר אשכול למ"ס | C6: =IFERROR(VLOOKUP($C$5,'רשימת רשויות'!A:B,2,0),"") | E6: =IF(F13="","יש למלא נתוני אנשי קשר ברשות"," ") -> יש למלא נתוני אנשי קשר ברשות
B7: תעריף לילד חלק ההורים - ש"ח | C7: =IFERROR(VLOOKUP(C6,'גנים ובתי ספר- מבנה תקציב'!$B$81:$H$90,2),0) -> 0 | E7: {=IF(טבלה22[שם הגוף המפעיל ו/או מעסיק את העובדים]="","יש למלא נתוני מפעילי התכנית"," ")} -> יש למלא נתוני מפעילי התכנית
B10: אנשי קשר ברשות
B12: תפקיד | C12: שם פרטי | D12: שם משפחה | E12: טלפון | F12: מייל
B13: גזבר | C13: ענבל | D13: ברמי | F13: inbalb@beer-tuvia.org.il
B14: מנהלת מחלקת חינוך | C14: דורון | D14: חנין | F14: doronh@beer-tuvia.org.il
A15: אנשי קשר נוספים:
B18: מפעילי התכנית
A19: מס' סידורי | B19: שם הגוף המפעיל ו/או מעסיק את העובדים | C19: מספר עמותה/ חברה/ עוסק | D19: מפתח חלוקה בין מפעילים | E19: פרטי חברה מנהלת | F19: הערות
A20: 1 | B20: אמיתי לוי יזמות בע"מ | C20: 516498417 | F20: קייטנת בוקר
A21: 2
A22: 3
A23: 4
A24: 5
A25: 6
A26: 7
A27: 8
A28: 9
A29: 10
A30: 11
A31: 12
A32: 13
... A49: 30

Sheet מצבת והרשמה (2)
A1: תוכן העניינים | F1: ='גנים ובתי ספר- מבנה תקציב'!$E$1 -> תכנית בתי הספר והגנים של החופש הגדול, קיץ תשפ"ו
D4: שם הרשות המקומית | F4: ='נתונים כלליים (1)'!$C$5 -> 0
D5: סוג מוסד | F5: בתי ספר
D6: מספר אשכול למ"ס | F6: ='נתונים כלליים (1)'!$C$6
D8: בגיליון זה אין צורך להזין נתונים!
F9: נתוני מצבת תלמידים והרשמה
D11: סיכום | E11: מספר בתי"ס במצבת | F11: מס' תלמידי א-ג במצבת | H11: מס' בתי"ס גדולים - 150 תלמידים ומעלה | I11: מס' בתי"ס בהם מתקיימת פעילות | K11: מס' תלמידים רשומים | M11: מס' בתי"ס גדולים - 150 תלמידים ומעלה
F12: חינוך רגיל | G12: חינוך מיוחד | J12: חינוך רגיל | K12: חינוך מיוחד | L12: סה"כ תלמידים שנרשמו
E13: =COUNTIF(מוסדות,">1") -> 0 | F13: =SUM($G$21:$G$520) -> 0 | G13: =SUM($H$21:$H$520) -> 0 | H13: =COUNTIF($I$21:I$520,">149") -> 0 | I13: =SUM(IF(FREQUENCY($F$21:$F$520,$F$21:$F$520)>0,1)) -> 0 | J13: =SUM($J$21:$J$520) -> 0 | K13: =SUM($K$21:$K$520) -> 0 | L13: =K13+J13 -> 0 | M13: =COUNTIF($L$21:L$520,">149") -> 0
H15: במידה ונתוני הרישום הרשומים בקובץ אינם תואמים לנתונים המאושרים על ידי משה"ח,
H16: יש לרשום מייל מפורט לכתובת: hofesh-gadol26@cdk-cpa.co.il
E19: נתונים כללים | H19: נתוני מצבת | J19: נתוני רישום (01.07.26-21.07.26)
B20: מס' סידורי | C20: סמל בית ספר | D20: שם בית הספר | E20: מעמד - רשמי/ מוכש"ר | F20: סמל בית ספר בו מתקיימת הפעילות | G20: סה"כ תלמידי חינוך רגיל א-ג במצבת | H20: סה"כ תלמידי חינוך מיוחד א-ג במצבת | I20: סה"כ תלמידים במצבת | J20: סה"כ תלמידי חינוך רגיל שנרשמו | K20: סה"כ תלמידי חינוך מיוחד שנרשמו | L20: סה"כ תלמידים שנרשמו | M20: האם בי"ס גדול - 150 תלמידים ומעלה
B21: 1 | C21: {=IFERROR( INDEX('נתוני רישום ומצבת'!$B:$B, SMALL( IF(('נתוני רישום ומצבת'!A$2:A$2998='נתונים כלליים (1)'!$C$5), ROW('נתוני רישום ומצבת'!A$2:A$2998)), ROW(A1)) ), "")} -> 0 | D21: =IF(C21="", "", IFERROR( IF(VLOOKUP(C21, 'נתוני רישום ומצבת'!B:J, 9, FALSE) = $F$4, VLOOKUP(C21, 'נתוני רישום ומצבת'!B:J, 3, FALSE), "המוסד לא קיים ברשות"), "המוסד לא קיים")) -> המוסד לא קיים | E21: =IFERROR(VLOOKUP(C21,'נתוני רישום ומצבת'!B:G,6,0),"") | F21: =IFERROR(VLOOKUP(C21,'נתוני רישום ומצבת'!B:K,10,0)," ") | G21: =IFERROR(VLOOKUP(C21,'נתוני רישום ומצבת'!B:E,4,0)," ") | H21: =IFERROR(VLOOKUP(C21,'נתוני רישום ומצבת'!B:K,7,0),"") | I21: =IFERROR(H21+G21,"") | J21: =IFERROR(VLOOKUP(C21,'נתוני רישום ומצבת'!B:I,5,0)," ") | K21: =IFERROR(VLOOKUP(C21,'נתוני רישום ומצבת'!B:I,8,0),"") | L21: =IFERROR(K21+J21,0) -> 0 | M21: =IF(L21>149,"כן","-") -> -
B22: 2 | C22: {=IFERROR( INDEX('נתוני רישום ומצבת'!$B:$B, SMALL( IF(('נתוני רישום ומצבת'!A$2:A$2998='נתונים כלליים (1)'!$C$5), ROW('נתוני רישום ומצבת'!A$2:A$2998)), ROW(A2)) ), "")} -> 0 | D22: =IF(C22="", "", IFERROR( IF(VLOOKUP(C22, 'נתוני רישום ומצבת'!B:J, 9, FALSE) = $F$4, VLOOKUP(C22, 'נתוני רישום ומצבת'!B:J, 3, FALSE), "המוסד לא קיים ברשות"), "המוסד לא קיים")) -> המוסד לא קיים | E22: =IFERROR(VLOOKUP(C22,'נתוני רישום ומצבת'!B:G,6,0),"") | F22: =IFERROR(VLOOKUP(C22,'נתוני רישום ומצבת'!B:K,10,0)," ") | G22: =IFERROR(VLOOKUP(C22,'נתוני רישום ומצבת'!B:E,4,0)," ") | H22: =IFERROR(VLOOKUP(C22,'נתוני רישום ומצבת'!B:K,7,0),"") | I22: =IFERROR(H22+G22,"") | J22: =IFERROR(VLOOKUP(C22,'נתוני רישום ומצבת'!B:I,5,0)," ") | K22: =IFERROR(VLOOKUP(C22,'נתוני רישום ומצבת'!B:I,8,0),"") | L22: =IFERROR(K22+J22,0) -> 0 | M22: =IF(L22>149,"כן","-") -> -
B23: 3 | C23: {=IFERROR( INDEX('נתוני רישום ומצבת'!$B:$B, SMALL( IF(('נתוני רישום ומצבת'!A$2:A$2998='נתונים כלליים (1)'!$C$5), ROW('נתוני רישום ומצבת'!A$2:A$2998)), ROW(A3)) ), "")} -> 0 | D23: =IF(C23="", "", IFERROR( IF(VLOOKUP(C23, 'נתוני רישום ומצבת'!B:J, 9, FALSE) = $F$4, VLOOKUP(C23, 'נתוני רישום ומצבת'!B:J, 3, FALSE), "המוסד לא קיים ברשות"), "המוסד לא קיים")) -> המוסד לא קיים | E23: =IFERROR(VLOOKUP(C23,'נתוני רישום ומצבת'!B:G,6,0),"") | F23: =IFERROR(VLOOKUP(C23,'נתוני רישום ומצבת'!B:K,10,0)," ") | G23: =IFERROR(VLOOKUP(C23,'נתוני רישום ומצבת'!B:E,4,0)," ") | H23: =IFERROR(VLOOKUP(C23,'נתוני רישום ומצבת'!B:K,7,0),"") | I23: =IFERROR(H23+G23,"") | J23: =IFERROR(VLOOKUP(C23,'נתוני רישום ומצבת'!B:I,5,0)," ") | K23: =IFERROR(VLOOKUP(C23,'נתוני רישום ומצבת'!B:I,8,0),"") | L23: =IFERROR(K23+J23,0) -> 0 | M23: =IF(L23>149,"כן","-") -> -
B24: 4 | C24: {=IFERROR( INDEX('נתוני רישום ומצבת'!$B:$B, SMALL( IF(('נתוני רישום ומצבת'!A$2:A$2998='נתונים כלליים (1)'!$C$5), ROW('נתוני רישום ומצבת'!A$2:A$2998)), ROW(A4)) ), "")} -> 0 | D24: =IF(C24="", "", IFERROR( IF(VLOOKUP(C24, 'נתוני רישום ומצבת'!B:J, 9, FALSE) = $F$4, VLOOKUP(C24, 'נתוני רישום ומצבת'!B:J, 3, FALSE), "המוסד לא קיים ברשות"), "המוסד לא קיים")) -> המוסד לא קיים | E24: =IFERROR(VLOOKUP(C24,'נתוני רישום ומצבת'!B:G,6,0),"") | F24: =IFERROR(VLOOKUP(C24,'נתוני רישום ומצבת'!B:K,10,0)," ") | G24: =IFERROR(VLOOKUP(C24,'נתוני רישום ומצבת'!B:E,4,0)," ") | H24: =IFERROR(VLOOKUP(C24,'נתוני רישום ומצבת'!B:K,7,0),"") | I24: =IFERROR(H24+G24,"") | J24: =IFERROR(VLOOKUP(C24,'נתוני רישום ומצבת'!B:I,5,0)," ") | K24: =IFERROR(VLOOKUP(C24,'נתוני רישום ומצבת'!B:I,8,0),"") | L24: =IFERROR(K24+J24,0) -> 0 | M24: =IF(L24>149,"כן","-") -> -
B25: 5 | C25: {=IFERROR( INDEX('נתוני רישום ומצבת'!$B:$B, SMALL( IF(('נתוני רישום ומצבת'!A$2:A$2998='נתונים כלליים (1)'!$C$5), ROW('נתוני רישום ומצבת'!A$2:A$2998)), ROW(A5)) ), "")} -> 0 | D25: =IF(C25="", "", IFERROR( IF(VLOOKUP(C25, 'נתוני רישום ומצבת'!B:J, 9, FALSE) = $F$4, VLOOKUP(C25, 'נתוני רישום ומצבת'!B:J, 3, FALSE), "המוסד לא קיים ברשות"), "המוסד לא קיים")) -> המוסד לא קיים | E25: =IFERROR(VLOOKUP(C25,'נתוני רישום ומצבת'!B:G,6,0),"") | F25: =IFERROR(VLOOKUP(C25,'נתוני רישום ומצבת'!B:K,10,0)," ") | G25: =IFERROR(VLOOKUP(C25,'נתוני רישום ומצבת'!B:E,4,0)," ") | H25: =IFERROR(VLOOKUP(C25,'נתוני רישום ומצבת'!B:K,7,0),"") | I25: =IFERROR(H25+G25,"") | J25: =IFERROR(VLOOKUP(C25,'נתוני רישום ומצבת'!B:I,5,0)," ") | K25: =IFERROR(VLOOKUP(C25,'נתוני רישום ומצבת'!B:I,8,0),"") | L25: =IFERROR(K25+J25,0) -> 0 | M25: =IF(L25>149,"כן","-") -> -
B26: 6 | C26: {=IFERROR( INDEX('נתוני רישום ומצבת'!$B:$B, SMALL( IF(('נתוני רישום ומצבת'!A$2:A$2998='נתונים כלליים (1)'!$C$5), ROW('נתוני רישום ומצבת'!A$2:A$2998)), ROW(A6)) ), "")} -> 0 | D26: =IF(C26="", "", IFERROR( IF(VLOOKUP(C26, 'נתוני רישום ומצבת'!B:J, 9, FALSE) = $F$4, VLOOKUP(C26, 'נתוני רישום ומצבת'!B:J, 3, FALSE), "המוסד לא קיים ברשות"), "המוסד לא קיים")) -> המוסד לא קיים | E26: =IFERROR(VLOOKUP(C26,'נתוני רישום ומצבת'!B:G,6,0),"") | F26: =IFERROR(VLOOKUP(C26,'נתוני רישום ומצבת'!B:K,10,0)," ") | G26: =IFERROR(VLOOKUP(C26,'נתוני רישום ומצבת'!B:E,4,0)," ") | H26: =IFERROR(VLOOKUP(C26,'נתוני רישום ומצבת'!B:K,7,0),"") | I26: =IFERROR(H26+G26,"") | J26: =IFERROR(VLOOKUP(C26,'נתוני רישום ומצבת'!B:I,5,0)," ") | K26: =IFERROR(VLOOKUP(C26,'נתוני רישום ומצבת'!B:I,8,0),"") | L26: =IFERROR(K26+J26,0) -> 0 | M26: =IF(L26>149,"כן","-") -> -
B27: 7 | C27: {=IFERROR( INDEX('נתוני רישום ומצבת'!$B:$B, SMALL( IF(('נתוני רישום ומצבת'!A$2:A$2998='נתונים כלליים (1)'!$C$5), ROW('נתוני רישום ומצבת'!A$2:A$2998)), ROW(A7)) ), "")} -> 0 | D27: =IF(C27="", "", IFERROR( IF(VLOOKUP(C27, 'נתוני רישום ומצבת'!B:J, 9, FALSE) = $F$4, VLOOKUP(C27, 'נתוני רישום ומצבת'!B:J, 3, FALSE), "המוסד לא קיים ברשות"), "המוסד לא קיים")) -> המוסד לא קיים | E27: =IFERROR(VLOOKUP(C27,'נתוני רישום ומצבת'!B:G,6,0),"") | F27: =IFERROR(VLOOKUP(C27,'נתוני רישום ומצבת'!B:K,10,0)," ") | G27: =IFERROR(VLOOKUP(C27,'נתוני רישום ומצבת'!B:E,4,0)," ") | H27: =IFERROR(VLOOKUP(C27,'נתוני רישום ומצבת'!B:K,7,0),"") | I27: =IFERROR(H27+G27,"") | J27: =IFERROR(VLOOKUP(C27,'נתוני רישום ומצבת'!B:I,5,0)," ") | K27: =IFERROR(VLOOKUP(C27,'נתוני רישום ומצבת'!B:I,8,0),"") | L27: =IFERROR(K27+J27,0) -> 0 | M27: =IF(L27>149,"כן","-") -> -
B28: 8 | C28: {=IFERROR( INDEX('נתוני רישום ומצבת'!$B:$B, SMALL( IF(('נתוני רישום ומצבת'!A$2:A$2998='נתונים כלליים (1)'!$C$5), ROW('נתוני רישום ומצבת'!A$2:A$2998)), ROW(A8)) ), "")} -> 0 | D28: =IF(C28="", "", IFERROR( IF(VLOOKUP(C28, 'נתוני רישום ומצבת'!B:J, 9, FALSE) = $F$4, VLOOKUP(C28, 'נתוני רישום ומצבת'!B:J, 3, FALSE), "המוסד לא קיים ברשות"), "המוסד לא קיים")) -> המוסד לא קיים | E28: =IFERROR(VLOOKUP(C28,'נתוני רישום ומצבת'!B:G,6,0),"") | F28: =IFERROR(VLOOKUP(C28,'נתוני רישום ומצבת'!B:K,10,0)," ") | G28: =IFERROR(VLOOKUP(C28,'נתוני רישום ומצבת'!B:E,4,0)," ") | H28: =IFERROR(VLOOKUP(C28,'נתוני רישום ומצבת'!B:K,7,0),"") | I28: =IFERROR(H28+G28,"") | J28: =IFERROR(VLOOKUP(C28,'נתוני רישום ומצבת'!B:I,5,0)," ") | K28: =IFERROR(VLOOKUP(C28,'נתוני רישום ומצבת'!B:I,8,0),"") | L28: =IFERROR(K28+J28,0) -> 0 | M28: =IF(L28>149,"כן","-") -> -
B29: 9 | C29: {=IFERROR( INDEX('נתוני רישום ומצבת'!$B:$B, SMALL( IF(('נתוני רישום ומצבת'!A$2:A$2998='נתונים כלליים (1)'!$C$5), ROW('נתוני רישום ומצבת'!A$2:A$2998)), ROW(A9)) ), "")} -> 0 | D29: =IF(C29="", "", IFERROR( IF(VLOOKUP(C29, 'נתוני רישום ומצבת'!B:J, 9, FALSE) = $F$4, VLOOKUP(C29, 'נתוני רישום ומצבת'!B:J, 3, FALSE), "המוסד לא קיים ברשות"), "המוסד לא קיים")) -> המוסד לא קיים | E29: =IFERROR(VLOOKUP(C29,'נתוני רישום ומצבת'!B:G,6,0),"") | F29: =IFERROR(VLOOKUP(C29,'נתוני רישום ומצבת'!B:K,10,0)," ") | G29: =IFERROR(VLOOKUP(C29,'נתוני רישום ומצבת'!B:E,4,0)," ") | H29: =IFERROR(VLOOKUP(C29,'נתוני רישום ומצבת'!B:K,7,0),"") | I29: =IFERROR(H29+G29,"") | J29: =IFERROR(VLOOKUP(C29,'נתוני רישום ומצבת'!B:I,5,0)," ") | K29: =IFERROR(VLOOKUP(C29,'נתוני רישום ומצבת'!B:I,8,0),"") | L29: =IFERROR(K29+J29,0) -> 0 | M29: =IF(L29>149,"כן","-") -> -
B30: 10 | C30: {=IFERROR( INDEX('נתוני רישום ומצבת'!$B:$B, SMALL( IF(('נתוני רישום ומצבת'!A$2:A$2998='נתונים כלליים (1)'!$C$5), ROW('נתוני רישום ומצבת'!A$2:A$2998)), ROW(A10)) ), "")} -> 0 | D30: =IF(C30="", "", IFERROR( IF(VLOOKUP(C30, 'נתוני רישום ומצבת'!B:J, 9, FALSE) = $F$4, VLOOKUP(C30, 'נתוני רישום ומצבת'!B:J, 3, FALSE), "המוסד לא קיים ברשות"), "המוסד לא קיים")) -> המוסד לא קיים | E30: =IFERROR(VLOOKUP(C30,'נתוני רישום ומצבת'!B:G,6,0),"") | F30: =IFERROR(VLOOKUP(C30,'נתוני רישום ומצבת'!B:K,10,0)," ") | G30: =IFERROR(VLOOKUP(C30,'נתוני רישום ומצבת'!B:E,4,0)," ") | H30: =IFERROR(VLOOKUP(C30,'נתוני רישום ומצבת'!B:K,7,0),"") | I30: =IFERROR(H30+G30,"") | J30: =IFERROR(VLOOKUP(C30,'נתוני רישום ומצבת'!B:I,5,0)," ") | K30: =IFERROR(VLOOKUP(C30,'נתוני רישום ומצבת'!B:I,8,0),"") | L30: =IFERROR(K30+J30,0) -> 0 | M30: =IF(L30>149,"כן","-") -> -
B31: 11 | C31: {=IFERROR( INDEX('נתוני רישום ומצבת'!$B:$B, SMALL( IF(('נתוני רישום ומצבת'!A$2:A$2998='נתונים כלליים (1)'!$C$5), ROW('נתוני רישום ומצבת'!A$2:A$2998)), ROW(A11)) ), "")} -> 0 | D31: =IF(C31="", "", IFERROR( IF(VLOOKUP(C31, 'נתוני רישום ומצבת'!B:J, 9, FALSE) = $F$4, VLOOKUP(C31, 'נתוני רישום ומצבת'!B:J, 3, FALSE), "המוסד לא קיים ברשות"), "המוסד לא קיים")) -> המוסד לא קיים | E31: =IFERROR(VLOOKUP(C31,'נתוני רישום ומצבת'!B:G,6,0),"") | F31: =IFERROR(VLOOKUP(C31,'נתוני רישום ומצבת'!B:K,10,0)," ") | G31: =IFERROR(VLOOKUP(C31,'נתוני רישום ומצבת'!B:E,4,0)," ") | H31: =IFERROR(VLOOKUP(C31,'נתוני רישום ומצבת'!B:K,7,0),"") | I31: =IFERROR(H31+G31,"") | J31: =IFERROR(VLOOKUP(C31,'נתוני רישום ומצבת'!B:I,5,0)," ") | K31: =IFERROR(VLOOKUP(C31,'נתוני רישום ומצבת'!B:I,8,0),"") | L31: =IFERROR(K31+J31,0) -> 0 | M31: =IF(L31>149,"כן","-") -> -
B32: 12 | C32: {=IFERROR( INDEX('נתוני רישום ומצבת'!$B:$B, SMALL( IF(('נתוני רישום ומצבת'!A$2:A$2998='נתונים כלליים (1)'!$C$5), ROW('נתוני רישום ומצבת'!A$2:A$2998)), ROW(A12)) ), "")} -> 0 | D32: =IF(C32="", "", IFERROR( IF(VLOOKUP(C32, 'נתוני רישום ומצבת'!B:J, 9, FALSE) = $F$4, VLOOKUP(C32, 'נתוני רישום ומצבת'!B:J, 3, FALSE), "המוסד לא קיים ברשות"), "המוסד לא קיים")) -> המוסד לא קיים | E32: =IFERROR(VLOOKUP(C32,'נתוני רישום ומצבת'!B:G,6,0),"") | F32: =IFERROR(VLOOKUP(C32,'נתוני רישום ומצבת'!B:K,10,0)," ") | G32: =IFERROR(VLOOKUP(C32,'נתוני רישום ומצבת'!B:E,4,0)," ") | H32: =IFERROR(VLOOKUP(C32,'נתוני רישום ומצבת'!B:K,7,0),"") | I32: =IFERROR(H32+G32,"") | J32: =IFERROR(VLOOKUP(C32,'נתוני רישום ומצבת'!B:I,5,0)," ") | K32: =IFERROR(VLOOKUP(C32,'נתוני רישום ומצבת'!B:I,8,0),"") | L32: =IFERROR(K32+J32,0) -> 0 | M32: =IF(L32>149,"כן","-") -> -
... B520: 500 | C520: {=IFERROR( INDEX('נתוני רישום ומצבת'!$B:$B, SMALL( IF(('נתוני רישום ומצבת'!A$2:A$2998='נתונים כלליים (1)'!$C$5), ROW('נתוני רישום ומצבת'!A$2:A$2998)), ROW(A500)) ), "")} | D520: =IF(C520="", "", IFERROR( IF(VLOOKUP(C520, 'נתוני רישום ומצבת'!B:J, 9, FALSE) = $F$4, VLOOKUP(C520, 'נתוני רישום ומצבת'!B:J, 3, FALSE), "המוסד לא קיים ברשות"), "המוסד לא קיים")) | E520: =IFERROR(VLOOKUP(C520,'נתוני רישום ומצבת'!B:G,6,0),"") | F520: =IFERROR(VLOOKUP(C520,'נתוני רישום ומצבת'!B:K,10,0)," ") | G520: =IFERROR(VLOOKUP(C520,'נתוני רישום ומצבת'!B:E,4,0)," ") | H520: =IFERROR(VLOOKUP(C520,'נתוני רישום ומצבת'!B:K,7,0),"") | I520: =IFERROR(H520+G520,"") | J520: =IFERROR(VLOOKUP(C520,'נתוני רישום ומצבת'!B:I,5,0)," ") | K520: =IFERROR(VLOOKUP(C520,'נתוני רישום ומצבת'!B:I,8,0),"") | L520: =IFERROR(K520+J520,0) -> 0 | M520: =IF(L520>149,"כן","-") -> -

Sheet דוח ביצוע (3)
A1: תוכן העניינים | H1: ='גנים ובתי ספר- מבנה תקציב'!$E$1 -> תכנית בתי הספר והגנים של החופש הגדול, קיץ תשפ"ו | N1: * | S1: * | T1: * | U1: * | AA1: * | AB1: * | AD1: * | AE1: * | AF1: * | AG1: * | AH1: * | AI1: * | AJ1: *
S2: תנאי סף לתקצוב: 0=לפרסום, 1=פעיל | T2: 0
E3: שם הרשות המקומית | H3: ='נתונים כלליים (1)'!$C$5 -> 0 | L3: =IF(AND(L4="",L5="",L6="")," ","שגיאות בגיליון:")
E4: סוג מוסד | H4: בתי ספר | L4: {=IF(SUMPRODUCT((COUNTIF(B21:B520,B21:B520)>1)/IF(B21:B520="",1,COUNTIF(B21:B520,B21:B520)))>0,CONCATENATE("קיימים ",SUMPRODUCT((COUNTIF(B21:B520,B21:B520)>1)/IF(B21:B520="",1,COUNTIF(B21:B520,B21:B520)))," מוסדות שמופיעים יותר מפעם אחת בדיווח."),"")}
E5: מספר אשכול למ"ס | H5: ='נתונים כלליים (1)'!$C$6 | L5: =IF(SUM($AB$21:$AB$520)>0,CONCATENATE(" קיימים ",SUM($AB$21:$AB$520)," מוסדות בהם לא מולאו נתונים לגבי מספר התלמידים שהשתתפו בתוכנית."),"")
L6: =IF(SUM($Z$21:$Z$520)>0,CONCATENATE(" קיימים ",SUM($Z$21:$Z$520)," מוסדות בהם לא מולאו נתונים לגבי תקופת הפעילות."),"")
H7: דוח ביצוע מפורט לפי תלמידים | Z7: * | AA7: * | AB7: * | AC7: * | AD7: * | AE7: * | AF7: * | AG7: * | AH7: * | AI7: * | AJ7: *
H8: ריכוז לפי בתי הספר בהם מופעלת התכנית
C10: סיכום
D11: נתוני הרשמה מגליון מצבת והרשמה (2) | G11: ביצוע בפועל | K11: נתונים לחישוב תקציב
C12: מס' בתי"ס בהם מתקיימת פעילות | D12: מס' תלמידים רשומים חינוך רגיל | E12: מס' תלמידים רשומים חינוך מיוחד | F12: סה"כ תלמידים בביה"ס | G12: מס' תלמידים מדווחים חינוך רגיל | H12: מס' תלמידים מדווחים חינוך מיוחד | I12: סה"כ תלמידים בביה"ס | J12: בתי ספר גדולים | K12: מס' תלמידים חינוך רגיל | L12: מס' תלמידים חינוך מיוחד | M12: סה"כ מס' תלמידים
C13: =SUM(IF(FREQUENCY(B21:$B$520,B21:$B$520)>0,1)) -> 0 | D13: =SUM(D21:D520) -> 0 | E13: =SUM(E21:E520) -> 0 | F13: =SUM(F21:F520) -> 0 | G13: =SUM(G21:G520) -> 0 | H13: =SUM(H21:H520) -> 0 | I13: =SUM(I21:I520) -> 0 | J13: =SUM(J21:J520) -> 0 | K13: =SUM(S21:S520) -> 0 | L13: =SUM(T21:T520) -> 0 | M13: =SUM(U21:U520) -> 0
B15: לתשומת ליבכם, סמל מוסד של גני ילדים בחטיבות צעירות ידווח כחלק מגני הילדים של הרשות בדו״ח הביצוע של גני הילדים.
C17: דוח ביצוע מפורט | AC17: לעדכן
B19: נתוני הרשמה מגליון מצבת והרשמה (2) | G19: ביצוע בפועל | K19: תקופת הפעילות | O19: קיץ פלוס | S19: נתונים לחישוב תקציב | W19: בקרות - יש לוודא כי לא קיימות שורות עם התראה | AC19: נתוני בקרות שטח
A20: מס' סידורי | B20: סמל בית ספר בו מתקיימת הפעילות לפי נתוני הרשמה | C20: מפעיל התכנית | D20: מס' תלמידים רשומים חינוך רגיל | E20: מס' תלמידים רשומים חינוך מיוחד | F20: סה"כ תלמידים בביה"ס | G20: מס' תלמידים חינוך רגיל | H20: מס' תלמידים חינוך מיוחד | I20: סה"כ תלמידים בביה"ס | J20: בתי ספר גדולים | K20: תאריך פתיחה | L20: תאריך סיום | M20: מספר ימי פעילות בפועל | N20: בדיקת תנאי סף לקיום מלוא ימי הפעילות | O20: מס' תלמידים במצבת חינוך ד-ו | P20: מס' תלמידים רשומים חינוך ד-ו | Q20: מס' תלמידים משתתפים בפועל ד-ו | S20: מס' תלמידים חינוך רגיל | T20: מס' תלמידים חינוך מיוחד | U20: סה"כ מס' תלמידים | V20: בקרת מילוי מס' ימי פעילות - עמודה M | W20: בקרת סמלי מוסדות - האם קיים כמוסד בו מתבצעת פעילות? | X20: בקרת סמלי בתי"ס - עמודה B | Y20: בקרת שורות ריקות - עמודה B | Z20: בקרת מילוי מס' ימי פעילות | AA20: בקרת כפילות מילוי מוסדות | AB20: בקרת אי מילוי תלמידים | AC20: ממוצע ח.ר | AD20: ממוצע ח.מ | AE20: סיבה לאי ביצוע בקרה | AF20: האם הופעל קיץ פלוס בבית הספר? | AG20: תוספת תקצוב רכז בית ספר ד-ו | AH20: תוספת תקצוב תקורה רכז בית ספר ד-ו | AI20: סה"כ | AJ20: האם פעלו פחות מ-15 יום
A21: 1 | D21: =(IFERROR(SUMIF('מצבת והרשמה (2)'!$F$21:$F$501,'דוח ביצוע (3)'!$B21,'מצבת והרשמה (2)'!$J$21:$J$501),0)) -> 0 | E21: =IFERROR(SUMIF('מצבת והרשמה (2)'!$F$21:$F$501,'דוח ביצוע (3)'!$B21,'מצבת והרשמה (2)'!$K$21:$K$501),0) -> 0 | F21: =E21+D21 -> 0 | I21: =H21+G21 -> 0 | J21: =IF(F21>149,1,0) -> 0 | M21: =MIN(NETWORKDAYS.INTL(K21,L21,7),15) -> 0 | N21: =IF(B21>0,IF(M21<15,"תקופת הפעילות נמוכה מהתקופה הנדרשת, ועל כן המוסד אינו זכאי לתקצוב","תקין"),"") | O21: =IFERROR(VLOOKUP(B21,'נתוני רישום ומצבת'!B:Q,16,0),"") | P21: =IFERROR(VLOOKUP(B21,'נתוני רישום ומצבת'!B:R,17,0),0) -> 0 | S21: =IF(OR($T$2=0,N21="תקין"),MAX(IF(G21="",0,MIN(G21,D21)),0),0) -> 0 | T21: =IF(OR($T$2=0,N21="תקין"),MAX(IF(H21="",0,MIN(H21,E21)),0),0) -> 0 | U21: =SUM(S21:T21) -> 0 | V21: =IF(ISNUMBER(B21),IF(M21<1,"יש למלא מס' ימי פעילות",IF(M21<15,"יש למלא סיבה לחוסר ימי פעילות","תקין")),"") | W21: =IF(ISBLANK(B21)," ",IF(B21=IFERROR(VLOOKUP(B21,'מצבת והרשמה (2)'!F:F,1,0),0),"תקין","לא קיים במצבת כבית ספר בו מתקיימת פעילות")) | X21: =IF(IFERROR(COUNTIF($C$20:$C$2460,B21)," ")>1,"סמל המוסד מופיע יותר מפעם אחת",IF(ISBLANK(B21),"","תקין")) | Y21: =IF(AND(ISNUMBER(B21),ISBLANK(B20)),"יש למלא שורות רצופות","") | Z21: =IF(OR(LEFT(V21,10)="יש למלא מס",LEFT(V21,10)="יש למלא סי"),1,0) -> 0 | AA21: =IF(COUNTIF(סמלפעילות,B21)>1,1,0) -> 0 | AB21: =IF(B21>0,IF(I21=0,1,0),0) -> 0 | AC21: =MAX(IF(G21=" ",0,MIN(G21,D21)),0) -> 0 | AD21: =MAX(IF(H21=" ",0,MIN(H21,E21)),0) -> 0 | AE21: =IFERROR(VLOOKUP(B21,'[1]סיכום בקרת רשויות'!$A:$D,4,0),"") | AF21: =IF(B21>0,IF(Q21>=MIN(40,P21),"כן",""),"") | AG21: =IF(AF21="כן",M21*'גנים ובתי ספר- מבנה תקציב'!$H$59,0) -> 0 | AH21: =IF(AF21="כן",M21*'גנים ובתי ספר- מבנה תקציב'!$I$59,0) -> 0 | AI21: =AH21+AG21 -> 0 | AJ21: =IF(B21>0,IF(M21<15,1,0),"")
A22: 2 | D22: =(IFERROR(SUMIF('מצבת והרשמה (2)'!$F$21:$F$501,'דוח ביצוע (3)'!$B22,'מצבת והרשמה (2)'!$J$21:$J$501),0)) -> 0 | E22: =IFERROR(SUMIF('מצבת והרשמה (2)'!$F$21:$F$501,'דוח ביצוע (3)'!$B22,'מצבת והרשמה (2)'!$K$21:$K$501),0) -> 0 | F22: =E22+D22 -> 0 | I22: =H22+G22 -> 0 | J22: =IF(F22>149,1,0) -> 0 | M22: =MIN(NETWORKDAYS.INTL(K22,L22,7),15) -> 0 | N22: =IF(B22>0,IF(M22<15,"תקופת הפעילות נמוכה מהתקופה הנדרשת, ועל כן המוסד אינו זכאי לתקצוב","תקין"),"") | O22: =IFERROR(VLOOKUP(B22,'נתוני רישום ומצבת'!B:Q,16,0),"") | P22: =IFERROR(VLOOKUP(B22,'נתוני רישום ומצבת'!B:R,17,0),"") | S22: =IF(OR($T$2=0,N22="תקין"),MAX(IF(G22="",0,MIN(G22,D22)),0),0) -> 0 | T22: =IF(OR($T$2=0,N22="תקין"),MAX(IF(H22="",0,MIN(H22,E22)),0),0) -> 0 | U22: =SUM(S22:T22) -> 0 | V22: =IF(ISNUMBER(B22),IF(M22<1,"יש למלא מס' ימי פעילות",IF(M22<15,"יש למלא סיבה לחוסר ימי פעילות","תקין")),"") | W22: =IF(ISBLANK(B22)," ",IF(B22=IFERROR(VLOOKUP(B22,'מצבת והרשמה (2)'!F:F,1,0),0),"תקין","לא קיים במצבת כבית ספר בו מתקיימת פעילות")) | X22: =IF(IFERROR(COUNTIF($C$20:$C$2460,B22)," ")>1,"סמל המוסד מופיע יותר מפעם אחת",IF(ISBLANK(B22),"","תקין")) | Y22: =IF(AND(ISNUMBER(B22),ISBLANK(B21)),"יש למלא שורות רצופות","") | Z22: =IF(OR(LEFT(V22,10)="יש למלא מס",LEFT(V22,10)="יש למלא סי"),1,0) -> 0 | AA22: =IF(COUNTIF(סמלפעילות,B22)>1,1,0) -> 0 | AB22: =IF(B22>0,IF(I22=0,1,0),0) -> 0 | AC22: =MAX(IF(G22=" ",0,MIN(G22,D22)),0) -> 0 | AD22: =MAX(IF(H22=" ",0,MIN(H22,E22)),0) -> 0 | AE22: =IFERROR(VLOOKUP(B22,'[1]סיכום בקרת רשויות'!$A:$D,4,0),"") | AF22: =IF(B22>0,IF(Q22>=MIN(40,P22),"כן",""),"") | AG22: =IF(AF22="כן",M22*'גנים ובתי ספר- מבנה תקציב'!$H$59,0) -> 0 | AH22: =IF(AF22="כן",M22*'גנים ובתי ספר- מבנה תקציב'!$I$59,0) -> 0 | AI22: =AH22+AG22 -> 0 | AJ22: =IF(B22>0,IF(M22<15,1,0),"")
A23: 3 | D23: =(IFERROR(SUMIF('מצבת והרשמה (2)'!$F$21:$F$501,'דוח ביצוע (3)'!$B23,'מצבת והרשמה (2)'!$J$21:$J$501),0)) -> 0 | E23: =IFERROR(SUMIF('מצבת והרשמה (2)'!$F$21:$F$501,'דוח ביצוע (3)'!$B23,'מצבת והרשמה (2)'!$K$21:$K$501),0) -> 0 | F23: =E23+D23 -> 0 | I23: =H23+G23 -> 0 | J23: =IF(F23>149,1,0) -> 0 | M23: =MIN(NETWORKDAYS.INTL(K23,L23,7),15) -> 0 | N23: =IF(B23>0,IF(M23<15,"תקופת הפעילות נמוכה מהתקופה הנדרשת, ועל כן המוסד אינו זכאי לתקצוב","תקין"),"") | O23: =IFERROR(VLOOKUP(B23,'נתוני רישום ומצבת'!B:Q,16,0),"") | P23: =IFERROR(VLOOKUP(B23,'נתוני רישום ומצבת'!B:R,17,0),"") | S23: =IF(OR($T$2=0,N23="תקין"),MAX(IF(G23="",0,MIN(G23,D23)),0),0) -> 0 | T23: =IF(OR($T$2=0,N23="תקין"),MAX(IF(H23="",0,MIN(H23,E23)),0),0) -> 0 | U23: =SUM(S23:T23) -> 0 | V23: =IF(ISNUMBER(B23),IF(M23<1,"יש למלא מס' ימי פעילות",IF(M23<15,"יש למלא סיבה לחוסר ימי פעילות","תקין")),"") | W23: =IF(ISBLANK(B23)," ",IF(B23=IFERROR(VLOOKUP(B23,'מצבת והרשמה (2)'!F:F,1,0),0),"תקין","לא קיים במצבת כבית ספר בו מתקיימת פעילות")) | X23: =IF(IFERROR(COUNTIF($C$20:$C$2460,B23)," ")>1,"סמל המוסד מופיע יותר מפעם אחת",IF(ISBLANK(B23),"","תקין")) | Y23: =IF(AND(ISNUMBER(B23),ISBLANK(B22)),"יש למלא שורות רצופות","") | Z23: =IF(OR(LEFT(V23,10)="יש למלא מס",LEFT(V23,10)="יש למלא סי"),1,0) -> 0 | AA23: =IF(COUNTIF(סמלפעילות,B23)>1,1,0) -> 0 | AB23: =IF(B23>0,IF(I23=0,1,0),0) -> 0 | AC23: =MAX(IF(G23=" ",0,MIN(G23,D23)),0) -> 0 | AD23: =MAX(IF(H23=" ",0,MIN(H23,E23)),0) -> 0 | AE23: =IFERROR(VLOOKUP(B23,'[1]סיכום בקרת רשויות'!$A:$D,4,0),"") | AF23: =IF(B23>0,IF(Q23>=MIN(40,P23),"כן",""),"") | AG23: =IF(AF23="כן",M23*'גנים ובתי ספר- מבנה תקציב'!$H$59,0) -> 0 | AH23: =IF(AF23="כן",M23*'גנים ובתי ספר- מבנה תקציב'!$I$59,0) -> 0 | AI23: =AH23+AG23 -> 0 | AJ23: =IF(B23>0,IF(M23<15,1,0),"")
A24: 4 | D24: =(IFERROR(SUMIF('מצבת והרשמה (2)'!$F$21:$F$501,'דוח ביצוע (3)'!$B24,'מצבת והרשמה (2)'!$J$21:$J$501),0)) -> 0 | E24: =IFERROR(SUMIF('מצבת והרשמה (2)'!$F$21:$F$501,'דוח ביצוע (3)'!$B24,'מצבת והרשמה (2)'!$K$21:$K$501),0) -> 0 | F24: =E24+D24 -> 0 | I24: =H24+G24 -> 0 | J24: =IF(F24>149,1,0) -> 0 | M24: =MIN(NETWORKDAYS.INTL(K24,L24,7),15) -> 0 | N24: =IF(B24>0,IF(M24<15,"תקופת הפעילות נמוכה מהתקופה הנדרשת, ועל כן המוסד אינו זכאי לתקצוב","תקין"),"") | O24: =IFERROR(VLOOKUP(B24,'נתוני רישום ומצבת'!B:Q,16,0),"") | P24: =IFERROR(VLOOKUP(B24,'נתוני רישום ומצבת'!B:R,17,0),"") | S24: =IF(OR($T$2=0,N24="תקין"),MAX(IF(G24="",0,MIN(G24,D24)),0),0) -> 0 | T24: =IF(OR($T$2=0,N24="תקין"),MAX(IF(H24="",0,MIN(H24,E24)),0),0) -> 0 | U24: =SUM(S24:T24) -> 0 | V24: =IF(ISNUMBER(B24),IF(M24<1,"יש למלא מס' ימי פעילות",IF(M24<15,"יש למלא סיבה לחוסר ימי פעילות","תקין")),"") | W24: =IF(ISBLANK(B24)," ",IF(B24=IFERROR(VLOOKUP(B24,'מצבת והרשמה (2)'!F:F,1,0),0),"תקין","לא קיים במצבת כבית ספר בו מתקיימת פעילות")) | X24: =IF(IFERROR(COUNTIF($C$20:$C$2460,B24)," ")>1,"סמל המוסד מופיע יותר מפעם אחת",IF(ISBLANK(B24),"","תקין")) | Y24: =IF(AND(ISNUMBER(B24),ISBLANK(B23)),"יש למלא שורות רצופות","") | Z24: =IF(OR(LEFT(V24,10)="יש למלא מס",LEFT(V24,10)="יש למלא סי"),1,0) -> 0 | AA24: =IF(COUNTIF(סמלפעילות,B24)>1,1,0) -> 0 | AB24: =IF(B24>0,IF(I24=0,1,0),0) -> 0 | AC24: =MAX(IF(G24=" ",0,MIN(G24,D24)),0) -> 0 | AD24: =MAX(IF(H24=" ",0,MIN(H24,E24)),0) -> 0 | AE24: =IFERROR(VLOOKUP(B24,'[1]סיכום בקרת רשויות'!$A:$D,4,0),"") | AF24: =IF(B24>0,IF(Q24>=MIN(40,P24),"כן",""),"") | AG24: =IF(AF24="כן",M24*'גנים ובתי ספר- מבנה תקציב'!$H$59,0) -> 0 | AH24: =IF(AF24="כן",M24*'גנים ובתי ספר- מבנה תקציב'!$I$59,0) -> 0 | AI24: =AH24+AG24 -> 0 | AJ24: =IF(B24>0,IF(M24<15,1,0),"")
A25: 5 | D25: =(IFERROR(SUMIF('מצבת והרשמה (2)'!$F$21:$F$501,'דוח ביצוע (3)'!$B25,'מצבת והרשמה (2)'!$J$21:$J$501),0)) -> 0 | E25: =IFERROR(SUMIF('מצבת והרשמה (2)'!$F$21:$F$501,'דוח ביצוע (3)'!$B25,'מצבת והרשמה (2)'!$K$21:$K$501),0) -> 0 | F25: =E25+D25 -> 0 | I25: =H25+G25 -> 0 | J25: =IF(F25>149,1,0) -> 0 | M25: =MIN(NETWORKDAYS.INTL(K25,L25,7),15) -> 0 | N25: =IF(B25>0,IF(M25<15,"תקופת הפעילות נמוכה מהתקופה הנדרשת, ועל כן המוסד אינו זכאי לתקצוב","תקין"),"") | O25: =IFERROR(VLOOKUP(B25,'נתוני רישום ומצבת'!B:Q,16,0),"") | P25: =IFERROR(VLOOKUP(B25,'נתוני רישום ומצבת'!B:R,17,0),"") | S25: =IF(OR($T$2=0,N25="תקין"),MAX(IF(G25="",0,MIN(G25,D25)),0),0) -> 0 | T25: =IF(OR($T$2=0,N25="תקין"),MAX(IF(H25="",0,MIN(H25,E25)),0),0) -> 0 | U25: =SUM(S25:T25) -> 0 | V25: =IF(ISNUMBER(B25),IF(M25<1,"יש למלא מס' ימי פעילות",IF(M25<15,"יש למלא סיבה לחוסר ימי פעילות","תקין")),"") | W25: =IF(ISBLANK(B25)," ",IF(B25=IFERROR(VLOOKUP(B25,'מצבת והרשמה (2)'!F:F,1,0),0),"תקין","לא קיים במצבת כבית ספר בו מתקיימת פעילות")) | X25: =IF(IFERROR(COUNTIF($C$20:$C$2460,B25)," ")>1,"סמל המוסד מופיע יותר מפעם אחת",IF(ISBLANK(B25),"","תקין")) | Y25: =IF(AND(ISNUMBER(B25),ISBLANK(B24)),"יש למלא שורות רצופות","") | Z25: =IF(OR(LEFT(V25,10)="יש למלא מס",LEFT(V25,10)="יש למלא סי"),1,0) -> 0 | AA25: =IF(COUNTIF(סמלפעילות,B25)>1,1,0) -> 0 | AB25: =IF(B25>0,IF(I25=0,1,0),0) -> 0 | AC25: =MAX(IF(G25=" ",0,MIN(G25,D25)),0) -> 0 | AD25: =MAX(IF(H25=" ",0,MIN(H25,E25)),0) -> 0 | AE25: =IFERROR(VLOOKUP(B25,'[1]סיכום בקרת רשויות'!$A:$D,4,0),"") | AF25: =IF(B25>0,IF(Q25>=MIN(40,P25),"כן",""),"") | AG25: =IF(AF25="כן",M25*'גנים ובתי ספר- מבנה תקציב'!$H$59,0) -> 0 | AH25: =IF(AF25="כן",M25*'גנים ובתי ספר- מבנה תקציב'!$I$59,0) -> 0 | AI25: =AH25+AG25 -> 0 | AJ25: =IF(B25>0,IF(M25<15,1,0),"")
A26: 6 | D26: =(IFERROR(SUMIF('מצבת והרשמה (2)'!$F$21:$F$501,'דוח ביצוע (3)'!$B26,'מצבת והרשמה (2)'!$J$21:$J$501),0)) -> 0 | E26: =IFERROR(SUMIF('מצבת והרשמה (2)'!$F$21:$F$501,'דוח ביצוע (3)'!$B26,'מצבת והרשמה (2)'!$K$21:$K$501),0) -> 0 | F26: =E26+D26 -> 0 | I26: =H26+G26 -> 0 | J26: =IF(F26>149,1,0) -> 0 | M26: =MIN(NETWORKDAYS.INTL(K26,L26,7),15) -> 0 | N26: =IF(B26>0,IF(M26<15,"תקופת הפעילות נמוכה מהתקופה הנדרשת, ועל כן המוסד אינו זכאי לתקצוב","תקין"),"") | O26: =IFERROR(VLOOKUP(B26,'נתוני רישום ומצבת'!B:Q,16,0),"") | P26: =IFERROR(VLOOKUP(B26,'נתוני רישום ומצבת'!B:R,17,0),"") | S26: =IF(OR($T$2=0,N26="תקין"),MAX(IF(G26="",0,MIN(G26,D26)),0),0) -> 0 | T26: =IF(OR($T$2=0,N26="תקין"),MAX(IF(H26="",0,MIN(H26,E26)),0),0) -> 0 | U26: =SUM(S26:T26) -> 0 | V26: =IF(ISNUMBER(B26),IF(M26<1,"יש למלא מס' ימי פעילות",IF(M26<15,"יש למלא סיבה לחוסר ימי פעילות","תקין")),"") | W26: =IF(ISBLANK(B26)," ",IF(B26=IFERROR(VLOOKUP(B26,'מצבת והרשמה (2)'!F:F,1,0),0),"תקין","לא קיים במצבת כבית ספר בו מתקיימת פעילות")) | X26: =IF(IFERROR(COUNTIF($C$20:$C$2460,B26)," ")>1,"סמל המוסד מופיע יותר מפעם אחת",IF(ISBLANK(B26),"","תקין")) | Y26: =IF(AND(ISNUMBER(B26),ISBLANK(B25)),"יש למלא שורות רצופות","") | Z26: =IF(OR(LEFT(V26,10)="יש למלא מס",LEFT(V26,10)="יש למלא סי"),1,0) -> 0 | AA26: =IF(COUNTIF(סמלפעילות,B26)>1,1,0) -> 0 | AB26: =IF(B26>0,IF(I26=0,1,0),0) -> 0 | AC26: =MAX(IF(G26=" ",0,MIN(G26,D26)),0) -> 0 | AD26: =MAX(IF(H26=" ",0,MIN(H26,E26)),0) -> 0 | AE26: =IFERROR(VLOOKUP(B26,'[1]סיכום בקרת רשויות'!$A:$D,4,0),"") | AF26: =IF(B26>0,IF(Q26>=MIN(40,P26),"כן",""),"") | AG26: =IF(AF26="כן",M26*'גנים ובתי ספר- מבנה תקציב'!$H$59,0) -> 0 | AH26: =IF(AF26="כן",M26*'גנים ובתי ספר- מבנה תקציב'!$I$59,0) -> 0 | AI26: =AH26+AG26 -> 0 | AJ26: =IF(B26>0,IF(M26<15,1,0),"")
A27: 7 | D27: =(IFERROR(SUMIF('מצבת והרשמה (2)'!$F$21:$F$501,'דוח ביצוע (3)'!$B27,'מצבת והרשמה (2)'!$J$21:$J$501),0)) -> 0 | E27: =IFERROR(SUMIF('מצבת והרשמה (2)'!$F$21:$F$501,'דוח ביצוע (3)'!$B27,'מצבת והרשמה (2)'!$K$21:$K$501),0) -> 0 | F27: =E27+D27 -> 0 | I27: =H27+G27 -> 0 | J27: =IF(F27>149,1,0) -> 0 | M27: =MIN(NETWORKDAYS.INTL(K27,L27,7),15) -> 0 | N27: =IF(B27>0,IF(M27<15,"תקופת הפעילות נמוכה מהתקופה הנדרשת, ועל כן המוסד אינו זכאי לתקצוב","תקין"),"") | O27: =IFERROR(VLOOKUP(B27,'נתוני רישום ומצבת'!B:Q,16,0),"") | P27: =IFERROR(VLOOKUP(B27,'נתוני רישום ומצבת'!B:R,17,0),"") | S27: =IF(OR($T$2=0,N27="תקין"),MAX(IF(G27="",0,MIN(G27,D27)),0),0) -> 0 | T27: =IF(OR($T$2=0,N27="תקין"),MAX(IF(H27="",0,MIN(H27,E27)),0),0) -> 0 | U27: =SUM(S27:T27) -> 0 | V27: =IF(ISNUMBER(B27),IF(M27<1,"יש למלא מס' ימי פעילות",IF(M27<15,"יש למלא סיבה לחוסר ימי פעילות","תקין")),"") | W27: =IF(ISBLANK(B27)," ",IF(B27=IFERROR(VLOOKUP(B27,'מצבת והרשמה (2)'!F:F,1,0),0),"תקין","לא קיים במצבת כבית ספר בו מתקיימת פעילות")) | X27: =IF(IFERROR(COUNTIF($C$20:$C$2460,B27)," ")>1,"סמל המוסד מופיע יותר מפעם אחת",IF(ISBLANK(B27),"","תקין")) | Y27: =IF(AND(ISNUMBER(B27),ISBLANK(B26)),"יש למלא שורות רצופות","") | Z27: =IF(OR(LEFT(V27,10)="יש למלא מס",LEFT(V27,10)="יש למלא סי"),1,0) -> 0 | AA27: =IF(COUNTIF(סמלפעילות,B27)>1,1,0) -> 0 | AB27: =IF(B27>0,IF(I27=0,1,0),0) -> 0 | AC27: =MAX(IF(G27=" ",0,MIN(G27,D27)),0) -> 0 | AD27: =MAX(IF(H27=" ",0,MIN(H27,E27)),0) -> 0 | AE27: =IFERROR(VLOOKUP(B27,'[1]סיכום בקרת רשויות'!$A:$D,4,0),"") | AF27: =IF(B27>0,IF(Q27>=MIN(40,P27),"כן",""),"") | AG27: =IF(AF27="כן",M27*'גנים ובתי ספר- מבנה תקציב'!$H$59,0) -> 0 | AH27: =IF(AF27="כן",M27*'גנים ובתי ספר- מבנה תקציב'!$I$59,0) -> 0 | AI27: =AH27+AG27 -> 0 | AJ27: =IF(B27>0,IF(M27<15,1,0),"")
A28: 8 | D28: =(IFERROR(SUMIF('מצבת והרשמה (2)'!$F$21:$F$501,'דוח ביצוע (3)'!$B28,'מצבת והרשמה (2)'!$J$21:$J$501),0)) -> 0 | E28: =IFERROR(SUMIF('מצבת והרשמה (2)'!$F$21:$F$501,'דוח ביצוע (3)'!$B28,'מצבת והרשמה (2)'!$K$21:$K$501),0) -> 0 | F28: =E28+D28 -> 0 | I28: =H28+G28 -> 0 | J28: =IF(F28>149,1,0) -> 0 | M28: =MIN(NETWORKDAYS.INTL(K28,L28,7),15) -> 0 | N28: =IF(B28>0,IF(M28<15,"תקופת הפעילות נמוכה מהתקופה הנדרשת, ועל כן המוסד אינו זכאי לתקצוב","תקין"),"") | O28: =IFERROR(VLOOKUP(B28,'נתוני רישום ומצבת'!B:Q,16,0),"") | P28: =IFERROR(VLOOKUP(B28,'נתוני רישום ומצבת'!B:R,17,0),"") | S28: =IF(OR($T$2=0,N28="תקין"),MAX(IF(G28="",0,MIN(G28,D28)),0),0) -> 0 | T28: =IF(OR($T$2=0,N28="תקין"),MAX(IF(H28="",0,MIN(H28,E28)),0),0) -> 0 | U28: =SUM(S28:T28) -> 0 | V28: =IF(ISNUMBER(B28),IF(M28<1,"יש למלא מס' ימי פעילות",IF(M28<15,"יש למלא סיבה לחוסר ימי פעילות","תקין")),"") | W28: =IF(ISBLANK(B28)," ",IF(B28=IFERROR(VLOOKUP(B28,'מצבת והרשמה (2)'!F:F,1,0),0),"תקין","לא קיים במצבת כבית ספר בו מתקיימת פעילות")) | X28: =IF(IFERROR(COUNTIF($C$20:$C$2460,B28)," ")>1,"סמל המוסד מופיע יותר מפעם אחת",IF(ISBLANK(B28),"","תקין")) | Y28: =IF(AND(ISNUMBER(B28),ISBLANK(B27)),"יש למלא שורות רצופות","") | Z28: =IF(OR(LEFT(V28,10)="יש למלא מס",LEFT(V28,10)="יש למלא סי"),1,0) -> 0 | AA28: =IF(COUNTIF(סמלפעילות,B28)>1,1,0) -> 0 | AB28: =IF(B28>0,IF(I28=0,1,0),0) -> 0 | AC28: =MAX(IF(G28=" ",0,MIN(G28,D28)),0) -> 0 | AD28: =MAX(IF(H28=" ",0,MIN(H28,E28)),0) -> 0 | AE28: =IFERROR(VLOOKUP(B28,'[1]סיכום בקרת רשויות'!$A:$D,4,0),"") | AF28: =IF(B28>0,IF(Q28>=MIN(40,P28),"כן",""),"") | AG28: =IF(AF28="כן",M28*'גנים ובתי ספר- מבנה תקציב'!$H$59,0) -> 0 | AH28: =IF(AF28="כן",M28*'גנים ובתי ספר- מבנה תקציב'!$I$59,0) -> 0 | AI28: =AH28+AG28 -> 0 | AJ28: =IF(B28>0,IF(M28<15,1,0),"")
A29: 9 | D29: =(IFERROR(SUMIF('מצבת והרשמה (2)'!$F$21:$F$501,'דוח ביצוע (3)'!$B29,'מצבת והרשמה (2)'!$J$21:$J$501),0)) -> 0 | E29: =IFERROR(SUMIF('מצבת והרשמה (2)'!$F$21:$F$501,'דוח ביצוע (3)'!$B29,'מצבת והרשמה (2)'!$K$21:$K$501),0) -> 0 | F29: =E29+D29 -> 0 | I29: =H29+G29 -> 0 | J29: =IF(F29>149,1,0) -> 0 | M29: =MIN(NETWORKDAYS.INTL(K29,L29,7),15) -> 0 | N29: =IF(B29>0,IF(M29<15,"תקופת הפעילות נמוכה מהתקופה הנדרשת, ועל כן המוסד אינו זכאי לתקצוב","תקין"),"") | O29: =IFERROR(VLOOKUP(B29,'נתוני רישום ומצבת'!B:Q,16,0),"") | P29: =IFERROR(VLOOKUP(B29,'נתוני רישום ומצבת'!B:R,17,0),"") | S29: =IF(OR($T$2=0,N29="תקין"),MAX(IF(G29="",0,MIN(G29,D29)),0),0) -> 0 | T29: =IF(OR($T$2=0,N29="תקין"),MAX(IF(H29="",0,MIN(H29,E29)),0),0) -> 0 | U29: =SUM(S29:T29) -> 0 | V29: =IF(ISNUMBER(B29),IF(M29<1,"יש למלא מס' ימי פעילות",IF(M29<15,"יש למלא סיבה לחוסר ימי פעילות","תקין")),"") | W29: =IF(ISBLANK(B29)," ",IF(B29=IFERROR(VLOOKUP(B29,'מצבת והרשמה (2)'!F:F,1,0),0),"תקין","לא קיים במצבת כבית ספר בו מתקיימת פעילות")) | X29: =IF(IFERROR(COUNTIF($C$20:$C$2460,B29)," ")>1,"סמל המוסד מופיע יותר מפעם אחת",IF(ISBLANK(B29),"","תקין")) | Y29: =IF(AND(ISNUMBER(B29),ISBLANK(B28)),"יש למלא שורות רצופות","") | Z29: =IF(OR(LEFT(V29,10)="יש למלא מס",LEFT(V29,10)="יש למלא סי"),1,0) -> 0 | AA29: =IF(COUNTIF(סמלפעילות,B29)>1,1,0) -> 0 | AB29: =IF(B29>0,IF(I29=0,1,0),0) -> 0 | AC29: =MAX(IF(G29=" ",0,MIN(G29,D29)),0) -> 0 | AD29: =MAX(IF(H29=" ",0,MIN(H29,E29)),0) -> 0 | AE29: =IFERROR(VLOOKUP(B29,'[1]סיכום בקרת רשויות'!$A:$D,4,0),"") | AF29: =IF(B29>0,IF(Q29>=MIN(40,P29),"כן",""),"") | AG29: =IF(AF29="כן",M29*'גנים ובתי ספר- מבנה תקציב'!$H$59,0) -> 0 | AH29: =IF(AF29="כן",M29*'גנים ובתי ספר- מבנה תקציב'!$I$59,0) -> 0 | AI29: =AH29+AG29 -> 0 | AJ29: =IF(B29>0,IF(M29<15,1,0),"")
A30: 10 | D30: =(IFERROR(SUMIF('מצבת והרשמה (2)'!$F$21:$F$501,'דוח ביצוע (3)'!$B30,'מצבת והרשמה (2)'!$J$21:$J$501),0)) -> 0 | E30: =IFERROR(SUMIF('מצבת והרשמה (2)'!$F$21:$F$501,'דוח ביצוע (3)'!$B30,'מצבת והרשמה (2)'!$K$21:$K$501),0) -> 0 | F30: =E30+D30 -> 0 | I30: =H30+G30 -> 0 | J30: =IF(F30>149,1,0) -> 0 | M30: =MIN(NETWORKDAYS.INTL(K30,L30,7),15) -> 0 | N30: =IF(B30>0,IF(M30<15,"תקופת הפעילות נמוכה מהתקופה הנדרשת, ועל כן המוסד אינו זכאי לתקצוב","תקין"),"") | O30: =IFERROR(VLOOKUP(B30,'נתוני רישום ומצבת'!B:Q,16,0),"") | P30: =IFERROR(VLOOKUP(B30,'נתוני רישום ומצבת'!B:R,17,0),"") | S30: =IF(OR($T$2=0,N30="תקין"),MAX(IF(G30="",0,MIN(G30,D30)),0),0) -> 0 | T30: =IF(OR($T$2=0,N30="תקין"),MAX(IF(H30="",0,MIN(H30,E30)),0),0) -> 0 | U30: =SUM(S30:T30) -> 0 | V30: =IF(ISNUMBER(B30),IF(M30<1,"יש למלא מס' ימי פעילות",IF(M30<15,"יש למלא סיבה לחוסר ימי פעילות","תקין")),"") | W30: =IF(ISBLANK(B30)," ",IF(B30=IFERROR(VLOOKUP(B30,'מצבת והרשמה (2)'!F:F,1,0),0),"תקין","לא קיים במצבת כבית ספר בו מתקיימת פעילות")) | X30: =IF(IFERROR(COUNTIF($C$20:$C$2460,B30)," ")>1,"סמל המוסד מופיע יותר מפעם אחת",IF(ISBLANK(B30),"","תקין")) | Y30: =IF(AND(ISNUMBER(B30),ISBLANK(B29)),"יש למלא שורות רצופות","") | Z30: =IF(OR(LEFT(V30,10)="יש למלא מס",LEFT(V30,10)="יש למלא סי"),1,0) -> 0 | AA30: =IF(COUNTIF(סמלפעילות,B30)>1,1,0) -> 0 | AB30: =IF(B30>0,IF(I30=0,1,0),0) -> 0 | AC30: =MAX(IF(G30=" ",0,MIN(G30,D30)),0) -> 0 | AD30: =MAX(IF(H30=" ",0,MIN(H30,E30)),0) -> 0 | AE30: =IFERROR(VLOOKUP(B30,'[1]סיכום בקרת רשויות'!$A:$D,4,0),"") | AF30: =IF(B30>0,IF(Q30>=MIN(40,P30),"כן",""),"") | AG30: =IF(AF30="כן",M30*'גנים ובתי ספר- מבנה תקציב'!$H$59,0) -> 0 | AH30: =IF(AF30="כן",M30*'גנים ובתי ספר- מבנה תקציב'!$I$59,0) -> 0 | AI30: =AH30+AG30 -> 0 | AJ30: =IF(B30>0,IF(M30<15,1,0),"")
A31: 11 | D31: =(IFERROR(SUMIF('מצבת והרשמה (2)'!$F$21:$F$501,'דוח ביצוע (3)'!$B31,'מצבת והרשמה (2)'!$J$21:$J$501),0)) -> 0 | E31: =IFERROR(SUMIF('מצבת והרשמה (2)'!$F$21:$F$501,'דוח ביצוע (3)'!$B31,'מצבת והרשמה (2)'!$K$21:$K$501),0) -> 0 | F31: =E31+D31 -> 0 | I31: =H31+G31 -> 0 | J31: =IF(F31>149,1,0) -> 0 | M31: =MIN(NETWORKDAYS.INTL(K31,L31,7),15) -> 0 | N31: =IF(B31>0,IF(M31<15,"תקופת הפעילות נמוכה מהתקופה הנדרשת, ועל כן המוסד אינו זכאי לתקצוב","תקין"),"") | O31: =IFERROR(VLOOKUP(B31,'נתוני רישום ומצבת'!B:Q,16,0),"") | P31: =IFERROR(VLOOKUP(B31,'נתוני רישום ומצבת'!B:R,17,0),"") | S31: =IF(OR($T$2=0,N31="תקין"),MAX(IF(G31="",0,MIN(G31,D31)),0),0) -> 0 | T31: =IF(OR($T$2=0,N31="תקין"),MAX(IF(H31="",0,MIN(H31,E31)),0),0) -> 0 | U31: =SUM(S31:T31) -> 0 | V31: =IF(ISNUMBER(B31),IF(M31<1,"יש למלא מס' ימי פעילות",IF(M31<15,"יש למלא סיבה לחוסר ימי פעילות","תקין")),"") | W31: =IF(ISBLANK(B31)," ",IF(B31=IFERROR(VLOOKUP(B31,'מצבת והרשמה (2)'!F:F,1,0),0),"תקין","לא קיים במצבת כבית ספר בו מתקיימת פעילות")) | X31: =IF(IFERROR(COUNTIF($C$20:$C$2460,B31)," ")>1,"סמל המוסד מופיע יותר מפעם אחת",IF(ISBLANK(B31),"","תקין")) | Y31: =IF(AND(ISNUMBER(B31),ISBLANK(B30)),"יש למלא שורות רצופות","") | Z31: =IF(OR(LEFT(V31,10)="יש למלא מס",LEFT(V31,10)="יש למלא סי"),1,0) -> 0 | AA31: =IF(COUNTIF(סמלפעילות,B31)>1,1,0) -> 0 | AB31: =IF(B31>0,IF(I31=0,1,0),0) -> 0 | AC31: =MAX(IF(G31=" ",0,MIN(G31,D31)),0) -> 0 | AD31: =MAX(IF(H31=" ",0,MIN(H31,E31)),0) -> 0 | AE31: =IFERROR(VLOOKUP(B31,'[1]סיכום בקרת רשויות'!$A:$D,4,0),"") | AF31: =IF(B31>0,IF(Q31>=MIN(40,P31),"כן",""),"") | AG31: =IF(AF31="כן",M31*'גנים ובתי ספר- מבנה תקציב'!$H$59,0) -> 0 | AH31: =IF(AF31="כן",M31*'גנים ובתי ספר- מבנה תקציב'!$I$59,0) -> 0 | AI31: =AH31+AG31 -> 0 | AJ31: =IF(B31>0,IF(M31<15,1,0),"")
A32: 12 | D32: =(IFERROR(SUMIF('מצבת והרשמה (2)'!$F$21:$F$501,'דוח ביצוע (3)'!$B32,'מצבת והרשמה (2)'!$J$21:$J$501),0)) -> 0 | E32: =IFERROR(SUMIF('מצבת והרשמה (2)'!$F$21:$F$501,'דוח ביצוע (3)'!$B32,'מצבת והרשמה (2)'!$K$21:$K$501),0) -> 0 | F32: =E32+D32 -> 0 | I32: =H32+G32 -> 0 | J32: =IF(F32>149,1,0) -> 0 | M32: =MIN(NETWORKDAYS.INTL(K32,L32,7),15) -> 0 | N32: =IF(B32>0,IF(M32<15,"תקופת הפעילות נמוכה מהתקופה הנדרשת, ועל כן המוסד אינו זכאי לתקצוב","תקין"),"") | O32: =IFERROR(VLOOKUP(B32,'נתוני רישום ומצבת'!B:Q,16,0),"") | P32: =IFERROR(VLOOKUP(B32,'נתוני רישום ומצבת'!B:R,17,0),"") | S32: =IF(OR($T$2=0,N32="תקין"),MAX(IF(G32="",0,MIN(G32,D32)),0),0) -> 0 | T32: =IF(OR($T$2=0,N32="תקין"),MAX(IF(H32="",0,MIN(H32,E32)),0),0) -> 0 | U32: =SUM(S32:T32) -> 0 | V32: =IF(ISNUMBER(B32),IF(M32<1,"יש למלא מס' ימי פעילות",IF(M32<15,"יש למלא סיבה לחוסר ימי פעילות","תקין")),"") | W32: =IF(ISBLANK(B32)," ",IF(B32=IFERROR(VLOOKUP(B32,'מצבת והרשמה (2)'!F:F,1,0),0),"תקין","לא קיים במצבת כבית ספר בו מתקיימת פעילות")) | X32: =IF(IFERROR(COUNTIF($C$20:$C$2460,B32)," ")>1,"סמל המוסד מופיע יותר מפעם אחת",IF(ISBLANK(B32),"","תקין")) | Y32: =IF(AND(ISNUMBER(B32),ISBLANK(B31)),"יש למלא שורות רצופות","") | Z32: =IF(OR(LEFT(V32,10)="יש למלא מס",LEFT(V32,10)="יש למלא סי"),1,0) -> 0 | AA32: =IF(COUNTIF(סמלפעילות,B32)>1,1,0) -> 0 | AB32: =IF(B32>0,IF(I32=0,1,0),0) -> 0 | AC32: =MAX(IF(G32=" ",0,MIN(G32,D32)),0) -> 0 | AD32: =MAX(IF(H32=" ",0,MIN(H32,E32)),0) -> 0 | AE32: =IFERROR(VLOOKUP(B32,'[1]סיכום בקרת רשויות'!$A:$D,4,0),"") | AF32: =IF(B32>0,IF(Q32>=MIN(40,P32),"כן",""),"") | AG32: =IF(AF32="כן",M32*'גנים ובתי ספר- מבנה תקציב'!$H$59,0) -> 0 | AH32: =IF(AF32="כן",M32*'גנים ובתי ספר- מבנה תקציב'!$I$59,0) -> 0 | AI32: =AH32+AG32 -> 0 | AJ32: =IF(B32>0,IF(M32<15,1,0),"")
A33: 13 | D33: =(IFERROR(SUMIF('מצבת והרשמה (2)'!$F$21:$F$501,'דוח ביצוע (3)'!$B33,'מצבת והרשמה (2)'!$J$21:$J$501),0)) -> 0 | E33: =IFERROR(SUMIF('מצבת והרשמה (2)'!$F$21:$F$501,'דוח ביצוע (3)'!$B33,'מצבת והרשמה (2)'!$K$21:$K$501),0) -> 0 | F33: =E33+D33 -> 0 | I33: =H33+G33 -> 0 | J33: =IF(F33>149,1,0) -> 0 | M33: =MIN(NETWORKDAYS.INTL(K33,L33,7),15) -> 0 | N33: =IF(B33>0,IF(M33<15,"תקופת הפעילות נמוכה מהתקופה הנדרשת, ועל כן המוסד אינו זכאי לתקצוב","תקין"),"") | O33: =IFERROR(VLOOKUP(B33,'נתוני רישום ומצבת'!B:Q,16,0),"") | P33: =IFERROR(VLOOKUP(B33,'נתוני רישום ומצבת'!B:R,17,0),"") | S33: =IF(OR($T$2=0,N33="תקין"),MAX(IF(G33="",0,MIN(G33,D33)),0),0) -> 0 | T33: =IF(OR($T$2=0,N33="תקין"),MAX(IF(H33="",0,MIN(H33,E33)),0),0) -> 0 | U33: =SUM(S33:T33) -> 0 | V33: =IF(ISNUMBER(B33),IF(M33<1,"יש למלא מס' ימי פעילות",IF(M33<15,"יש למלא סיבה לחוסר ימי פעילות","תקין")),"") | W33: =IF(ISBLANK(B33)," ",IF(B33=IFERROR(VLOOKUP(B33,'מצבת והרשמה (2)'!F:F,1,0),0),"תקין","לא קיים במצבת כבית ספר בו מתקיימת פעילות")) | X33: =IF(IFERROR(COUNTIF($C$20:$C$2460,B33)," ")>1,"סמל המוסד מופיע יותר מפעם אחת",IF(ISBLANK(B33),"","תקין")) | Y33: =IF(AND(ISNUMBER(B33),ISBLANK(B32)),"יש למלא שורות רצופות","") | Z33: =IF(OR(LEFT(V33,10)="יש למלא מס",LEFT(V33,10)="יש למלא סי"),1,0) -> 0 | AA33: =IF(COUNTIF(סמלפעילות,B33)>1,1,0) -> 0 | AB33: =IF(B33>0,IF(I33=0,1,0),0) -> 0 | AC33: =MAX(IF(G33=" ",0,MIN(G33,D33)),0) -> 0 | AD33: =MAX(IF(H33=" ",0,MIN(H33,E33)),0) -> 0 | AE33: =IFERROR(VLOOKUP(B33,'[1]סיכום בקרת רשויות'!$A:$D,4,0),"") | AF33: =IF(B33>0,IF(Q33>=MIN(40,P33),"כן",""),"") | AG33: =IF(AF33="כן",M33*'גנים ובתי ספר- מבנה תקציב'!$H$59,0) -> 0 | AH33: =IF(AF33="כן",M33*'גנים ובתי ספר- מבנה תקציב'!$I$59,0) -> 0 | AI33: =AH33+AG33 -> 0 | AJ33: =IF(B33>0,IF(M33<15,1,0),"")
... A520: 500 | D520: =(IFERROR(SUMIF('מצבת והרשמה (2)'!$F$21:$F$501,'דוח ביצוע (3)'!$B520,'מצבת והרשמה (2)'!$J$21:$J$501),0)) -> 0 | E520: =IFERROR(SUMIF('מצבת והרשמה (2)'!$F$21:$F$501,'דוח ביצוע (3)'!$B520,'מצבת והרשמה (2)'!$K$21:$K$501),0) -> 0 | F520: =E520+D520 -> 0 | I520: =H520+G520 -> 0 | J520: =IF(F520>149,1,0) -> 0 | M520: =MIN(NETWORKDAYS.INTL(K520,L520,7),15) -> 0 | N520: =IF(B520>0,IF(M520<15,"תקופת הפעילות נמוכה מהתקופה הנדרשת, ועל כן המוסד אינו זכאי לתקצוב","תקין"),"") | O520: =IFERROR(VLOOKUP(B520,'נתוני רישום ומצבת'!B:Q,16,0),"") | P520: =IFERROR(VLOOKUP(B520,'נתוני רישום ומצבת'!B:R,17,0),"") | S520: =IF(OR($T$2=0,N520="תקין"),MAX(IF(G520="",0,MIN(G520,D520)),0),0) -> 0 | T520: =IF(OR($T$2=0,N520="תקין"),MAX(IF(H520="",0,MIN(H520,E520)),0),0) -> 0 | U520: =SUM(S520:T520) -> 0 | V520: =IF(ISNUMBER(B520),IF(M520<1,"יש למלא מס' ימי פעילות",IF(M520<15,"יש למלא סיבה לחוסר ימי פעילות","תקין")),"") | W520: =IF(ISBLANK(B520)," ",IF(B520=IFERROR(VLOOKUP(B520,'מצבת והרשמה (2)'!F:F,1,0),0),"תקין","לא קיים במצבת כבית ספר בו מתקיימת פעילות")) | X520: =IF(IFERROR(COUNTIF($C$20:$C$2460,B520)," ")>1,"סמל המוסד מופיע יותר מפעם אחת",IF(ISBLANK(B520),"","תקין")) | Y520: =IF(AND(ISNUMBER(B520),ISBLANK(B519)),"יש למלא שורות רצופות","") | Z520: =IF(OR(LEFT(V520,10)="יש למלא מס",LEFT(V520,10)="יש למלא סי"),1,0) -> 0 | AA520: =IF(COUNTIF(סמלפעילות,B520)>1,1,0) -> 0 | AB520: =IF(B520>0,IF(I520=0,1,0),0) -> 0 | AC520: =MAX(IF(G520=" ",0,MIN(G520,D520)),0) -> 0 | AD520: =MAX(IF(H520=" ",0,MIN(H520,E520)),0) -> 0 | AE520: =IFERROR(VLOOKUP(B520,'[1]סיכום בקרת רשויות'!$A:$D,4,0),"") | AF520: =IF(B520>0,IF(Q520>=MIN(40,P520),"כן",""),"") | AG520: =IF(AF520="כן",M520*'גנים ובתי ספר- מבנה תקציב'!$H$59,0) -> 0 | AH520: =IF(AF520="כן",M520*'גנים ובתי ספר- מבנה תקציב'!$I$59,0) -> 0 | AI520: =AH520+AG520 -> 0 | AJ520: =IF(B520>0,IF(M520<15,1,0),"")

Sheet דוח הוצאות בפועל (4)
A1: תוכן העניינים | D1: ='גנים ובתי ספר- מבנה תקציב'!$E$1 -> תכנית בתי הספר והגנים של החופש הגדול, קיץ תשפ"ו | M1: *
B3: שם הרשות המקומית | C3: ='נתונים כלליים (1)'!$C$5 -> 0 | I3: =IF(AND(I4="",I5="")," ","שגיאות בגיליון:")
B4: מספר אשכול למ"ס | C4: ='נתונים כלליים (1)'!$C$6 | E4: יש למלא קודם את גיליון " נתונים כלליים (1)" | I4: =IF(C9<B9,CONCATENATE("שימו לב, ישנם ",B9-C9," מוסדות אשר דווחו בדוח ביצוע ולא דווח עליהם הוצאות"),IF(B9<C9,CONCATENATE("שימו לב, ישנם ",C9-B9," מוסדות אשר דווח עליהם הוצאות אולם לא דווחו בדוח ביצוע"),""))
B5: תעריף לילד חלק ההורים ש"ח | C5: ='נתונים כלליים (1)'!$C$7 -> 0 | E5: ואת גיליון "דוח ביצוע (3)"
B7: סיכום
B8: סה"כ מוסדות מדווחים בדוח ביצוע | C8: סה"כ מוסדות שדווח עבורם הוצאות | D8: העשרה | E8: ארוחת בוקר | F8: מלגות להורים | G8: ניהול ותפעול | H8: סה"כ הוצאות שדווחו
B9: ='דוח ביצוע (3)'!C13 -> 0 | C9: =SUM(IF(FREQUENCY(B17:$B$3016,B17:$B$3016)>0,1)) -> 0 | D9: =SUMIF($D$16:$D$3016,D$8,$E$16:$E$3016) -> 0 | E9: =SUMIF($D$16:$D$3016,E$8,$E$16:$E$3016) -> 0 | F9: =SUMIF($D$16:$D$3016,F$8,$E$16:$E$3016) -> 0 | G9: =SUMIF($D$16:$D$3016,G$8,$E$16:$E$3016) -> 0 | H9: =SUM(D9:G9) -> 0
D12: דוח ביצוע כספי - הוצאות בפועל
D13: את הוצאות השכר יש לדווח בגיליון נפרד - 'עלויות כח אדם (6)'
D15: יש לבחור מתוך הרשימה הנפתחת בלבד!
