Workbook
Name ba_KoachAdam: 'פירוט עלויות כח אדם (6)'!$B$15:$M$3015
Name bs_mafilim: #REF!
Name bs_mafilim: #REF!
Name bs_mafilim: #REF!
Name bs_SganRakaz: ' איוש משרות (9)'!$B$16:$N$516
Name gan_bitzua: 'גנים - דוח ביצוע (5)'!$A$17:$O$1017
Name gan_hotzaot: 'דוח הוצאות בפועל (2)'!$B$9:$E$15
Name gan_mafilim: #REF!
Name gan_matzevet: 'גנים - מצבת והרשמה (4)'!$B$15:$I$1015
Name gan_melagot: 'תשלומי הורים ומלגות להורים (3) '!$B$10:$I$12
Name gan_netunim: 'נתונים כללים (1)'!$C$5:$C$7
Name gan_rakazot: 'רכזות גנים - דוח ביצוע (8)'!$B$16:$I$316
Name איש_צוות: 'גיליון עזר'!$A$2:$F$2
Name בדיק: #REF!
Name בדיק: #REF!
Name בדיק: #REF!
Name בדיקה: #REF!
Name בדיקה: #REF!
Name בדיקה: #REF!
Name בדיקה: #REF!
Name בדיקה: #REF!
Name בדיקה: [1]מעמד!$B$2:$B$3
Name בדיקה: #REF!
Name בדיקה: 'גיליון עזר'!$A$19:$A$20
Name גן: 'גנים - מצבת והרשמה (4)'!$C$15:$C$20
Name גננת: 'גיליון עזר'!$A$3:$A$8
Name השתתפות_לילד_ביס: '[2]גנים ובתי ספר- מבנה תקציב'!$B$80:$H$90
Name השתתפות_לילד_ביס: '[2]גנים ובתי ספר- מבנה תקציב'!$B$80:$H$90
Name השתתפות_לילד_ביס: 'גנים ובתי ספר- מבנה תקציב'!$B$80:$H$90
Name השתתפות_לילד_ביס: '[2]גנים ובתי ספר- מבנה תקציב'!$B$80:$H$90
Name השתתפות_לילד_ביס: '[2]גנים ובתי ספר- מבנה תקציב'!$B$80:$H$90
Name השתתפות_לילד_ביס: '[2]גנים ובתי ספר- מבנה תקציב'!$B$80:$H$90
Name השתתפות_לילד_ביס: '[1]גנים ובתי ספר- מבנה תקציב'!$B$66:$G$76
Name ישובים_מפונים: #REF!
Name ישובים_מפונים: #REF!
Name ישובים_מפונים: #REF!
Name ישובים_מפונים: #REF!
Name ישובים_מפונים: #REF!
Name ישובים_מפונים: #REF!
Name ישובים_מפונים: #REF!
Name ישובים_מפונים: #REF!
Name מוכשר: #REF!
Name מוכשר: #REF!
Name מוכשר: #REF!
Name מוכשר: #REF!
Name מוכשר: #REF!
Name מוכשר: [1]מעמד!$A$3
Name מוכשר: #REF!
Name מוכשר: 'גיליון עזר'!$B$20
Name מוסדות: '[2]מצבת והרשמה (2)'!$C$21:$C$520
Name מעמד: '[2]מצבת והרשמה (2)'!#REF!
Name מעמד: '[2]מצבת והרשמה (2)'!#REF!
Name מעמד: '[2]מצבת והרשמה (2)'!#REF!
Name מעמד: '[2]מצבת והרשמה (2)'!#REF!
Name מעמד: '[2]מצבת והרשמה (2)'!#REF!
Name מעמד: '[1] מצבת והרשמה (3)'!$F$5
Name מעמד: '[2]מצבת והרשמה (2)'!#REF!
Name מעמד: 'גנים - מצבת והרשמה (4)'!#REF!
Name מעמד_משפטי: #REF!
Name מעמד_משפטי: #REF!

Sheet תוכן העניינים
B2: תוכנית הגנים ובתי הספר של החופש הגדול - תשפ"ו | דוח ביצוע ותקצוב
B3: יש למלא את הגיליונות לפי הסדר המוצג מטה (שלב 1 עד 9). לחצו על שם השלב למעבר ישיר.
B5: מקרא צבעים:
C6: תא קלט - יש למלא | D6: תא מחושב/נעול - אין לערוך | E6: שגיאה / לא תקין
B9: # | C9: שלב / גיליון | D9: הסבר קצר | E9: הנחיות מפורטות | F9: סטטוס מילוי | G9: בדיקת תקינות
B10: 1 | C10: נתונים כלליים (1) | D10: מלאו פרטי רשות, אנשי קשר וגופים מפעילים | E10: הנחיות כלליות | F10: =IF('נתונים כללים (1)'!$C$5="","טרם מולא","תקין") -> טרם מולא | G10: =IF('נתונים כללים (1)'!$E$4="","תקין","לא תקין, יש לתקן דיווח!") -> לא תקין, יש לתקן דיווח!
B11: 2 | C11: דוח הוצאות בפועל (2) | D11: מלאו הוצאות בפועל לפי סעיפים תקציביים | E11: הנחיות למילוי הדוח | F11: =IF('דוח הוצאות בפועל (2)'!$C$15=0,"טרם מולא","תקין") -> טרם מולא
B12: 3 | C12: תשלומי הורים ומלגות להורים (3) | D12: גבייה מהורים ומלגות שניתנו | E12: הנחיות למילוי הדוח | F12: =IF('תשלומי הורים ומלגות להורים (3) '!$C$11=0,"טרם מולא","תקין") -> טרם מולא
B13: 4 | C13: גנים- מצבת והרשמה (4) | D13: מתעדכן אוטומטית - אין למלא | E13: הנחיות למילוי הדוח
B14: 5 | C14: גנים- דוח ביצוע (5) | D14: בחרו סמל מוסד, מפעיל ותאריכי פעילות | E14: הנחיות למילוי הדוח | F14: =IF('גנים - דוח ביצוע (5)'!$H$11=0,"טרם מולא","תקין") -> טרם מולא | G14: =IF('גנים - דוח ביצוע (5)'!$L$2=" ","תקין","לא תקין, יש לתקן דיווח!") -> תקין
B15: 6 | C15: עלויות כח אדם (6) | D15: פירוט כח אדם, תפקידים ושעות | E15: הנחיות למילוי הדוח | F15: =IF('פירוט עלויות כח אדם (6)'!G13=0,"טרם מולא","תקין") -> טרם מולא | G15: =IF('פירוט עלויות כח אדם (6)'!$I$4=" ","תקין","לא תקין, יש לתקן דיווח!") -> תקין
B16: 7 | C16: סייעות רפואיות או אישיות (7) | D16: פרטי סייעות ותלמידים זכאים | E16: הנחיות למילוי הדוח | F16: =IF('סייעות רפואיות או אישיות (7)'!$D$13=0,"טרם מולא","תקין") -> טרם מולא
B17: 8 | C17: רכזות גנים- דוח ביצוע (8) | D17: נבדק אוטומטית - אין למלא | E17: הנחיות למילוי הדוח | F17: =IF('רכזות גנים - דוח ביצוע (8)'!H10="","טרם מולא","תקין") -> תקין
B18: 9 | C18: איוש משרות (9) | D18: נבדק אוטומטית - אין למלא | E18: הנחיות למילוי הדוח | F18: =IF(' איוש משרות (9)'!$C$17="","טרם מולא","תקין") -> טרם מולא | G18: =IF(' איוש משרות (9)'!$K$4=" ","תקין","לא תקין, יש לתקן דיווח!") -> תקין
B19: 10 | C19: ריכוז נתונים (10) | D19: גיליון מחושב ונעול - לעיון בלבד | E19: הנחיות למילוי הדוח

Sheet הנחיות כלליות
A1: גירסה גנים הרחבה 8.2026
A2: בס"ד | B2: הנחיות למילוי
A3: תכנית בתי הספר והגנים של החופש הגדול, קיץ תשפ"ו
A4: מסמכים נדרשים ודגשים לדיווח לצורך קבלת תקצוב
A6: >> חשוב לקרוא בעיון את ההוראות על מנת להגיש את המסמכים בצורה תקינה ולמנוע קיזוזים מיותרים!
A8: להלן רשימת מסמכים הנדרשים לצורך קבלת תקצוב ברשויות עבור תוכנית "הגנים ובית הספר של החופש הגדול" תשפ"ו בגני הילדים ובכיתות א-ג:
A9: סעיף | B9: מס' | C9: מסמכים נדרשים ודגשים לדיווח
A10: שכר | B10: 1 | C10: יש להגדיר בתוכנת השכר מחלקה/רכיב נפרדת עבור שכר עובדי הקייטנה.
B11: 2 | C11: דוח ריכוז משכורות – דוח מרוכז לכלל העובדים המכיל פירוט של כל רכיבי השכר ששולמו לעובדים בחודש הקייטנה – יולי 2026, בהתאמה לנתונים שדווחו בדוח ביצוע. יצוין כי כל תוכנה מגדירה את הדוח בשם אחר (לדוגמא: דוח חזותי, ריכוז תלושים, דוח רכיבי שכר) ולכן נא להתייחס לרכיבים הנדרשים בדוח.
B12: 3 | C12: דוח עלות – דוח מרכז המפרט את עלויות המעסיק של כלל העובדים (נקרא: דוח 66) בהתאמה לסכום שדווח בדוח ביצוע.
B13: 4 | C13: כרטסת הוצאות שכר – כרטסת הנהלת חשבונות נפרדת המכילה את הוצאות השכר בגין הקייטנה בלבד, בהתאמה לסכום שדווח בדוח ביצוע. במידה וכרטסת השכר כוללת הוצאות שכר בגין פעילות העשרה יש לצרף מסמך התאמה ברור ולציין את שם העובד המועסק ותפקידו בקייטנה (לדוג' ישראל ישראלי – פעילות ספורט).
A14: ניהול ותפעול | B14: 1 | C14: כרטסת ניהול ותפעול – א. כרטסת הנהלת חשבונות נפרדת המכילה את הוצאות הניהול והתפעול בהתאמה לסכום שדווח בדוח ביצוע. הכרטסת צריכה להכיל את פירוט מהות ההוצאות ושמות הספקים של כל חשבונית. ב. ההוצאות צריכות להתבצע בחודש הפעילות – חודש יולי 2026. במידה וההוצאות רשומות במועדים אחרים יש לצרף הסבר.
A15: העשרה | B15: 1 | C15: כרטסת העשרה – א. כרטסת הנהלת חשבונות נפרדת המכילה את הוצאות העשרה בהתאמה לסכום שדווח בדוח ביצוע. הכרטסת צריכה להכיל את פירוט מהות ההוצאות ושמות הספקים של כל חשבונית. ב. ההוצאות צריכות להתבצע בחודש הפעילות – חודש יולי 2026. במידה וההוצאות רשומות במועדים אחרים יש לצרף הסבר.
A16: ארוחת בוקר | B16: 1 | C16: כרטסת ארוחת בוקר - כרטסת הנהלת חשבונות נפרדת המכילה את ההוצאות שדווחו בדוח ביצוע בגין ארוחת בוקר כהגדרתה בקול קורא – "ארוחת בוקר קלה במימון המסגרת" (לא ממתקים כגון קרטיבים וכד'). הכרטסת צריכה להכיל את פירוט מהות ההוצאות ושמות הספקים של כל חשבונית.
A17: גביה | C17: ברשויות בהן קיימת גביה מההורים נדרש להגיש את המסמכים הבאים:
B18: 1 | C18: כרטסת גביה מההורים - כרטסת הנהלת חשבונות נפרדת המכילה את ההכנסות בגין הכנסות גביה בהתאמה לסכום שדווח בדוח ביצוע.
B19: 2 | C19: כרטסת מלגות – כרטסת הנהלת חשבונות נפרדת המכילה את המלגות שניתנו להורים בהתאמה לסכום שדווח בדוח ביצוע, יש להקפיד על רישום בשיטת הברוטו ובהתאמה לדרישות קול הקורא בנושא.
A20: חשוב מאוד! | B20: 1 | C20: נדרש להעביר את הקבצים בפורמט אקסל.
B21: 2 | C21: יש להעביר קבצים מקוריים מתוכנת השכר או מתוכנת הנהלת חשבונות ולא קבצים מעובדים. (במידת הצורך ניתן להעביר מסמך התאמה).
B22: 3 | C22: נדרש רישום הוצאות או הכנסות בכרטסות נפרדות למוסדות כדלהלן: גנים רשמי – לכלל הגנים יחד (שכר בנפרד העשרה בנפרד וכו', כל כרטסת מכילה את ההוצאות של כל הגנים רשמי בלבד), גנים מוכשר – לכלל הגנים יחד, בתי ספר רשמי – כל בית ספר בנפרד (שכר בנפרד העשרה בנפרד וכו', כל כרטסת מכילה את ההוצאות של כל מוסד בנפרד), בתי ספר מוכשר – כל בית ספר בנפרד.
B23: 4 | C23: יש להקפיד על ניהול ותיעוד אסמכתאות מפורטות ברמת מוסד ככל הניתן.
B24: 5 | C24: במידה והרשות מבצעת את פעילות העשרה או הדרכה באמצעות עובדים חיצוניים (תשלום בחשבונית), יש לצרף בנוסף לכרטסת חשבונית מס או קבלה בגין השירות שניתן. על החשבונית להיות מפורטת וכוללת כמות שעות תאריכים ותעריפים.
B25: 6 | C25: לכל שאלה בנושא אופן הגשת המסמכים יש לפנות למדריכות מטעם משרד החינוך בדוא"ל.

Sheet הנחיות למילוי הדוח
A3: שם גיליון | B3: מס' | C3: הנחיות למילוי דוח הביצוע
A4: כללי | B4: 1 | C4: יש להקפיד למלא את הגיליונות לפי סדר הצגתם בדוח מגיליון 1 עד גיליון 8.
A5: נתונים כלליים (1) | B5: 1 | C5: יש לבחור את שם הרשות מהרשימה הנפתחת.
B6: 2 | C6: יש למלא נתוני אנשי קשר- גזבר ומנהל מחלקת חינוך. לתשומת לב, לכתובות מייל אלו יישלחו המכתבים.
B7: 3 | C7: יש לרשום בגליון את פרטי כל הגופים איתם הרשות התקשרה בהסכמים לביצוע הפעילות כולה או חלקה. בעמודת הערות יש לפרט את הפעילות שבוצעה ע"י כל אחד מהגופים.
B8: 4 | C8: במקרים שישנה בנוסף גם חברה מנהלת (כגון משכ"ל, החברה למשאבי אנוש וכו') יש לציין זאת. במקרים שהרשות מפעילה את הפעילות בעצמה, ומעסיקה את העובדים בתכנית, יש לציין זאת.
A9: דוח הוצאות בפועל (2) | B9: 1 | C9: יש להקפיד ולערוך את הדוח אך ורק עפ"י ההוצאות והנתונים שנכללו במערכת הנהלת החשבונות של הרשות. יש למלא את מספר הסעיף התקציבי בו נרשמה ההוצאה בכל אחד מהסעיפים בדוח הביצוע הכספי.
B10: 2 | C10: לגבי "הוצאות ניהול ותפעול" (תקורה) - אין צורך להציג את מספרי הסעיפים התקציביים בהם נרשמו ההוצאות.
B11: 3 | C11: לגבי "מלגות להורים" - יש לרשום את הסכום הכולל שהרשות חילקה להורים כמלגות ושימשו למימון התכנית במקום תשלומי הורים. בכלל זה, גם סכומי המלגות שמתוקצבות ע"י משרד החינוך.
A12: תשלומי הורים ומלגות להורים (3) | B12: 1 | C12: הסכום שחולק כמלגות להורים, מועבר מגיליון דוח הוצאות בפועל (2), כאמור לעיל.
B13: 2 | C13: יש למלא בעמודה H את כמות הילדים להם ניתנה מלגה.
B14: 3 | C14: יש למלא בעמודה I את כמות הילדים עבורם בוצעה גביה.
B15: 4 | C15: יש להקפיד ולרשום את מספרי הכרטיסים בהם נרשמו ההכנסות בסעיפים אלו.
A16: מצבת והרשמה (4) | B16: 1 | C16: הגיליון כולו מוזן באופן אוטומטי.
B17: 2 | C17: סמל מוסד של גני ילדים בחטיבות צעירות ידווח כחלק מגני הילדים של הרשות בדו״ח הביצוע של גני הילדים.
A18: דוח ביצוע (5) | B18: 1 | C18: בעמודה C - "סמל גן בו מתקיימת הפעילות" - יש לבחור סמל גן מהרשימה הנפתחת. יש להקפיד כי כל סמל גן יירשם פעם אחת בלבד.
B19: 2 | C19: יש לבחור מרשימה נפתחת את מפעיל התוכנית.
B20: 3 | C20: בעמודות F ו-G "ביצוע בפועל" - יש למלא את מספר התלמידים עבורם הרשות דורשת תשלום.
B21: 4 | C21: בעמודות I, H "תקופת הפעילות" - יש לרשום את תאריכי הפתיחה והסגירה בני הילדים.
B22: 5 | C22: בבתי"ס בהם מספר הימים נמוך מ- 15 יש לציין בעמודה L את הסיבה (לדוגמא: פעילות עד ט' באב, איחוד עם בי"ס אחר בגלל מיעוט משתתפים וכו') וכן בעמודה M האם אושר ע"י המשרד. כמו כן בגנים בהם מספר התלמידים נמוך ממינימום משתתפים - 15 תלמידים יש לציין את הסיבה לכך ולצרף את אישור כאסמכתא.
A23: עלויות כח אדם (6) | B23: 1 | C23: בכל שורה בטבלה, יש למלא את התא בעמודה I רק לאחר מילוי התא בעמודה H. בעמודות אלו יש לבחור את סוג איש הצוות ואת התפקיד מתוך הרשימה הנפתחת, סעיפים שיירשמו באופן שונה לא ייכנסו לחישוב התשלום בגיליון (10). יש לשים לב שחלק מהתאים בעמודה I ימולאו באופן אוטומטי ללא צורך בבחירה מתוך הרשימה הנפתחת (התאים ייצבעו בלבן אוטומטית).
A24: סייעות רפואיות או אישיות (7) | B24: 1 | C24: יש למלא סייעות רפואיות או אישיות שהועסקו במהלך הפעילות ומספרי הזהות של התלמידים הזכאים במהלך השנה.
A25: רכזות גנים - דוח ביצוע (8) | B25: 1 | C25: בעמודה C - יש למלא את סמלי הגנים עבורם בהם הועסק/ה בפועל רכז/ת גנים.
B26: 2 | C26: בעמודה G - יש למלא את היקף המשרה שהועסק/ה רכז/ת הגנים עבור הגן שבאותה שורה.
A27: איוש משרות (9) | B27: 1 | C27: בגיליון זה אין צורך להזין נתונים, נתוני איוש המשרות נלקחים מגיליון 'פירוט עלויות כח אדם (6)', נתוני המוסדות וכמות תלמידים נלקחים מגיליון 'גנים-דוח ביצוע (5)' במידה ויש לרשות הערות ניתן לציין בעמודה L.
B28: 2 | C28: שימו לב, בהתאם לסעיף ג.1.ב. בקול קורא איוש הצוות החינוכי במתכונות שמפורטת בקול קורא הינם תנאי סף לתקצוב התוכנית כולה.
A29: גיליון ריכוז נתונים (10) | B29: 1 | C29: בגיליון זה אין צורך להזין נתונים, הגיליון כולו מחושב עפ"י הנתונים שמולאו בגיליונות 1-8 כאמור לעיל.

Sheet גנים ובתי ספר- מבנה תקציב
E1: תכנית בתי הספר והגנים של החופש הגדול, קיץ תשפ"ו
E2: חישוב לפי מרכיבי התקצוב והעלויות שפורסמו
A4: א. | B4: מבנה תקציבי גנים
B6: מפתח עלות לתלמיד - כל האשכולות כולל גבייה מהורים
B7: סוג המסגרת | C7: סוג עלות | D7: מספר ימים/תלמידים | E7: סל ניהול ותפעול | F7: סל הדרכה | G7: סל העשרה | H7: סל גמיש | I7: סה"כ
B8: גן רגיל | C8: כוללת למסגרת של 25 תלמידים | D8: 5 | E8: 428 | F8: 3920 | G8: 1400 | H8: 800 | I8: =SUM(E8:H8) -> 6548
D9: משקל יחסי | E9: =E8/$I$8 -> 0.06536347 | F9: =F8/$I$8 -> 0.59865608 | G9: =G8/$I$8 -> 0.21380574 | H9: =H8/$I$8 -> 0.12217471 | I9: =SUM(E9:H9) -> 1
C10: לתלמיד נורמטיבי | D10: לתלמיד ליום | E10: =E8/25/5 -> 3.424 | F10: =F8/25/5 -> 31.36 | G10: =G8/25/5 -> 11.2 | H10: =H8/25/5 -> 6.4 | I10: =I8/25/5 -> 52.384
D11: לתלמיד ל- 15 ימים | E11: =E10*15 -> 51.36 | F11: =F10*15 -> 470.4 | G11: =G10*15 -> 168 | H11: =H10*15 -> 96 | I11: =I8/25*3 -> 785.76
C12: הרחבה | D12: 5 | E12: 497 | F12: 4895 | G12: 1400 | H12: 800 | I12: =SUM(E12:H12) -> 7592
D13: משקל יחסי | E13: =E12/$I$12 -> 0.065463646 | F13: =F12/$I$12 -> 0.64475764 | G13: =G12/$I$12 -> 0.18440464 | H13: =H12/$I$12 -> 0.10537408 | I13: =SUM(E13:H13) -> 1
D14: לתלמיד ליום | E14: =E12/25/5 -> 3.976 | F14: =F12/25/5 -> 39.16 | G14: =G12/25/5 -> 11.2 | H14: =H12/25/5 -> 6.4 | I14: =I12/25/5 -> 60.736
D15: לתלמיד ל- 7 ימים | E15: =E14*7 -> 27.832 | F15: =F14*7 -> 274.12 | G15: =G14*7 -> 78.4 | H15: =H14*7 -> 44.8 | I15: =I14*7 -> 425.152
B18: עלות קבועה לרכזת גנים שאושרה
B19: סוג המסגרת | C19: סוג עלות | D19: מספר ימים | E19: עלות לרכזת | F19: עלות לגן
B20: גנים | C20: שכר עבור ריכוז 5 גנים בהם המובילה איננה גננת, לפי 5 שעות ביום ו- 103.6 ש"ח עלות שעה | D20: 7 | E20: =6*D20*103.6 -> 4351.2 | F20: =E20/5 -> 870.24
B22: מפתח השתתפויות לתלמיד גן
B24: מפתח השתתפויות לתלמיד ח. רגיל | G24: =I11 -> 785.76 | H24: =I15 -> 425.152
B25: אשכול למ"ס | C25: גבייה מההורים | D25: גבייה מההורים - הרחבה | E25: סבסוד המשרד - חינוך רגיל | F25: סבסוד המשרד - חינוך רגיל -הרחבה | G25: אחוז הסבסוד חינוך רגיל | H25: אחוז הסבסוד חינוך רגיל-הרחבה
B26: 1 | C26: 75 | D26: 35 | E26: =$G$24-C26 -> 710.76 | F26: =$H$24-D26 -> 390.152 | G26: =1-C26/$G$24 -> 0.90455101 | H26: =1-D26/$H$24 -> 0.9176765
B27: 2 | C27: 75 | D27: 35 | E27: =$G$24-C27 -> 710.76 | F27: =$H$24-D27 -> 390.152 | G27: =1-C27/$G$24 -> 0.90455101 | H27: =1-D27/$H$24 -> 0.9176765
B28: 3 | C28: 75 | D28: 35 | E28: =$G$24-C28 -> 710.76 | F28: =$H$24-D28 -> 390.152 | G28: =1-C28/$G$24 -> 0.90455101 | H28: =1-D28/$H$24 -> 0.9176765
B29: 4 | C29: 75 | D29: 35 | E29: =$G$24-C29 -> 710.76 | F29: =$H$24-D29 -> 390.152 | G29: =1-C29/$G$24 -> 0.90455101 | H29: =1-D29/$H$24 -> 0.9176765
B30: 5 | C30: 300 | D30: 140 | E30: =$G$24-C30 -> 485.76 | F30: =$H$24-D30 -> 285.152 | G30: =1-C30/$G$24 -> 0.61820403 | H30: =1-D30/$H$24 -> 0.67070601
B31: 6 | C31: 300 | D31: 140 | E31: =$G$24-C31 -> 485.76 | F31: =$H$24-D31 -> 285.152 | G31: =1-C31/$G$24 -> 0.61820403 | H31: =1-D31/$H$24 -> 0.67070601
B32: 7 | C32: 300 | D32: 140 | E32: =$G$24-C32 -> 485.76 | F32: =$H$24-D32 -> 285.152 | G32: =1-C32/$G$24 -> 0.61820403 | H32: =1-D32/$H$24 -> 0.67070601
B33: 8 | C33: 450 | D33: 210 | E33: =$G$24-C33 -> 335.76 | F33: =$H$24-D33 -> 215.152 | G33: =1-C33/$G$24 -> 0.42730605 | H33: =1-D33/$H$24 -> 0.50605901
B34: 9 | C34: 450 | D34: 210 | E34: =$G$24-C34 -> 335.76 | F34: =$H$24-D34 -> 215.152 | G34: =1-C34/$G$24 -> 0.42730605 | H34: =1-D34/$H$24 -> 0.50605901
B35: 10 | C35: 450 | D35: 210 | E35: =$G$24-C35 -> 335.76 | F35: =$H$24-D35 -> 215.152 | G35: =1-C35/$G$24 -> 0.42730605 | H35: =1-D35/$H$24 -> 0.50605901
A37: ב. | B37: מבנה תקציבי בתי ספר
B39: בית ספר - עלות לתלמיד
B40: מפתח עלות לתלמיד - כל האשכולות כולל גבייה מהורים
B41: סוג המסגרת | C41: סוג עלות | D41: מספר ימים | E41: סל ניהול ותפעול | F41: סל הדרכה | G41: סל העשרה | H41: סל גמיש | I41: סה"כ
B42: בי"ס רגיל | C42: כוללת למסגרת של 28 תלמידים | D42: 5 | E42: 396 | F42: 3108 | G42: 1550 | H42: 1000 | I42: =SUM(E42:H42) -> 6054
D43: משקל יחסי | E43: =E42/$I$42 -> 0.065411298 | F43: =F42/$I$42 -> 0.51337958 | G43: =G42/$I$42 -> 0.25602907 | H43: =H42/$I$42 -> 0.16518005 | I43: =SUM(E43:H43) -> 1
C44: לפי תלמיד נורמטיבי לתקופה | D44: לתלמיד ליום | E44: =E43*$I$44 -> 2.8285714 | F44: =F43*$I$44 -> 22.2 | G44: =G43*$I$44 -> 11.071429 | H44: =H43*$I$44 -> 7.1428571 | I44: =I42/28/5 -> 43.242857
D45: לתלמיד ל- 15 ימים | E45: =E43*$I$45 -> 42.428571 | F45: =F43*$I$45 -> 333 | G45: =G43*$I$45 -> 166.07143 | H45: =H43*$I$45 -> 107.14286 | I45: =I42/28*3 -> 648.64286
D46: לתלמיד ל- 7 ימים | E46: =E44*7 -> 19.8 | F46: =F44*7 -> 155.4 | G46: =G44*7 -> 77.5 | H46: =H44*7 -> 50 | I46: =SUM(E46:H46) -> 302.7
B47: בי"ס חנ"מ | C47: כוללת למסגרת של 8 תלמידים | D47: 5 | E47: 324 | F47: 3108 | G47: 1215 | H47: 300 | I47: =SUM(E47:H47) -> 4947
D48: משקל יחסי | E48: =E47/$I$47 -> 0.065494239 | F48: =F47/$I$47 -> 0.62825955 | G48: =G47/$I$47 -> 0.2456034 | H48: =H47/$I$47 -> 0.060642814 | I48: =SUM(E48:H48) -> 1
...

Sheet נתונים כללים (1)
A1: תוכן העניינים | C1: תכנית בתי הספר והגנים של החופש הגדול, קיץ תשפ"ו
B3: נתונים כללים
E4: =IF(AND(E5=" ",E6=" ",E7=" ")," ","שגיאות בגיליון:") -> שגיאות בגיליון:
B5: שם הרשות המקומית | C5: באר טוביה | E5: =IF(ISBLANK(C5),"יש לבחור את שם הרשות מהרשימה הנפתחת"," ") -> יש לבחור את שם הרשות מהרשימה הנפתחת
B6: מספר אשכול למ"ס | C6: =IFERROR(VLOOKUP($C$5,'רשימת רשויות'!A:B,2,0),"") | E6: =IF(C13="","יש למלא נתוני אנשי קשר ברשות"," ") -> יש למלא נתוני אנשי קשר ברשות
B7: תעריף לילד חלק ההורים - ש"ח | C7: =IFERROR(VLOOKUP(C6,'גנים ובתי ספר- מבנה תקציב'!$B$25:$D$35,3,0),0) -> 0 | E7: {=IF(טבלה22[שם הגוף המפעיל ו/או מעסיק את העובדים]="","יש למלא נתוני מפעילי התכנית"," ")} -> יש למלא נתוני מפעילי התכנית
B10: אנשי קשר ברשות
B12: תפקיד | C12: שם פרטי | D12: שם משפחה | E12: טלפון | F12: מייל
B13: גזבר | C13: ענבל | D13: ברמי | F13: inbalb@beer-tuvia.org.il
B14: מנהלת מחלקת חינוך | C14: דורון | D14: חנין | F14: doronh@beer-tuvia.org.il
A15: אנשי קשר נוספים:
B18: מפעילי התכנית
A19: מס' סידורי | B19: שם הגוף המפעיל ו/או מעסיק את העובדים | C19: מספר עמותה/ חברה/ עוסק | D19: מפתח חלוקה בין מפעילים | E19: פרטי חברה מנהלת | F19: הערות
A20: 1 | B20: אמיתי לוי יזמות בע"מ | C20: 516498417 | F20: קייטנת בוקר
A21: 2
A22: 3
A23: 4
A24: 5
A25: 6
A26: 7
A27: 8
A28: 9
A29: 10
A30: 11
A31: 12
A32: 13
... A49: 30

Sheet דוח הוצאות בפועל (2)
A1: תוכן העניינים | C1: תכנית בתי הספר והגנים של החופש הגדול, קיץ תשפ"ו
B3: שם הרשות המקומית | C3: ='נתונים כללים (1)'!$C$5 -> 0
B4: מספר אשכול למ"ס | C4: ='נתונים כללים (1)'!$C$6
B5: תעריף לילד חלק ההורים - ש"ח | C5: ='נתונים כללים (1)'!$C$7 -> 0
B7: דוח ביצוע כספי - הוצאות בפועל
A9: סידורי | B9: סלים | C9: סכום ההוצאה בפועל | D9: מספר כרטיס ספק בהנהלת חשבונות | E9: מקור הפעלה (רשות/קבלן משנה)
A10: 1 | B10: העשרה
A11: 2 | B11: ארוחת בוקר
A12: 3 | B12: מלגות להורים
B13: סה"כ הוצאות לפעילות | C13: =SUM(C10:C12) -> 0
A14: 4 | B14: ניהול ותפעול
B15: סה"כ הוצאות לתכנית | C15: =SUM(C13:C14) -> 0

Sheet תשלומי הורים ומלגות להורים (3) 
A1: תוכן העניינים | C1: תכנית בתי הספר והגנים של החופש הגדול, קיץ תשפ"ו
B3: שם הרשות המקומית | C3: ='נתונים כללים (1)'!$C$5 -> 0
B4: מספר אשכול למ"ס | C4: ='נתונים כללים (1)'!$C$6
B5: תעריף לילד חלק ההורים - ש"ח | C5: ='נתונים כללים (1)'!$C$7 -> 0
B8: דוח ביצוע כספי - הכנסות בפועל עבור חלק ההורים
M9: בקרות
B10: סלים | C10: הכנסות בפועל - ש"ח | D10: מלגות להורים | E10: הכנסות נטו | F10: נרשם ברשות בכרטיס הנה"ח מס' | G10: שם כרטיס | H10: כמות ילדים להם ניתנו מלגות | I10: כמות ילדים - גביה | J10: ממוצע גביה לילד | K10: כמות ילדים מדווחים | M10: הפרש כמות ילדים דיווח לעומת גביה | N10: הפרש גביה לילד לעומת תעריף לילד | O10: הסבר הרשות במידה ויש הפרש
B11: גבייה בפועל מהורים | D11: ='דוח הוצאות בפועל (2)'!$C$12 -> 0 | E11: =C11-D11 -> 0 | J11: =IFERROR(C11/I11,0) -> 0 | K11: ='גנים - מצבת והרשמה (4)'!G10 -> 0 | M11: =K11-I11 -> 0 | N11: =IF(J11>0,C5-J11,0) -> 0
B12: סה"כ הכנסות לתכנית עבור חלק ההורים | C12: =SUM(C11:C11) -> 0

Sheet גנים - מצבת והרשמה  (4)
A1: תוכן העניינים | D1: תכנית בתי הספר והגנים של החופש הגדול, קיץ תשפ"ו
B3: שם הרשות המקומית | D3: ='נתונים כללים (1)'!$C$5 -> 0
B4: סוג מוסד | D4: גנים | F4: בגיליון זה אין צורך להזין נתונים!
B5: מספר אשכול למ"ס | D5: ='נתונים כללים (1)'!$C$6
D7: גנים חינוך רגיל - מצבת תלמידים והרשמה
B9: סיכום | D9: מספר גנים חינוך רגיל | E9: מספר גנים בהם מתקיימת פעילות | F9: סה"כ ילדים במצבת סוף שנה | G9: מספר ילדים שנרשמו
D10: =COUNTIF(סמלים,">1") -> 0 | E10: =SUM(IF(FREQUENCY($F$16:$F$1015,$F$16:$F$1015)>0,1)) -> 0 | F10: =SUM($G$16:$G$1015) -> 0 | G10: =SUM($H$16:$H$1015) -> 0
E12: במידה ונתוני הרישום הרשומים בקובץ אינם תואמים לנתונים המאושרים על ידי משה"ח,
E13: יש לרשום מייל מפורט לכתובת: hofesh-gadol26@cdk-cpa.co.il
B15: מס' סידורי | C15: סמל גן | D15: שם הגן | E15: מעמד - רשמי/ מוכש"ר | F15: סמל גן בו מתקיימת הפעילות | G15: מספר ילדים במצבת סוף שנה | H15: מספר ילדים שנרשמו
B16: 1 | C16: {=IFERROR( INDEX('מצבת ורישום גנים'!B:$B, SMALL( IF(('מצבת ורישום גנים'!$A$3:$A$18000='נתונים כללים (1)'!$C$5), ROW('מצבת ורישום גנים'!$A$3:$A$18000)), ROW(A1)) ), "")} -> 0 | D16: =IF(C16="", "", IFERROR( IF(VLOOKUP(C16, 'מצבת ורישום גנים'!B:H,7, FALSE) =$D$3, VLOOKUP(C16,'מצבת ורישום גנים'!B:D, 3, FALSE), "המוסד לא קיים ברשות"), "המוסד לא קיים")) -> המוסד לא קיים | E16: =IFERROR(VLOOKUP(C16,'מצבת ורישום גנים'!B:G,6,0),"") | F16: =IFERROR(VLOOKUP(C:C,'מצבת ורישום גנים'!B:I,8,0)," ") | G16: =IFERROR(VLOOKUP(C:C,'מצבת ורישום גנים'!B:H,4,0),"") | H16: =IFERROR(VLOOKUP(C:C,'מצבת ורישום גנים'!B:H,5,0),"")
B17: 2 | C17: {=IFERROR( INDEX('מצבת ורישום גנים'!B:$B, SMALL( IF(('מצבת ורישום גנים'!$A$3:$A$18000='נתונים כללים (1)'!$C$5), ROW('מצבת ורישום גנים'!$A$3:$A$18000)), ROW(A2)) ), "")} -> 0 | D17: =IF(C17="", "", IFERROR( IF(VLOOKUP(C17, 'מצבת ורישום גנים'!B:H,7, FALSE) =$D$3, VLOOKUP(C17,'מצבת ורישום גנים'!B:D, 3, FALSE), "המוסד לא קיים ברשות"), "המוסד לא קיים")) -> המוסד לא קיים | E17: =IFERROR(VLOOKUP(C17,'מצבת ורישום גנים'!B:G,6,0),"") | F17: =IFERROR(VLOOKUP(C:C,'מצבת ורישום גנים'!B:I,8,0)," ") | G17: =IFERROR(VLOOKUP(C:C,'מצבת ורישום גנים'!B:H,4,0),"") | H17: =IFERROR(VLOOKUP(C:C,'מצבת ורישום גנים'!B:H,5,0),"")
B18: 3 | C18: {=IFERROR( INDEX('מצבת ורישום גנים'!B:$B, SMALL( IF(('מצבת ורישום גנים'!$A$3:$A$18000='נתונים כללים (1)'!$C$5), ROW('מצבת ורישום גנים'!$A$3:$A$18000)), ROW(A3)) ), "")} -> 0 | D18: =IF(C18="", "", IFERROR( IF(VLOOKUP(C18, 'מצבת ורישום גנים'!B:H,7, FALSE) =$D$3, VLOOKUP(C18,'מצבת ורישום גנים'!B:D, 3, FALSE), "המוסד לא קיים ברשות"), "המוסד לא קיים")) -> המוסד לא קיים | E18: =IFERROR(VLOOKUP(C18,'מצבת ורישום גנים'!B:G,6,0),"") | F18: =IFERROR(VLOOKUP(C:C,'מצבת ורישום גנים'!B:I,8,0)," ") | G18: =IFERROR(VLOOKUP(C:C,'מצבת ורישום גנים'!B:H,4,0),"") | H18: =IFERROR(VLOOKUP(C:C,'מצבת ורישום גנים'!B:H,5,0),"")
B19: 4 | C19: {=IFERROR( INDEX('מצבת ורישום גנים'!B:$B, SMALL( IF(('מצבת ורישום גנים'!$A$3:$A$18000='נתונים כללים (1)'!$C$5), ROW('מצבת ורישום גנים'!$A$3:$A$18000)), ROW(A4)) ), "")} -> 0 | D19: =IF(C19="", "", IFERROR( IF(VLOOKUP(C19, 'מצבת ורישום גנים'!B:H,7, FALSE) =$D$3, VLOOKUP(C19,'מצבת ורישום גנים'!B:D, 3, FALSE), "המוסד לא קיים ברשות"), "המוסד לא קיים")) -> המוסד לא קיים | E19: =IFERROR(VLOOKUP(C19,'מצבת ורישום גנים'!B:G,6,0),"") | F19: =IFERROR(VLOOKUP(C:C,'מצבת ורישום גנים'!B:I,8,0)," ") | G19: =IFERROR(VLOOKUP(C:C,'מצבת ורישום גנים'!B:H,4,0),"") | H19: =IFERROR(VLOOKUP(C:C,'מצבת ורישום גנים'!B:H,5,0),"")
B20: 5 | C20: {=IFERROR( INDEX('מצבת ורישום גנים'!B:$B, SMALL( IF(('מצבת ורישום גנים'!$A$3:$A$18000='נתונים כללים (1)'!$C$5), ROW('מצבת ורישום גנים'!$A$3:$A$18000)), ROW(A5)) ), "")} -> 0 | D20: =IF(C20="", "", IFERROR( IF(VLOOKUP(C20, 'מצבת ורישום גנים'!B:H,7, FALSE) =$D$3, VLOOKUP(C20,'מצבת ורישום גנים'!B:D, 3, FALSE), "המוסד לא קיים ברשות"), "המוסד לא קיים")) -> המוסד לא קיים | E20: =IFERROR(VLOOKUP(C20,'מצבת ורישום גנים'!B:G,6,0),"") | F20: =IFERROR(VLOOKUP(C:C,'מצבת ורישום גנים'!B:I,8,0)," ") | G20: =IFERROR(VLOOKUP(C:C,'מצבת ורישום גנים'!B:H,4,0),"") | H20: =IFERROR(VLOOKUP(C:C,'מצבת ורישום גנים'!B:H,5,0),"")
B21: 6 | C21: {=IFERROR( INDEX('מצבת ורישום גנים'!B:$B, SMALL( IF(('מצבת ורישום גנים'!$A$3:$A$18000='נתונים כללים (1)'!$C$5), ROW('מצבת ורישום גנים'!$A$3:$A$18000)), ROW(A6)) ), "")} -> 0 | D21: =IF(C21="", "", IFERROR( IF(VLOOKUP(C21, 'מצבת ורישום גנים'!B:H,7, FALSE) =$D$3, VLOOKUP(C21,'מצבת ורישום גנים'!B:D, 3, FALSE), "המוסד לא קיים ברשות"), "המוסד לא קיים")) -> המוסד לא קיים | E21: =IFERROR(VLOOKUP(C21,'מצבת ורישום גנים'!B:G,6,0),"") | F21: =IFERROR(VLOOKUP(C:C,'מצבת ורישום גנים'!B:I,8,0)," ") | G21: =IFERROR(VLOOKUP(C:C,'מצבת ורישום גנים'!B:H,4,0),"") | H21: =IFERROR(VLOOKUP(C:C,'מצבת ורישום גנים'!B:H,5,0),"")
B22: 7 | C22: {=IFERROR( INDEX('מצבת ורישום גנים'!B:$B, SMALL( IF(('מצבת ורישום גנים'!$A$3:$A$18000='נתונים כללים (1)'!$C$5), ROW('מצבת ורישום גנים'!$A$3:$A$18000)), ROW(A7)) ), "")} -> 0 | D22: =IF(C22="", "", IFERROR( IF(VLOOKUP(C22, 'מצבת ורישום גנים'!B:H,7, FALSE) =$D$3, VLOOKUP(C22,'מצבת ורישום גנים'!B:D, 3, FALSE), "המוסד לא קיים ברשות"), "המוסד לא קיים")) -> המוסד לא קיים | E22: =IFERROR(VLOOKUP(C22,'מצבת ורישום גנים'!B:G,6,0),"") | F22: =IFERROR(VLOOKUP(C:C,'מצבת ורישום גנים'!B:I,8,0)," ") | G22: =IFERROR(VLOOKUP(C:C,'מצבת ורישום גנים'!B:H,4,0),"") | H22: =IFERROR(VLOOKUP(C:C,'מצבת ורישום גנים'!B:H,5,0),"")
B23: 8 | C23: {=IFERROR( INDEX('מצבת ורישום גנים'!B:$B, SMALL( IF(('מצבת ורישום גנים'!$A$3:$A$18000='נתונים כללים (1)'!$C$5), ROW('מצבת ורישום גנים'!$A$3:$A$18000)), ROW(A8)) ), "")} -> 0 | D23: =IF(C23="", "", IFERROR( IF(VLOOKUP(C23, 'מצבת ורישום גנים'!B:H,7, FALSE) =$D$3, VLOOKUP(C23,'מצבת ורישום גנים'!B:D, 3, FALSE), "המוסד לא קיים ברשות"), "המוסד לא קיים")) -> המוסד לא קיים | E23: =IFERROR(VLOOKUP(C23,'מצבת ורישום גנים'!B:G,6,0),"") | F23: =IFERROR(VLOOKUP(C:C,'מצבת ורישום גנים'!B:I,8,0)," ") | G23: =IFERROR(VLOOKUP(C:C,'מצבת ורישום גנים'!B:H,4,0),"") | H23: =IFERROR(VLOOKUP(C:C,'מצבת ורישום גנים'!B:H,5,0),"")
B24: 9 | C24: {=IFERROR( INDEX('מצבת ורישום גנים'!B:$B, SMALL( IF(('מצבת ורישום גנים'!$A$3:$A$18000='נתונים כללים (1)'!$C$5), ROW('מצבת ורישום גנים'!$A$3:$A$18000)), ROW(A9)) ), "")} -> 0 | D24: =IF(C24="", "", IFERROR( IF(VLOOKUP(C24, 'מצבת ורישום גנים'!B:H,7, FALSE) =$D$3, VLOOKUP(C24,'מצבת ורישום גנים'!B:D, 3, FALSE), "המוסד לא קיים ברשות"), "המוסד לא קיים")) -> המוסד לא קיים | E24: =IFERROR(VLOOKUP(C24,'מצבת ורישום גנים'!B:G,6,0),"") | F24: =IFERROR(VLOOKUP(C:C,'מצבת ורישום גנים'!B:I,8,0)," ") | G24: =IFERROR(VLOOKUP(C:C,'מצבת ורישום גנים'!B:H,4,0),"") | H24: =IFERROR(VLOOKUP(C:C,'מצבת ורישום גנים'!B:H,5,0),"")
B25: 10 | C25: {=IFERROR( INDEX('מצבת ורישום גנים'!B:$B, SMALL( IF(('מצבת ורישום גנים'!$A$3:$A$18000='נתונים כללים (1)'!$C$5), ROW('מצבת ורישום גנים'!$A$3:$A$18000)), ROW(A10)) ), "")} -> 0 | D25: =IF(C25="", "", IFERROR( IF(VLOOKUP(C25, 'מצבת ורישום גנים'!B:H,7, FALSE) =$D$3, VLOOKUP(C25,'מצבת ורישום גנים'!B:D, 3, FALSE), "המוסד לא קיים ברשות"), "המוסד לא קיים")) -> המוסד לא קיים | E25: =IFERROR(VLOOKUP(C25,'מצבת ורישום גנים'!B:G,6,0),"") | F25: =IFERROR(VLOOKUP(C:C,'מצבת ורישום גנים'!B:I,8,0)," ") | G25: =IFERROR(VLOOKUP(C:C,'מצבת ורישום גנים'!B:H,4,0),"") | H25: =IFERROR(VLOOKUP(C:C,'מצבת ורישום גנים'!B:H,5,0),"")
B26: 11 | C26: {=IFERROR( INDEX('מצבת ורישום גנים'!B:$B, SMALL( IF(('מצבת ורישום גנים'!$A$3:$A$18000='נתונים כללים (1)'!$C$5), ROW('מצבת ורישום גנים'!$A$3:$A$18000)), ROW(A11)) ), "")} -> 0 | D26: =IF(C26="", "", IFERROR( IF(VLOOKUP(C26, 'מצבת ורישום גנים'!B:H,7, FALSE) =$D$3, VLOOKUP(C26,'מצבת ורישום גנים'!B:D, 3, FALSE), "המוסד לא קיים ברשות"), "המוסד לא קיים")) -> המוסד לא קיים | E26: =IFERROR(VLOOKUP(C26,'מצבת ורישום גנים'!B:G,6,0),"") | F26: =IFERROR(VLOOKUP(C:C,'מצבת ורישום גנים'!B:I,8,0)," ") | G26: =IFERROR(VLOOKUP(C:C,'מצבת ורישום גנים'!B:H,4,0),"") | H26: =IFERROR(VLOOKUP(C:C,'מצבת ורישום גנים'!B:H,5,0),"")
B27: 12 | C27: {=IFERROR( INDEX('מצבת ורישום גנים'!B:$B, SMALL( IF(('מצבת ורישום גנים'!$A$3:$A$18000='נתונים כללים (1)'!$C$5), ROW('מצבת ורישום גנים'!$A$3:$A$18000)), ROW(A12)) ), "")} -> 0 | D27: =IF(C27="", "", IFERROR( IF(VLOOKUP(C27, 'מצבת ורישום גנים'!B:H,7, FALSE) =$D$3, VLOOKUP(C27,'מצבת ורישום גנים'!B:D, 3, FALSE), "המוסד לא קיים ברשות"), "המוסד לא קיים")) -> המוסד לא קיים | E27: =IFERROR(VLOOKUP(C27,'מצבת ורישום גנים'!B:G,6,0),"") | F27: =IFERROR(VLOOKUP(C:C,'מצבת ורישום גנים'!B:I,8,0)," ") | G27: =IFERROR(VLOOKUP(C:C,'מצבת ורישום גנים'!B:H,4,0),"") | H27: =IFERROR(VLOOKUP(C:C,'מצבת ורישום גנים'!B:H,5,0),"")
... B1015: 1000 | C1015: {=IFERROR( INDEX('מצבת ורישום גנים'!B:$B, SMALL( IF(('מצבת ורישום גנים'!$A$3:$A$18000='נתונים כללים (1)'!$C$5), ROW('מצבת ורישום גנים'!$A$3:$A$18000)), ROW(A1000)) ), "")} | D1015: =IF(C1015="", "", IFERROR( IF(VLOOKUP(C1015, 'מצבת ורישום גנים'!B:H,7, FALSE) =$D$3, VLOOKUP(C1015,'מצבת ורישום גנים'!B:D, 3, FALSE), "המוסד לא קיים ברשות"), "המוסד לא קיים")) | E1015: =IFERROR(VLOOKUP(C1015,'מצבת ורישום גנים'!B:G,6,0),"") | F1015: =IFERROR(VLOOKUP(C:C,'מצבת ורישום גנים'!B:I,8,0)," ") | G1015: =IFERROR(VLOOKUP(C:C,'מצבת ורישום גנים'!B:H,4,0),"") | H1015: =IFERROR(VLOOKUP(C:C,'מצבת ורישום גנים'!B:H,5,0),"")

Sheet גנים - דוח ביצוע  (5)
A1: תוכן העניינים | E1: תכנית בתי הספר והגנים של החופש הגדול, קיץ תשפ"ו | K1: * | Q1: * | R1: *
L2: =IF(AND(L3="",L4="",L5="",L6="")," ","שגיאות בגיליון:") | Q2: תנאי סף לתקצוב: 0=לפרסום, 1=פעיל | R2: 0
C3: שם הרשות המקומית | E3: ='נתונים כללים (1)'!$C$5 -> 0 | L3: =IF(G11<D11,CONCATENATE("דווחו ",G11," גנים, מתוך ",D11," גנים שנרשמו."),"") | Q3: תנאי סף ימי פעילות | R3: 6
C4: סוג מוסד | E4: גנים | L4: {=IF(SUMPRODUCT((COUNTIF(B18:B1000,B18:B1000)>1)/IF(B18:B1000="",1,COUNTIF(B18:B1000,B18:B1000)))>0,CONCATENATE("קיימים ",SUMPRODUCT((COUNTIF(B18:B1000,B18:B1000)>1)/IF(B18:B1000="",1,COUNTIF(B18:B1000,B18:B1000)))," מוסדות שמופיעים יותר מפעם אחת בדיווח."),"")}
C5: מספר אשכול למ"ס | E5: ='נתונים כללים (1)'!$C$6 | L5: =IF(SUM($R$18:$R$1000)>0,CONCATENATE("קיימים ",SUM($R$18:$R$1000)," מוסדות בהם לא מולאו נתונים לגבי מספר התלמידים שהשתתפו בתוכנית."),"")
L6: =IF(SUM($Q$18:$Q$1000)>0,CONCATENATE("קיימים ",SUM($Q$18:$Q$1000)," מוסדות בהם לא מולאו נתונים לגבי תקופת הפעילות."),"")
G7: דוח ביצוע מפורט לפי תלמידים - גנים בהם מופעלת התכנית
E9: נתוני הרשמה | G9: ביצוע בפועל | J9: נתונים לחישוב התקציב
C10: סיכום | D10: מס' גנים רשומים בהם מתקיימת פעילות | E10: מס' גנים מדווחים בהם מתקיימת פעילות | F10: מס' תלמידים רשומים חינוך רגיל | G10: מספר גנים ביצוע בפועל | H10: מס' ילדים ביצוע בפועל או רישום | I10: מס' גנים בהם המובילה אינה גננת | J10: מס' גנים שפעלו פחות מ- 7 ימים | L10: מס' ימי תלמיד להפחתה | M10: מס' תלמידי הפחתה מחושבים (חלקי 7) | N10: סה"כ מס' תלמידים
D11: ='גנים - מצבת והרשמה (4)'!E10 -> 0 | E11: =COUNTIF(E18:E1017,">0") -> 0 | F11: =SUM(E18:E1017) -> 0 | G11: =COUNTIF(F18:F1017,">0") -> 0 | H11: =SUM(F18:F1017) -> 0 | I11: =SUM(G18:G1017) -> 0 | J11: =COUNTIFS(J18:J1017,"<7",J18:J1017,">0") -> 0 | L11: =SUM(M18:M1017) -> 0 | M11: =ROUND(L11/7,0) -> 0 | N11: =SUM(N18:N1017) -> 0
B13: לתשומת ליבכם, סמל מוסד של גני ילדים בחטיבות צעירות ידווח כחלק מגני הילדים של הרשות בדו״ח הביצוע של גני הילדים.
C14: דוח ביצוע מפורט
B16: נתוני הרשמה מגליון מצבת והרשמה (4) | F16: ביצוע בפועל | H16: תקופת הפעילות-הרחבה | N16: נתונים לחישוב תקציב | O16: בקרות - יש לוודא כי לא קיימות שורות עם התראה
A17: מס' סידורי | B17: סמל גן בו מתקיימת הפעילות | C17: מפעיל התכנית | D17: שם הגן | E17: מספר תלמידים רשומים | F17: ביצוע בפועל - מס' תלמידים | G17: המובילה אינה גננת. סייעת=1 | H17: תאריך פתיחה | I17: תאריך סיום | J17: מספר ימי פעילות בפועל | K17: בדיקת תנאי קיום מלוא ימי הפעילות במלואם | L17: סיבות לחוסר ימים (פחות מ- 7 ימים) ו/או לחוסר תלמידים (פחות מ-15) | M17: הפחתה בגין חוסר ימים | N17: מס' ילדים לחישוב התקציב | O17: בקרת סמלי גנים בעמודה B | P17: בקרת מילוי מס' ימי פעילות - עמודה J | Q17: בקרת מילוי מס' ימי פעילות | R17: בקרת אי מילוי תלמידים
A18: 1 | D18: =IFERROR(VLOOKUP($B18,'גנים - מצבת והרשמה (4)'!$C$16:$G$807,2,0),0) -> המוסד לא קיים | E18: =SUMIF('גנים - מצבת והרשמה (4)'!$F$15:$F$996,'גנים - דוח ביצוע (5)'!B18,'גנים - מצבת והרשמה (4)'!$H$15:$H$996) -> 0 | J18: =MIN(NETWORKDAYS.INTL(H18,I18,7),7) -> 0 | K18: =IF(B18>0,IF(J18<$R$3,"תקופת הפעילות נמוכה מהתקופה הנדרשת, ועל כן המוסד אינו זכאי לתקצוב","תקין"),"") | M18: =IF(OR($R$2=0,K18="תקין"),ROUND(IF(J18=6,(7-J18)*MIN(E18,F18),0),0),0) -> 0 | N18: =IF(OR($R$2=0,K18="תקין"),MAX(IF(B18="",0,MIN(F18,E18))-M18/7,0),0) -> 0 | O18: =IF(IF(B18=0,0,IFERROR(COUNTIF($B$18:$B$1017,B18)," "))>1,"סמל הגן מופיע יותר מפעם אחת",IF(ISBLANK(B18),"","תקין")) | P18: =IF(ISNUMBER(B18),IF(J18<1,"יש למלא מס' ימי פעילות",IF(AND(J18<7,L18=""),"יש למלא סיבה לחוסר ימי פעילות","תקין")),"") | Q18: =IF(LEFT(P18,10)="יש למלא מס",1,0) -> 0 | R18: =IF(B18>0,IF(F18=0,1,0),0) -> 0
A19: 2 | D19: =IFERROR(VLOOKUP($B19,'גנים - מצבת והרשמה (4)'!$C$16:$G$807,2,0),0) -> המוסד לא קיים | E19: =SUMIF('גנים - מצבת והרשמה (4)'!$F$15:$F$996,'גנים - דוח ביצוע (5)'!B19,'גנים - מצבת והרשמה (4)'!$H$15:$H$996) -> 0 | J19: =MIN(NETWORKDAYS.INTL(H19,I19,7),7) -> 0 | K19: =IF(B19>0,IF(J19<$R$3,"תקופת הפעילות נמוכה מהתקופה הנדרשת, ועל כן המוסד אינו זכאי לתקצוב","תקין"),"") | M19: =IF(OR($R$2=0,K19="תקין"),ROUND(IF(J19=6,(7-J19)*MIN(E19,F19),0),0),0) -> 0 | N19: =IF(OR($R$2=0,K19="תקין"),MAX(IF(B19="",0,MIN(F19,E19))-M19/7,0),0) -> 0 | O19: =IF(IF(B19=0,0,IFERROR(COUNTIF($B$18:$B$1017,B19)," "))>1,"סמל הגן מופיע יותר מפעם אחת",IF(ISBLANK(B19),"","תקין")) | P19: =IF(ISNUMBER(B19),IF(J19<1,"יש למלא מס' ימי פעילות",IF(AND(J19<7,L19=""),"יש למלא סיבה לחוסר ימי פעילות","תקין")),"") | Q19: =IF(LEFT(P19,10)="יש למלא מס",1,0) -> 0 | R19: =IF(B19>0,IF(F19=0,1,0),0) -> 0
A20: 3 | D20: =IFERROR(VLOOKUP($B20,'גנים - מצבת והרשמה (4)'!$C$16:$G$807,2,0),0) -> המוסד לא קיים | E20: =SUMIF('גנים - מצבת והרשמה (4)'!$F$15:$F$996,'גנים - דוח ביצוע (5)'!B20,'גנים - מצבת והרשמה (4)'!$H$15:$H$996) -> 0 | J20: =MIN(NETWORKDAYS.INTL(H20,I20,7),7) -> 0 | K20: =IF(B20>0,IF(J20<$R$3,"תקופת הפעילות נמוכה מהתקופה הנדרשת, ועל כן המוסד אינו זכאי לתקצוב","תקין"),"") | M20: =IF(OR($R$2=0,K20="תקין"),ROUND(IF(J20=6,(7-J20)*MIN(E20,F20),0),0),0) -> 0 | N20: =IF(OR($R$2=0,K20="תקין"),MAX(IF(B20="",0,MIN(F20,E20))-M20/7,0),0) -> 0 | O20: =IF(IF(B20=0,0,IFERROR(COUNTIF($B$18:$B$1017,B20)," "))>1,"סמל הגן מופיע יותר מפעם אחת",IF(ISBLANK(B20),"","תקין")) | P20: =IF(ISNUMBER(B20),IF(J20<1,"יש למלא מס' ימי פעילות",IF(AND(J20<7,L20=""),"יש למלא סיבה לחוסר ימי פעילות","תקין")),"") | Q20: =IF(LEFT(P20,10)="יש למלא מס",1,0) -> 0 | R20: =IF(B20>0,IF(F20=0,1,0),0) -> 0
A21: 4 | D21: =IFERROR(VLOOKUP($B21,'גנים - מצבת והרשמה (4)'!$C$16:$G$807,2,0),0) -> המוסד לא קיים | E21: =SUMIF('גנים - מצבת והרשמה (4)'!$F$15:$F$996,'גנים - דוח ביצוע (5)'!B21,'גנים - מצבת והרשמה (4)'!$H$15:$H$996) -> 0 | J21: =MIN(NETWORKDAYS.INTL(H21,I21,7),7) -> 0 | K21: =IF(B21>0,IF(J21<$R$3,"תקופת הפעילות נמוכה מהתקופה הנדרשת, ועל כן המוסד אינו זכאי לתקצוב","תקין"),"") | M21: =IF(OR($R$2=0,K21="תקין"),ROUND(IF(J21=6,(7-J21)*MIN(E21,F21),0),0),0) -> 0 | N21: =IF(OR($R$2=0,K21="תקין"),MAX(IF(B21="",0,MIN(F21,E21))-M21/7,0),0) -> 0 | O21: =IF(IF(B21=0,0,IFERROR(COUNTIF($B$18:$B$1017,B21)," "))>1,"סמל הגן מופיע יותר מפעם אחת",IF(ISBLANK(B21),"","תקין")) | P21: =IF(ISNUMBER(B21),IF(J21<1,"יש למלא מס' ימי פעילות",IF(AND(J21<7,L21=""),"יש למלא סיבה לחוסר ימי פעילות","תקין")),"") | Q21: =IF(LEFT(P21,10)="יש למלא מס",1,0) -> 0 | R21: =IF(B21>0,IF(F21=0,1,0),0) -> 0
A22: 5 | D22: =IFERROR(VLOOKUP($B22,'גנים - מצבת והרשמה (4)'!$C$16:$G$807,2,0),0) -> המוסד לא קיים | E22: =SUMIF('גנים - מצבת והרשמה (4)'!$F$15:$F$996,'גנים - דוח ביצוע (5)'!B22,'גנים - מצבת והרשמה (4)'!$H$15:$H$996) -> 0 | J22: =MIN(NETWORKDAYS.INTL(H22,I22,7),7) -> 0 | K22: =IF(B22>0,IF(J22<$R$3,"תקופת הפעילות נמוכה מהתקופה הנדרשת, ועל כן המוסד אינו זכאי לתקצוב","תקין"),"") | M22: =IF(OR($R$2=0,K22="תקין"),ROUND(IF(J22=6,(7-J22)*MIN(E22,F22),0),0),0) -> 0 | N22: =IF(OR($R$2=0,K22="תקין"),MAX(IF(B22="",0,MIN(F22,E22))-M22/7,0),0) -> 0 | O22: =IF(IF(B22=0,0,IFERROR(COUNTIF($B$18:$B$1017,B22)," "))>1,"סמל הגן מופיע יותר מפעם אחת",IF(ISBLANK(B22),"","תקין")) | P22: =IF(ISNUMBER(B22),IF(J22<1,"יש למלא מס' ימי פעילות",IF(AND(J22<7,L22=""),"יש למלא סיבה לחוסר ימי פעילות","תקין")),"") | Q22: =IF(LEFT(P22,10)="יש למלא מס",1,0) -> 0 | R22: =IF(B22>0,IF(F22=0,1,0),0) -> 0
A23: 6 | D23: =IFERROR(VLOOKUP($B23,'גנים - מצבת והרשמה (4)'!$C$16:$G$807,2,0),0) -> המוסד לא קיים | E23: =SUMIF('גנים - מצבת והרשמה (4)'!$F$15:$F$996,'גנים - דוח ביצוע (5)'!B23,'גנים - מצבת והרשמה (4)'!$H$15:$H$996) -> 0 | J23: =MIN(NETWORKDAYS.INTL(H23,I23,7),7) -> 0 | K23: =IF(B23>0,IF(J23<$R$3,"תקופת הפעילות נמוכה מהתקופה הנדרשת, ועל כן המוסד אינו זכאי לתקצוב","תקין"),"") | M23: =IF(OR($R$2=0,K23="תקין"),ROUND(IF(J23=6,(7-J23)*MIN(E23,F23),0),0),0) -> 0 | N23: =IF(OR($R$2=0,K23="תקין"),MAX(IF(B23="",0,MIN(F23,E23))-M23/7,0),0) -> 0 | O23: =IF(IF(B23=0,0,IFERROR(COUNTIF($B$18:$B$1017,B23)," "))>1,"סמל הגן מופיע יותר מפעם אחת",IF(ISBLANK(B23),"","תקין")) | P23: =IF(ISNUMBER(B23),IF(J23<1,"יש למלא מס' ימי פעילות",IF(AND(J23<7,L23=""),"יש למלא סיבה לחוסר ימי פעילות","תקין")),"") | Q23: =IF(LEFT(P23,10)="יש למלא מס",1,0) -> 0 | R23: =IF(B23>0,IF(F23=0,1,0),0) -> 0
A24: 7 | D24: =IFERROR(VLOOKUP($B24,'גנים - מצבת והרשמה (4)'!$C$16:$G$807,2,0),0) -> המוסד לא קיים | E24: =SUMIF('גנים - מצבת והרשמה (4)'!$F$15:$F$996,'גנים - דוח ביצוע (5)'!B24,'גנים - מצבת והרשמה (4)'!$H$15:$H$996) -> 0 | J24: =MIN(NETWORKDAYS.INTL(H24,I24,7),7) -> 0 | K24: =IF(B24>0,IF(J24<$R$3,"תקופת הפעילות נמוכה מהתקופה הנדרשת, ועל כן המוסד אינו זכאי לתקצוב","תקין"),"") | M24: =IF(OR($R$2=0,K24="תקין"),ROUND(IF(J24=6,(7-J24)*MIN(E24,F24),0),0),0) -> 0 | N24: =IF(OR($R$2=0,K24="תקין"),MAX(IF(B24="",0,MIN(F24,E24))-M24/7,0),0) -> 0 | O24: =IF(IF(B24=0,0,IFERROR(COUNTIF($B$18:$B$1017,B24)," "))>1,"סמל הגן מופיע יותר מפעם אחת",IF(ISBLANK(B24),"","תקין")) | P24: =IF(ISNUMBER(B24),IF(J24<1,"יש למלא מס' ימי פעילות",IF(AND(J24<7,L24=""),"יש למלא סיבה לחוסר ימי פעילות","תקין")),"") | Q24: =IF(LEFT(P24,10)="יש למלא מס",1,0) -> 0 | R24: =IF(B24>0,IF(F24=0,1,0),0) -> 0
A25: 8 | D25: =IFERROR(VLOOKUP($B25,'גנים - מצבת והרשמה (4)'!$C$16:$G$807,2,0),0) -> המוסד לא קיים | E25: =SUMIF('גנים - מצבת והרשמה (4)'!$F$15:$F$996,'גנים - דוח ביצוע (5)'!B25,'גנים - מצבת והרשמה (4)'!$H$15:$H$996) -> 0 | J25: =MIN(NETWORKDAYS.INTL(H25,I25,7),7) -> 0 | K25: =IF(B25>0,IF(J25<$R$3,"תקופת הפעילות נמוכה מהתקופה הנדרשת, ועל כן המוסד אינו זכאי לתקצוב","תקין"),"") | M25: =IF(OR($R$2=0,K25="תקין"),ROUND(IF(J25=6,(7-J25)*MIN(E25,F25),0),0),0) -> 0 | N25: =IF(OR($R$2=0,K25="תקין"),MAX(IF(B25="",0,MIN(F25,E25))-M25/7,0),0) -> 0 | O25: =IF(IF(B25=0,0,IFERROR(COUNTIF($B$18:$B$1017,B25)," "))>1,"סמל הגן מופיע יותר מפעם אחת",IF(ISBLANK(B25),"","תקין")) | P25: =IF(ISNUMBER(B25),IF(J25<1,"יש למלא מס' ימי פעילות",IF(AND(J25<7,L25=""),"יש למלא סיבה לחוסר ימי פעילות","תקין")),"") | Q25: =IF(LEFT(P25,10)="יש למלא מס",1,0) -> 0 | R25: =IF(B25>0,IF(F25=0,1,0),0) -> 0
A26: 9 | D26: =IFERROR(VLOOKUP($B26,'גנים - מצבת והרשמה (4)'!$C$16:$G$807,2,0),0) -> המוסד לא קיים | E26: =SUMIF('גנים - מצבת והרשמה (4)'!$F$15:$F$996,'גנים - דוח ביצוע (5)'!B26,'גנים - מצבת והרשמה (4)'!$H$15:$H$996) -> 0 | J26: =MIN(NETWORKDAYS.INTL(H26,I26,7),7) -> 0 | K26: =IF(B26>0,IF(J26<$R$3,"תקופת הפעילות נמוכה מהתקופה הנדרשת, ועל כן המוסד אינו זכאי לתקצוב","תקין"),"") | M26: =IF(OR($R$2=0,K26="תקין"),ROUND(IF(J26=6,(7-J26)*MIN(E26,F26),0),0),0) -> 0 | N26: =IF(OR($R$2=0,K26="תקין"),MAX(IF(B26="",0,MIN(F26,E26))-M26/7,0),0) -> 0 | O26: =IF(IF(B26=0,0,IFERROR(COUNTIF($B$18:$B$1017,B26)," "))>1,"סמל הגן מופיע יותר מפעם אחת",IF(ISBLANK(B26),"","תקין")) | P26: =IF(ISNUMBER(B26),IF(J26<1,"יש למלא מס' ימי פעילות",IF(AND(J26<7,L26=""),"יש למלא סיבה לחוסר ימי פעילות","תקין")),"") | Q26: =IF(LEFT(P26,10)="יש למלא מס",1,0) -> 0 | R26: =IF(B26>0,IF(F26=0,1,0),0) -> 0
A27: 10 | D27: =IFERROR(VLOOKUP($B27,'גנים - מצבת והרשמה (4)'!$C$16:$G$807,2,0),0) -> המוסד לא קיים | E27: =SUMIF('גנים - מצבת והרשמה (4)'!$F$15:$F$996,'גנים - דוח ביצוע (5)'!B27,'גנים - מצבת והרשמה (4)'!$H$15:$H$996) -> 0 | J27: =MIN(NETWORKDAYS.INTL(H27,I27,7),7) -> 0 | K27: =IF(B27>0,IF(J27<$R$3,"תקופת הפעילות נמוכה מהתקופה הנדרשת, ועל כן המוסד אינו זכאי לתקצוב","תקין"),"") | M27: =IF(OR($R$2=0,K27="תקין"),ROUND(IF(J27=6,(7-J27)*MIN(E27,F27),0),0),0) -> 0 | N27: =IF(OR($R$2=0,K27="תקין"),MAX(IF(B27="",0,MIN(F27,E27))-M27/7,0),0) -> 0 | O27: =IF(IF(B27=0,0,IFERROR(COUNTIF($B$18:$B$1017,B27)," "))>1,"סמל הגן מופיע יותר מפעם אחת",IF(ISBLANK(B27),"","תקין")) | P27: =IF(ISNUMBER(B27),IF(J27<1,"יש למלא מס' ימי פעילות",IF(AND(J27<7,L27=""),"יש למלא סיבה לחוסר ימי פעילות","תקין")),"") | Q27: =IF(LEFT(P27,10)="יש למלא מס",1,0) -> 0 | R27: =IF(B27>0,IF(F27=0,1,0),0) -> 0
A28: 11 | D28: =IFERROR(VLOOKUP($B28,'גנים - מצבת והרשמה (4)'!$C$16:$G$807,2,0),0) -> המוסד לא קיים | E28: =SUMIF('גנים - מצבת והרשמה (4)'!$F$15:$F$996,'גנים - דוח ביצוע (5)'!B28,'גנים - מצבת והרשמה (4)'!$H$15:$H$996) -> 0 | J28: =MIN(NETWORKDAYS.INTL(H28,I28,7),7) -> 0 | K28: =IF(B28>0,IF(J28<$R$3,"תקופת הפעילות נמוכה מהתקופה הנדרשת, ועל כן המוסד אינו זכאי לתקצוב","תקין"),"") | M28: =IF(OR($R$2=0,K28="תקין"),ROUND(IF(J28=6,(7-J28)*MIN(E28,F28),0),0),0) -> 0 | N28: =IF(OR($R$2=0,K28="תקין"),MAX(IF(B28="",0,MIN(F28,E28))-M28/7,0),0) -> 0 | O28: =IF(IF(B28=0,0,IFERROR(COUNTIF($B$18:$B$1017,B28)," "))>1,"סמל הגן מופיע יותר מפעם אחת",IF(ISBLANK(B28),"","תקין")) | P28: =IF(ISNUMBER(B28),IF(J28<1,"יש למלא מס' ימי פעילות",IF(AND(J28<7,L28=""),"יש למלא סיבה לחוסר ימי פעילות","תקין")),"") | Q28: =IF(LEFT(P28,10)="יש למלא מס",1,0) -> 0 | R28: =IF(B28>0,IF(F28=0,1,0),0) -> 0
A29: 12 | D29: =IFERROR(VLOOKUP($B29,'גנים - מצבת והרשמה (4)'!$C$16:$G$807,2,0),0) -> המוסד לא קיים | E29: =SUMIF('גנים - מצבת והרשמה (4)'!$F$15:$F$996,'גנים - דוח ביצוע (5)'!B29,'גנים - מצבת והרשמה (4)'!$H$15:$H$996) -> 0 | J29: =MIN(NETWORKDAYS.INTL(H29,I29,7),7) -> 0 | K29: =IF(B29>0,IF(J29<$R$3,"תקופת הפעילות נמוכה מהתקופה הנדרשת, ועל כן המוסד אינו זכאי לתקצוב","תקין"),"") | M29: =IF(OR($R$2=0,K29="תקין"),ROUND(IF(J29=6,(7-J29)*MIN(E29,F29),0),0),0) -> 0 | N29: =IF(OR($R$2=0,K29="תקין"),MAX(IF(B29="",0,MIN(F29,E29))-M29/7,0),0) -> 0 | O29: =IF(IF(B29=0,0,IFERROR(COUNTIF($B$18:$B$1017,B29)," "))>1,"סמל הגן מופיע יותר מפעם אחת",IF(ISBLANK(B29),"","תקין")) | P29: =IF(ISNUMBER(B29),IF(J29<1,"יש למלא מס' ימי פעילות",IF(AND(J29<7,L29=""),"יש למלא סיבה לחוסר ימי פעילות","תקין")),"") | Q29: =IF(LEFT(P29,10)="יש למלא מס",1,0) -> 0 | R29: =IF(B29>0,IF(F29=0,1,0),0) -> 0
... A1017: 1000 | D1017: =IFERROR(VLOOKUP($B1017,'גנים - מצבת והרשמה (4)'!$C$16:$G$807,2,0),0) -> המוסד לא קיים | E1017: =SUMIF('גנים - מצבת והרשמה (4)'!$F$15:$F$996,'גנים - דוח ביצוע (5)'!B1017,'גנים - מצבת והרשמה (4)'!$H$15:$H$996) -> 0 | J1017: =MIN(NETWORKDAYS.INTL(H1017,I1017,7),7) -> 0 | K1017: =IF(B1017>0,IF(J1017<$R$3,"תקופת הפעילות נמוכה מהתקופה הנדרשת, ועל כן המוסד אינו זכאי לתקצוב","תקין"),"") | M1017: =IF(OR($R$2=0,K1017="תקין"),ROUND(IF(J1017=6,(7-J1017)*MIN(E1017,F1017),0),0),0) -> 0 | N1017: =IF(OR($R$2=0,K1017="תקין"),MAX(IF(B1017="",0,MIN(F1017,E1017))-M1017/7,0),0) -> 0 | O1017: =IF(IF(B1017=0,0,IFERROR(COUNTIF($B$18:$B$1017,B1017)," "))>1,"סמל הגן מופיע יותר מפעם אחת",IF(ISBLANK(B1017),"","תקין")) | P1017: =IF(ISNUMBER(B1017),IF(J1017<1,"יש למלא מס' ימי פעילות",IF(AND(J1017<7,L1017=""),"יש למלא סיבה לחוסר ימי פעילות","תקין")),"") | Q1017: =IF(LEFT(P1017,10)="יש למלא מס",1,0) -> 0 | R1017: =IF(B1017>0,IF(F1017=0,1,0),0) -> 0

Sheet פירוט עלויות כח אדם (6)
A1: תוכן העניינים | F1: ='גנים - דוח ביצוע (5)'!E1 -> תכנית בתי הספר והגנים של החופש הגדול, קיץ תשפ"ו | N1: * | Q1: * | X1: * | Y1: * | Z1: * | AA1: * | AB1: * | AC1: * | AD1: * | AE1: * | AF1: *
E3: שם הרשות המקומית | F3: ='נתונים כללים (1)'!$C$5 -> 0
I4: =IF(AND(I5="",I6="")," ","שגיאות בגיליון:")
D5: סיכום שכר גנים: | E5: שכר גננות וסייעות | F5: =SUM(M:M)-F6 -> 0 | I5: =IF($C$13<$B$13,CONCATENATE("שימו לב, ישנם ",$B$13-D13," מוסדות אשר דווחו בדוח ביצוע ולא דווח עליהם הוצאות"),IF($B$13<$C$13,CONCATENATE("שימו לב, ישנם ",$C$13-$B$13," מוסדות אשר דווח עליהם הוצאות אולם לא דווחו בדוח ביצוע"),""))
E6: שכר רכזות גנים | F6: =SUMIF(H:H,"רכזת גן",M:M) -> 0 | I6: =' איוש משרות (9)'!K5
D9: דוח ביצוע כספי - הוצאות בפועל - עלויות שכר | I9: בכל שורה יש למלא ראשית את איש הצוות ולאחר מכן את התפקיד | P9: בקרת תקינות
I10: יש לבחור את הנתונים מתוך הרשימה הנפתחת בלבד!
B11: סיכום
B12: סה"כ גנים מדווחים בדוח ביצוע | C12: סה"כ גנים שדווח עבורם הוצאות שכר | D12: סה"כ אנשי צוות שדווחו | E12: שכר גננות וסייעות | F12: שכר רכזות גנים | G12: סה"כ שכר שדווח
B13: ='גנים - דוח ביצוע (5)'!D11 -> 0 | C13: {=SUM(IF(FREQUENCY($B16:B$3015,$B159:B$3015)>0,1))} -> 0 | D13: =COUNT(D16:D5001) -> 0 | E13: =SUM(M16:M3015)-F13 -> 0 | F13: =SUMIF(H:H,"רכזת גן",M:M) -> 0 | G13: =E13+F13 -> 0
B15: סמל מקום פעילות | C15: שם מוסד | D15: ת.ז. עובד | E15: שם פרטי | F15: שם משפחה | G15: הועסק ע"י | H15: איש צוות | I15: תפקיד | J15: שכר ברוטו שעתי | K15: עלות שכר שעתית | L15: סך שעות | M15: עלות שכר לתקופה | O15: 1 | P15: בדיקת תקינות תעודת זהות | Q15: בקרת שכר ברוטו שעתי | R15: בקרת עלות שכר שעתית | S15: בקרת ברוטו שעתי- לא חרג מ-120 ₪ | T15: בקרת שעות עבודה | U15: בקרת כפילויות עובדים | V15: הסבר במידה ולא תקין | W15: 1 | X15: תקינות | Y15: בדיקת עלות שכר שעתית | Z15: בדיקת כפילות | AA15: בקרת תקינות ת.ז. | AB15: בקרת תשלום שכר לגננת- נמוך מ-75 ש"ח לשעה | AC15: עזר- רכזות | AD15: עזר- שכר | AE15: עזר סייעת | AF15: עזר- שכר
C16: =IFERROR(VLOOKUP(B16,'מצבת ורישום גנים'!B:D,3,0),"") | I16: =SUBSTITUTE(IFERROR(IF(H16="מדצ","מדצ/ית",IF(OR(H16="סייעת ממשיכה",H16="סייעת חדשה",H16="סייעת רפואית/אישית"),"סייעת",IF(H16="רכזת גן","רכזת גן"))),""),"FALSE","") | M16: =IF(AND(L16>0,K16>0),K16*L16,"") | N16: =TEXT(LEFT(H16,2),0) | P16: =IF(D16="","",IF(AA16=FALSE,"לא תקין","תקין")) | Q16: =IF(J16="","",IFERROR(IF(OR(H16="גננת",H16="מורה",H16="רכז",H16="רכזת גן",H16="רכז גן",H16="רכז בית ספר",H16="רכזת בית ספר"),IF(J16>=75,"תקין","לא תקין"),IF(H16="סייעת ממשיכה",IF(J16>=30,"תקין","לא תקין"),IF(H16="סייעת רפואית/אישית",IF(J16>=12.5,"תקין","לא תקין"),IF(H16="סייעת חדשה",IF(J16>=37,"תקין","לא תקין"),IF(OR(H16<>"מורה",H16<>"גננת",H16<>"סייעת"),IF(J16>=30.61,"תקין","לא תקין"),"לא תקין"))))),"")) | R16: =IF(K16="","",IF(OR(Y16<100%,Y16>140%),"לא תקין","תקין")) | S16: =IF(J16="","",IFERROR(IF(J16>120,"לא תקין","תקין"),"")) | T16: =IF(L16="","",IF(H16="","יש להזין איש צוות",IF(OR(H16="מורה",H16="גננת",H16="רכז גן",H16="רכזת גן",H16="סייעת ממשיכה",H16="סייעת חדשה",H16="מדצית",H16="מדצ",H16="מדריך",H16="מדריכה",H16="תוספת כח אדם"),IF(L16<=90,"תקין","לא תקין"),IF(OR(H16="רכז בית ספר",H16="רכזת תכנית בבית הספר",H16="רכזת בית ספר"),IF(L16<=114,"תקין","לא תקין"),IF(OR(H16="סגנית רכזת מעל 150",H16="סגן רכז"),IF(L16<=93,"תקין","לא תקין"),"לא תקין"))))) | U16: =IF(D16="","",IF(Z16>1,IF(SUMIF(D:D,D16,L:L)>90,"לא תקין","תקין"),"תקין")) | X16: =IF(M16="","",IF(OR(R16="לא תקין",S16="לא תקין",T16="לא תקין",,U16="לא תקין"),"לא תקין","תקין")) | Y16: =IFERROR(IF(J16="","",K16/J16),"") | Z16: =IF(D16="","",COUNTIF(D:D,D16)) | AA16: =MOD(MID(REPT(0,9-LEN(D16))&D16,1,1)+MID("0246813579",MID(REPT(0,9-LEN(D16))&D16,2,1)+1,1)+MID(REPT(0,9-LEN(D16))&D16,3,1)+MID("0246813579",MID(REPT(0,9-LEN(D16))&D16,4,1)+1,1)+MID(REPT(0,9-LEN(D16))&D16,5,1)+MID("0246813579",MID(REPT(0,9-LEN(D16))&D16,6,1)+1,1)+MID(REPT(0,9-LEN(D16))&D16,7,1)+MID("0246813579",MID(REPT(0,9-LEN(D16))&D16,8,1)+1,1)+MID(REPT(0,9-LEN(D16))&D16,9,1),10)=0 -> TRUE | AB16: =IF(H16="גננת",IF(J16<75,"לא תקין","תקין"),"") | AC16: =IF(B16<>"",B16&H16,"") | AD16: =M16 | AE16: =IF(B16<>"",B16&LEFT(H16,5),"") | AF16: =M16
C17: =IFERROR(VLOOKUP(B17,'מצבת ורישום גנים'!B:D,3,0),"") | I17: =SUBSTITUTE(IFERROR(IF(H17="מדצ","מדצ/ית",IF(OR(H17="סייעת ממשיכה",H17="סייעת חדשה",H17="סייעת רפואית/אישית"),"סייעת",IF(H17="רכזת גן","רכזת גן"))),""),"FALSE","") | M17: =IF(AND(L17>0,K17>0),K17*L17,"") | N17: =TEXT(LEFT(H17,2),0) | P17: =IF(D17="","",IF(AA17=FALSE,"לא תקין","תקין")) | Q17: =IF(J17="","",IFERROR(IF(OR(H17="גננת",H17="מורה",H17="רכז",H17="רכזת גן",H17="רכז גן",H17="רכז בית ספר",H17="רכזת בית ספר"),IF(J17>=75,"תקין","לא תקין"),IF(H17="סייעת ממשיכה",IF(J17>=30,"תקין","לא תקין"),IF(H17="סייעת רפואית/אישית",IF(J17>=12.5,"תקין","לא תקין"),IF(H17="סייעת חדשה",IF(J17>=37,"תקין","לא תקין"),IF(OR(H17<>"מורה",H17<>"גננת",H17<>"סייעת"),IF(J17>=30.61,"תקין","לא תקין"),"לא תקין"))))),"")) | R17: =IF(K17="","",IF(OR(Y17<100%,Y17>140%),"לא תקין","תקין")) | S17: =IF(J17="","",IFERROR(IF(J17>120,"לא תקין","תקין"),"")) | T17: =IF(L17="","",IF(H17="","יש להזין איש צוות",IF(OR(H17="מורה",H17="גננת",H17="רכז גן",H17="רכזת גן",H17="סייעת ממשיכה",H17="סייעת חדשה",H17="מדצית",H17="מדצ",H17="מדריך",H17="מדריכה",H17="תוספת כח אדם"),IF(L17<=90,"תקין","לא תקין"),IF(OR(H17="רכז בית ספר",H17="רכזת תכנית בבית הספר",H17="רכזת בית ספר"),IF(L17<=114,"תקין","לא תקין"),IF(OR(H17="סגנית רכזת מעל 150",H17="סגן רכז"),IF(L17<=93,"תקין","לא תקין"),"לא תקין"))))) | U17: =IF(D17="","",IF(Z17>1,IF(SUMIF(D:D,D17,L:L)>90,"לא תקין","תקין"),"תקין")) | X17: =IF(M17="","",IF(OR(R17="לא תקין",S17="לא תקין",T17="לא תקין",,U17="לא תקין"),"לא תקין","תקין")) | Y17: =IFERROR(IF(J17="","",K17/J17),"") | Z17: =IF(D17="","",COUNTIF(D:D,D17)) | AA17: =MOD(MID(REPT(0,9-LEN(D17))&D17,1,1)+MID("0246813579",MID(REPT(0,9-LEN(D17))&D17,2,1)+1,1)+MID(REPT(0,9-LEN(D17))&D17,3,1)+MID("0246813579",MID(REPT(0,9-LEN(D17))&D17,4,1)+1,1)+MID(REPT(0,9-LEN(D17))&D17,5,1)+MID("0246813579",MID(REPT(0,9-LEN(D17))&D17,6,1)+1,1)+MID(REPT(0,9-LEN(D17))&D17,7,1)+MID("0246813579",MID(REPT(0,9-LEN(D17))&D17,8,1)+1,1)+MID(REPT(0,9-LEN(D17))&D17,9,1),10)=0 -> TRUE | AB17: =IF(H17="גננת",IF(J17<75,"לא תקין","תקין"),"") | AC17: =IF(B17<>"",B17&H17,"") | AD17: =M17 | AE17: =IF(B17<>"",B17&LEFT(H17,5),"") | AF17: =M17
C18: =IFERROR(VLOOKUP(B18,'מצבת ורישום גנים'!B:D,3,0),"") | I18: =SUBSTITUTE(IFERROR(IF(H18="מדצ","מדצ/ית",IF(OR(H18="סייעת ממשיכה",H18="סייעת חדשה",H18="סייעת רפואית/אישית"),"סייעת",IF(H18="רכזת גן","רכזת גן"))),""),"FALSE","") | M18: =IF(AND(L18>0,K18>0),K18*L18,"") | N18: =TEXT(LEFT(H18,2),0) | P18: =IF(D18="","",IF(AA18=FALSE,"לא תקין","תקין")) | Q18: =IF(J18="","",IFERROR(IF(OR(H18="גננת",H18="מורה",H18="רכז",H18="רכזת גן",H18="רכז גן",H18="רכז בית ספר",H18="רכזת בית ספר"),IF(J18>=75,"תקין","לא תקין"),IF(H18="סייעת ממשיכה",IF(J18>=30,"תקין","לא תקין"),IF(H18="סייעת רפואית/אישית",IF(J18>=12.5,"תקין","לא תקין"),IF(H18="סייעת חדשה",IF(J18>=37,"תקין","לא תקין"),IF(OR(H18<>"מורה",H18<>"גננת",H18<>"סייעת"),IF(J18>=30.61,"תקין","לא תקין"),"לא תקין"))))),"")) | R18: =IF(K18="","",IF(OR(Y18<100%,Y18>140%),"לא תקין","תקין")) | S18: =IF(J18="","",IFERROR(IF(J18>120,"לא תקין","תקין"),"")) | T18: =IF(L18="","",IF(H18="","יש להזין איש צוות",IF(OR(H18="מורה",H18="גננת",H18="רכז גן",H18="רכזת גן",H18="סייעת ממשיכה",H18="סייעת חדשה",H18="מדצית",H18="מדצ",H18="מדריך",H18="מדריכה",H18="תוספת כח אדם"),IF(L18<=90,"תקין","לא תקין"),IF(OR(H18="רכז בית ספר",H18="רכזת תכנית בבית הספר",H18="רכזת בית ספר"),IF(L18<=114,"תקין","לא תקין"),IF(OR(H18="סגנית רכזת מעל 150",H18="סגן רכז"),IF(L18<=93,"תקין","לא תקין"),"לא תקין"))))) | U18: =IF(D18="","",IF(Z18>1,IF(SUMIF(D:D,D18,L:L)>90,"לא תקין","תקין"),"תקין")) | X18: =IF(M18="","",IF(OR(R18="לא תקין",S18="לא תקין",T18="לא תקין",,U18="לא תקין"),"לא תקין","תקין")) | Y18: =IFERROR(IF(J18="","",K18/J18),"") | Z18: =IF(D18="","",COUNTIF(D:D,D18)) | AA18: =MOD(MID(REPT(0,9-LEN(D18))&D18,1,1)+MID("0246813579",MID(REPT(0,9-LEN(D18))&D18,2,1)+1,1)+MID(REPT(0,9-LEN(D18))&D18,3,1)+MID("0246813579",MID(REPT(0,9-LEN(D18))&D18,4,1)+1,1)+MID(REPT(0,9-LEN(D18))&D18,5,1)+MID("0246813579",MID(REPT(0,9-LEN(D18))&D18,6,1)+1,1)+MID(REPT(0,9-LEN(D18))&D18,7,1)+MID("0246813579",MID(REPT(0,9-LEN(D18))&D18,8,1)+1,1)+MID(REPT(0,9-LEN(D18))&D18,9,1),10)=0 -> TRUE | AB18: =IF(H18="גננת",IF(J18<75,"לא תקין","תקין"),"") | AC18: =IF(B18<>"",B18&H18,"") | AD18: =M18 | AE18: =IF(B18<>"",B18&LEFT(H18,5),"") | AF18: =M18
C19: =IFERROR(VLOOKUP(B19,'מצבת ורישום גנים'!B:D,3,0),"") | I19: =SUBSTITUTE(IFERROR(IF(H19="מדצ","מדצ/ית",IF(OR(H19="סייעת ממשיכה",H19="סייעת חדשה",H19="סייעת רפואית/אישית"),"סייעת",IF(H19="רכזת גן","רכזת גן"))),""),"FALSE","") | M19: =IF(AND(L19>0,K19>0),K19*L19,"") | N19: =TEXT(LEFT(H19,2),0) | P19: =IF(D19="","",IF(AA19=FALSE,"לא תקין","תקין")) | Q19: =IF(J19="","",IFERROR(IF(OR(H19="גננת",H19="מורה",H19="רכז",H19="רכזת גן",H19="רכז גן",H19="רכז בית ספר",H19="רכזת בית ספר"),IF(J19>=75,"תקין","לא תקין"),IF(H19="סייעת ממשיכה",IF(J19>=30,"תקין","לא תקין"),IF(H19="סייעת רפואית/אישית",IF(J19>=12.5,"תקין","לא תקין"),IF(H19="סייעת חדשה",IF(J19>=37,"תקין","לא תקין"),IF(OR(H19<>"מורה",H19<>"גננת",H19<>"סייעת"),IF(J19>=30.61,"תקין","לא תקין"),"לא תקין"))))),"")) | R19: =IF(K19="","",IF(OR(Y19<100%,Y19>140%),"לא תקין","תקין")) | S19: =IF(J19="","",IFERROR(IF(J19>120,"לא תקין","תקין"),"")) | T19: =IF(L19="","",IF(H19="","יש להזין איש צוות",IF(OR(H19="מורה",H19="גננת",H19="רכז גן",H19="רכזת גן",H19="סייעת ממשיכה",H19="סייעת חדשה",H19="מדצית",H19="מדצ",H19="מדריך",H19="מדריכה",H19="תוספת כח אדם"),IF(L19<=90,"תקין","לא תקין"),IF(OR(H19="רכז בית ספר",H19="רכזת תכנית בבית הספר",H19="רכזת בית ספר"),IF(L19<=114,"תקין","לא תקין"),IF(OR(H19="סגנית רכזת מעל 150",H19="סגן רכז"),IF(L19<=93,"תקין","לא תקין"),"לא תקין"))))) | U19: =IF(D19="","",IF(Z19>1,IF(SUMIF(D:D,D19,L:L)>90,"לא תקין","תקין"),"תקין")) | X19: =IF(M19="","",IF(OR(R19="לא תקין",S19="לא תקין",T19="לא תקין",,U19="לא תקין"),"לא תקין","תקין")) | Y19: =IFERROR(IF(J19="","",K19/J19),"") | Z19: =IF(D19="","",COUNTIF(D:D,D19)) | AA19: =MOD(MID(REPT(0,9-LEN(D19))&D19,1,1)+MID("0246813579",MID(REPT(0,9-LEN(D19))&D19,2,1)+1,1)+MID(REPT(0,9-LEN(D19))&D19,3,1)+MID("0246813579",MID(REPT(0,9-LEN(D19))&D19,4,1)+1,1)+MID(REPT(0,9-LEN(D19))&D19,5,1)+MID("0246813579",MID(REPT(0,9-LEN(D19))&D19,6,1)+1,1)+MID(REPT(0,9-LEN(D19))&D19,7,1)+MID("0246813579",MID(REPT(0,9-LEN(D19))&D19,8,1)+1,1)+MID(REPT(0,9-LEN(D19))&D19,9,1),10)=0 -> TRUE | AB19: =IF(H19="גננת",IF(J19<75,"לא תקין","תקין"),"") | AC19: =IF(B19<>"",B19&H19,"") | AD19: =M19 | AE19: =IF(B19<>"",B19&LEFT(H19,5),"") | AF19: =M19
C20: =IFERROR(VLOOKUP(B20,'מצבת ורישום גנים'!B:D,3,0),"") | I20: =SUBSTITUTE(IFERROR(IF(H20="מדצ","מדצ/ית",IF(OR(H20="סייעת ממשיכה",H20="סייעת חדשה",H20="סייעת רפואית/אישית"),"סייעת",IF(H20="רכזת גן","רכזת גן"))),""),"FALSE","") | M20: =IF(AND(L20>0,K20>0),K20*L20,"") | N20: =TEXT(LEFT(H20,2),0) | P20: =IF(D20="","",IF(AA20=FALSE,"לא תקין","תקין")) | Q20: =IF(J20="","",IFERROR(IF(OR(H20="גננת",H20="מורה",H20="רכז",H20="רכזת גן",H20="רכז גן",H20="רכז בית ספר",H20="רכזת בית ספר"),IF(J20>=75,"תקין","לא תקין"),IF(H20="סייעת ממשיכה",IF(J20>=30,"תקין","לא תקין"),IF(H20="סייעת רפואית/אישית",IF(J20>=12.5,"תקין","לא תקין"),IF(H20="סייעת חדשה",IF(J20>=37,"תקין","לא תקין"),IF(OR(H20<>"מורה",H20<>"גננת",H20<>"סייעת"),IF(J20>=30.61,"תקין","לא תקין"),"לא תקין"))))),"")) | R20: =IF(K20="","",IF(OR(Y20<100%,Y20>140%),"לא תקין","תקין")) | S20: =IF(J20="","",IFERROR(IF(J20>120,"לא תקין","תקין"),"")) | T20: =IF(L20="","",IF(H20="","יש להזין איש צוות",IF(OR(H20="מורה",H20="גננת",H20="רכז גן",H20="רכזת גן",H20="סייעת ממשיכה",H20="סייעת חדשה",H20="מדצית",H20="מדצ",H20="מדריך",H20="מדריכה",H20="תוספת כח אדם"),IF(L20<=90,"תקין","לא תקין"),IF(OR(H20="רכז בית ספר",H20="רכזת תכנית בבית הספר",H20="רכזת בית ספר"),IF(L20<=114,"תקין","לא תקין"),IF(OR(H20="סגנית רכזת מעל 150",H20="סגן רכז"),IF(L20<=93,"תקין","לא תקין"),"לא תקין"))))) | U20: =IF(D20="","",IF(Z20>1,IF(SUMIF(D:D,D20,L:L)>90,"לא תקין","תקין"),"תקין")) | X20: =IF(M20="","",IF(OR(R20="לא תקין",S20="לא תקין",T20="לא תקין",,U20="לא תקין"),"לא תקין","תקין")) | Y20: =IFERROR(IF(J20="","",K20/J20),"") | Z20: =IF(D20="","",COUNTIF(D:D,D20)) | AA20: =MOD(MID(REPT(0,9-LEN(D20))&D20,1,1)+MID("0246813579",MID(REPT(0,9-LEN(D20))&D20,2,1)+1,1)+MID(REPT(0,9-LEN(D20))&D20,3,1)+MID("0246813579",MID(REPT(0,9-LEN(D20))&D20,4,1)+1,1)+MID(REPT(0,9-LEN(D20))&D20,5,1)+MID("0246813579",MID(REPT(0,9-LEN(D20))&D20,6,1)+1,1)+MID(REPT(0,9-LEN(D20))&D20,7,1)+MID("0246813579",MID(REPT(0,9-LEN(D20))&D20,8,1)+1,1)+MID(REPT(0,9-LEN(D20))&D20,9,1),10)=0 -> TRUE | AB20: =IF(H20="גננת",IF(J20<75,"לא תקין","תקין"),"") | AC20: =IF(B20<>"",B20&H20,"") | AD20: =M20 | AE20: =IF(B20<>"",B20&LEFT(H20,5),"") | AF20: =M20
C21: =IFERROR(VLOOKUP(B21,'מצבת ורישום גנים'!B:D,3,0),"") | I21: =SUBSTITUTE(IFERROR(IF(H21="מדצ","מדצ/ית",IF(OR(H21="סייעת ממשיכה",H21="סייעת חדשה",H21="סייעת רפואית/אישית"),"סייעת",IF(H21="רכזת גן","רכזת גן"))),""),"FALSE","") | M21: =IF(AND(L21>0,K21>0),K21*L21,"") | N21: =TEXT(LEFT(H21,2),0) | P21: =IF(D21="","",IF(AA21=FALSE,"לא תקין","תקין")) | Q21: =IF(J21="","",IFERROR(IF(OR(H21="גננת",H21="מורה",H21="רכז",H21="רכזת גן",H21="רכז גן",H21="רכז בית ספר",H21="רכזת בית ספר"),IF(J21>=75,"תקין","לא תקין"),IF(H21="סייעת ממשיכה",IF(J21>=30,"תקין","לא תקין"),IF(H21="סייעת רפואית/אישית",IF(J21>=12.5,"תקין","לא תקין"),IF(H21="סייעת חדשה",IF(J21>=37,"תקין","לא תקין"),IF(OR(H21<>"מורה",H21<>"גננת",H21<>"סייעת"),IF(J21>=30.61,"תקין","לא תקין"),"לא תקין"))))),"")) | R21: =IF(K21="","",IF(OR(Y21<100%,Y21>140%),"לא תקין","תקין")) | S21: =IF(J21="","",IFERROR(IF(J21>120,"לא תקין","תקין"),"")) | T21: =IF(L21="","",IF(H21="","יש להזין איש צוות",IF(OR(H21="מורה",H21="גננת",H21="רכז גן",H21="רכזת גן",H21="סייעת ממשיכה",H21="סייעת חדשה",H21="מדצית",H21="מדצ",H21="מדריך",H21="מדריכה",H21="תוספת כח אדם"),IF(L21<=90,"תקין","לא תקין"),IF(OR(H21="רכז בית ספר",H21="רכזת תכנית בבית הספר",H21="רכזת בית ספר"),IF(L21<=114,"תקין","לא תקין"),IF(OR(H21="סגנית רכזת מעל 150",H21="סגן רכז"),IF(L21<=93,"תקין","לא תקין"),"לא תקין"))))) | U21: =IF(D21="","",IF(Z21>1,IF(SUMIF(D:D,D21,L:L)>90,"לא תקין","תקין"),"תקין")) | X21: =IF(M21="","",IF(OR(R21="לא תקין",S21="לא תקין",T21="לא תקין",,U21="לא תקין"),"לא תקין","תקין")) | Y21: =IFERROR(IF(J21="","",K21/J21),"") | Z21: =IF(D21="","",COUNTIF(D:D,D21)) | AA21: =MOD(MID(REPT(0,9-LEN(D21))&D21,1,1)+MID("0246813579",MID(REPT(0,9-LEN(D21))&D21,2,1)+1,1)+MID(REPT(0,9-LEN(D21))&D21,3,1)+MID("0246813579",MID(REPT(0,9-LEN(D21))&D21,4,1)+1,1)+MID(REPT(0,9-LEN(D21))&D21,5,1)+MID("0246813579",MID(REPT(0,9-LEN(D21))&D21,6,1)+1,1)+MID(REPT(0,9-LEN(D21))&D21,7,1)+MID("0246813579",MID(REPT(0,9-LEN(D21))&D21,8,1)+1,1)+MID(REPT(0,9-LEN(D21))&D21,9,1),10)=0 -> TRUE | AB21: =IF(H21="גננת",IF(J21<75,"לא תקין","תקין"),"") | AC21: =IF(B21<>"",B21&H21,"") | AD21: =M21 | AE21: =IF(B21<>"",B21&LEFT(H21,5),"") | AF21: =M21
C22: =IFERROR(VLOOKUP(B22,'מצבת ורישום גנים'!B:D,3,0),"") | I22: =SUBSTITUTE(IFERROR(IF(H22="מדצ","מדצ/ית",IF(OR(H22="סייעת ממשיכה",H22="סייעת חדשה",H22="סייעת רפואית/אישית"),"סייעת",IF(H22="רכזת גן","רכזת גן"))),""),"FALSE","") | M22: =IF(AND(L22>0,K22>0),K22*L22,"") | N22: =TEXT(LEFT(H22,2),0) | P22: =IF(D22="","",IF(AA22=FALSE,"לא תקין","תקין")) | Q22: =IF(J22="","",IFERROR(IF(OR(H22="גננת",H22="מורה",H22="רכז",H22="רכזת גן",H22="רכז גן",H22="רכז בית ספר",H22="רכזת בית ספר"),IF(J22>=75,"תקין","לא תקין"),IF(H22="סייעת ממשיכה",IF(J22>=30,"תקין","לא תקין"),IF(H22="סייעת רפואית/אישית",IF(J22>=12.5,"תקין","לא תקין"),IF(H22="סייעת חדשה",IF(J22>=37,"תקין","לא תקין"),IF(OR(H22<>"מורה",H22<>"גננת",H22<>"סייעת"),IF(J22>=30.61,"תקין","לא תקין"),"לא תקין"))))),"")) | R22: =IF(K22="","",IF(OR(Y22<100%,Y22>140%),"לא תקין","תקין")) | S22: =IF(J22="","",IFERROR(IF(J22>120,"לא תקין","תקין"),"")) | T22: =IF(L22="","",IF(H22="","יש להזין איש צוות",IF(OR(H22="מורה",H22="גננת",H22="רכז גן",H22="רכזת גן",H22="סייעת ממשיכה",H22="סייעת חדשה",H22="מדצית",H22="מדצ",H22="מדריך",H22="מדריכה",H22="תוספת כח אדם"),IF(L22<=90,"תקין","לא תקין"),IF(OR(H22="רכז בית ספר",H22="רכזת תכנית בבית הספר",H22="רכזת בית ספר"),IF(L22<=114,"תקין","לא תקין"),IF(OR(H22="סגנית רכזת מעל 150",H22="סגן רכז"),IF(L22<=93,"תקין","לא תקין"),"לא תקין"))))) | U22: =IF(D22="","",IF(Z22>1,IF(SUMIF(D:D,D22,L:L)>90,"לא תקין","תקין"),"תקין")) | X22: =IF(M22="","",IF(OR(R22="לא תקין",S22="לא תקין",T22="לא תקין",,U22="לא תקין"),"לא תקין","תקין")) | Y22: =IFERROR(IF(J22="","",K22/J22),"") | Z22: =IF(D22="","",COUNTIF(D:D,D22)) | AA22: =MOD(MID(REPT(0,9-LEN(D22))&D22,1,1)+MID("0246813579",MID(REPT(0,9-LEN(D22))&D22,2,1)+1,1)+MID(REPT(0,9-LEN(D22))&D22,3,1)+MID("0246813579",MID(REPT(0,9-LEN(D22))&D22,4,1)+1,1)+MID(REPT(0,9-LEN(D22))&D22,5,1)+MID("0246813579",MID(REPT(0,9-LEN(D22))&D22,6,1)+1,1)+MID(REPT(0,9-LEN(D22))&D22,7,1)+MID("0246813579",MID(REPT(0,9-LEN(D22))&D22,8,1)+1,1)+MID(REPT(0,9-LEN(D22))&D22,9,1),10)=0 -> TRUE | AB22: =IF(H22="גננת",IF(J22<75,"לא תקין","תקין"),"") | AC22: =IF(B22<>"",B22&H22,"") | AD22: =M22 | AE22: =IF(B22<>"",B22&LEFT(H22,5),"") | AF22: =M22
